Workbook

Sheet Item_Responses
A1: MCMI-III SCORING TOOL - ITEM RESPONSE INPUT
A2: Enter 1 for TRUE, 0 for FALSE for each of the 175 items
A4: Patient Name: | D4: Date: | G4: Age:
A5: Gender (M/F): | D5: Setting: | G5: Examiner:
A6: Inpatient (Y/N): | D6: Axis I Duration (weeks):
A8: Item # | B8: Response (1=T, 0=F) | D8: Item # | E8: Response (1=T, 0=F) | G8: Item # | H8: Response (1=T, 0=F)
A9: 1 | D9: 61 | G9: 121
A10: 2 | D10: 62 | G10: 122
A11: 3 | D11: 63 | G11: 123
A12: 4 | D12: 64 | G12: 124
A13: 5 | D13: 65 | G13: 125
A14: 6 | D14: 66 | G14: 126
A15: 7 | D15: 67 | G15: 127
A16: 8 | D16: 68 | G16: 128
A17: 9 | D17: 69 | G17: 129
A18: 10 | D18: 70 | G18: 130
A19: 11 | D19: 71 | G19: 131
A20: 12 | D20: 72 | G20: 132
... A63: 55 | D63: 115 | G63: 175
A64: 56 | D64: 116
A65: 57 | D65: 117
A66: 58 | D66: 118
A67: 59 | D67: 119
A68: 60 | D68: 120

Sheet Raw_Scores
A1: MCMI-III - AUTOMATIC RAW SCORE CALCULATION
A2: Raw scores are calculated automatically from item responses
A4: Scale Code | B4: Scale Name | C4: Category | D4: Items Scored TRUE | E4: Items Scored FALSE | F4: RAW SCORE
A5: X | B5: Disclosure | C5: Modifying Indices | D5: [1, 4, 5, 6, 7, 10, 14, 15, 17, 21, 23, 24, 25, 27, 29, 30, 31, 32, 34, 35, 37, 39, 40, 42, 43, 44, 46, 48, 50, 51, 52, 53, 54, 55, 56, 58, 60, 61, 62, 63, 64, 66, 67, 69, 70, 71, 73, 74, 75, 76, 77, | E5: None | F5: =Item_Responses!B9+Item_Responses!B12+Item_Responses!B13+Item_Responses!B14+Item_Responses!B15+Item_Responses!B18+Item_Responses!B22+Item_Responses!B23+Item_Responses!B25+Item_Responses!B29+Item_Responses!B31+Item_Responses!B32+Item_Responses!B33+Item_Responses!B35+Item_Responses!B37+Item_Responses!B38+Item_Responses!B39+Item_Responses!B40+Item_Responses!B42+Item_Responses!B43+Item_Responses!B45+Item_Responses!B47+Item_Responses!B48+Item_Responses!B50+Item_Responses!B51+Item_Responses!B52+Item_Responses!B54+Item_Responses!B56+Item_Responses!B58+Item_Responses!B59+Item_Responses!B60+Item_Responses!B61+Item_Responses!B62+Item_Responses!B63+Item_Responses!B64+Item_Responses!B66+Item_Responses!B68+Item_Responses!E9+Item_Responses!E10+Item_Responses!E11+Item_Responses!E12+Item_Responses!E14+Item_Responses!E15+Item_Responses!E17+Item_Responses!E18+Item_Responses!E19+Item_Responses!E21+Item_Responses!E22+Item_Responses!E23+Item_Responses!E24+Item_Responses!E25+Item_Responses!E27+Item_Responses!E28+Item_Responses!E29+Item_Responses!E30+Item_Responses!E31+Item_Responses!E32+Item_Responses!E33+Item_Responses!E34+Item_Responses!E35+Item_Responses!E36+Item_Responses!E37+Item_Responses!E38+Item_Responses!E39+Item_Responses!E40+Item_Responses!E41+Item_Responses!E42+Item_Responses!E43+Item_Responses!E44+Item_Responses!E45+Item_Responses!E46+Item_Responses!E47+Item_Responses!E48+Item_Responses!E49+Item_Responses!E50+Item_Responses!E51+Item_Responses!E52+Item_Responses!E54+Item_Responses!E55+Item_Responses!E56+Item_Responses!E57+Item_Responses!E59+Item_Responses!E60+Item_Responses!E61+Item_Responses!E62+Item_Responses!E63+Item_Responses!E64+Item_Responses!E65+Item_Responses!E66+Item_Responses!E67+Item_Responses!E68+Item_Responses!H9+Item_Responses!H10+Item_Responses!H11+Item_Responses!H12+Item_Responses!H13+Item_Responses!H14+Item_Responses!H15+Item_Responses!H16+Item_Responses!H17+Item_Responses!H18+Item_Responses!H19+Item_Responses!H20+Item_Responses!H21+Item_Responses!H22+Item_Responses!H23+Item_Responses!H24+Item_Responses!H25+Item_Responses!H26+Item_Responses!H27+Item_Responses!H28+Item_Responses!H29+Item_Responses!H30+Item_Responses!H31+Item_Responses!H32+Item_Responses!H33+Item_Responses!H34+Item_Responses!H35+Item_Responses!H36+Item_Responses!H37+Item_Responses!H38+Item_Responses!H39+Item_Responses!H40+Item_Responses!H41+Item_Responses!H42+Item_Responses!H43+Item_Responses!H44+Item_Responses!H46+Item_Responses!H47+Item_Responses!H48+Item_Responses!H49+Item_Responses!H50+Item_Responses!H51+Item_Responses!H52+Item_Responses!H53+Item_Responses!H54+Item_Responses!H55+Item_Responses!H56+Item_Responses!H57+Item_Responses!H58+Item_Responses!H59+Item_Responses!H60+Item_Responses!H61+Item_Responses!H62+Item_Responses!H63
A6: Y | B6: Desirability | C6: Modifying Indices | D6: [2, 8, 16, 36, 41, 57, 68, 78, 105] | E6: [12, 33, 45, 47, 59, 72, 110, 157] | F6: =Item_Responses!B10+Item_Responses!B16+Item_Responses!B24+Item_Responses!B44+Item_Responses!B49+Item_Responses!B65+Item_Responses!E16+Item_Responses!E26+Item_Responses!E53+(1-Item_Responses!B20)+(1-Item_Responses!B41)+(1-Item_Responses!B53)+(1-Item_Responses!B55)+(1-Item_Responses!B67)+(1-Item_Responses!E20)+(1-Item_Responses!E58)+(1-Item_Responses!H45)
A7: Z | B7: Debasement | C7: Modifying Indices | D7: [25, 31, 39, 50, 51, 53, 54, 56, 71, 82, 84, 86, 87, 89, 90, 94, 100, 104, 107, 113, 118, 121, 126, 131, 139, 145, 151, 158, 164, 172, 175] | E7: None | F7: =Item_Responses!B33+Item_Responses!B39+Item_Responses!B47+Item_Responses!B58+Item_Responses!B59+Item_Responses!B61+Item_Responses!B62+Item_Responses!B64+Item_Responses!E19+Item_Responses!E30+Item_Responses!E32+Item_Responses!E34+Item_Responses!E35+Item_Responses!E37+Item_Responses!E38+Item_Responses!E42+Item_Responses!E48+Item_Responses!E52+Item_Responses!E55+Item_Responses!E61+Item_Responses!E66+Item_Responses!H9+Item_Responses!H14+Item_Responses!H19+Item_Responses!H27+Item_Responses!H33+Item_Responses!H39+Item_Responses!H46+Item_Responses!H52+Item_Responses!H60+Item_Responses!H63
A8: 1 | B8: Schizoid | C8: Clinical Personality Patterns | D8: [1, 14, 25, 40, 46, 55, 70, 81, 86, 92, 112, 118, 124, 130, 136] | E8: [57, 78, 105] | F8: =Item_Responses!B9+Item_Responses!B22+Item_Responses!B33+Item_Responses!B48+Item_Responses!B54+Item_Responses!B63+Item_Responses!E18+Item_Responses!E29+Item_Responses!E34+Item_Responses!E40+Item_Responses!E60+Item_Responses!E66+Item_Responses!H12+Item_Responses!H18+Item_Responses!H24+(1-Item_Responses!B65)+(1-Item_Responses!E26)+(1-Item_Responses!E53)
A9: 2A | B9: Avoidant | C9: Clinical Personality Patterns | D9: [1, 14, 25, 40, 46, 55, 62, 70, 81, 86, 92, 99, 107, 112, 118, 124, 130, 135, 141, 148, 154, 160, 166] | E9: None | F9: =Item_Responses!B9+Item_Responses!B22+Item_Responses!B33+Item_Responses!B48+Item_Responses!B54+Item_Responses!B63+Item_Responses!E10+Item_Responses!E18+Item_Responses!E29+Item_Responses!E34+Item_Responses!E40+Item_Responses!E47+Item_Responses!E55+Item_Responses!E60+Item_Responses!E66+Item_Responses!H12+Item_Responses!H18+Item_Responses!H23+Item_Responses!H29+Item_Responses!H36+Item_Responses!H42+Item_Responses!H48+Item_Responses!H54
A10: 2B | B10: Depressive | C10: Clinical Personality Patterns | D10: [1, 10, 14, 24, 25, 31, 40, 46, 50, 55, 62, 70, 75, 81, 86, 92, 99, 107, 112, 118, 121, 124, 127, 130, 135, 139, 148, 154, 160, 166, 172] | E10: None | F10: =Item_Responses!B9+Item_Responses!B18+Item_Responses!B22+Item_Responses!B32+Item_Responses!B33+Item_Responses!B39+Item_Responses!B48+Item_Responses!B54+Item_Responses!B58+Item_Responses!B63+Item_Responses!E10+Item_Responses!E18+Item_Responses!E23+Item_Responses!E29+Item_Responses!E34+Item_Responses!E40+Item_Responses!E47+Item_Responses!E55+Item_Responses!E60+Item_Responses!E66+Item_Responses!H9+Item_Responses!H12+Item_Responses!H15+Item_Responses!H18+Item_Responses!H23+Item_Responses!H27+Item_Responses!H36+Item_Responses!H42+Item_Responses!H48+Item_Responses!H54+Item_Responses!H60
A11: 3 | B11: Dependent | C11: Clinical Personality Patterns | D11: [4, 10, 17, 24, 29, 34, 40, 46, 52, 58, 62, 66, 74, 79, 84, 91, 97, 103, 109, 115, 121, 127, 133, 139, 145, 151, 158, 164, 170] | E11: None | F11: =Item_Responses!B12+Item_Responses!B18+Item_Responses!B25+Item_Responses!B32+Item_Responses!B37+Item_Responses!B42+Item_Responses!B48+Item_Responses!B54+Item_Responses!B60+Item_Responses!B66+Item_Responses!E10+Item_Responses!E14+Item_Responses!E22+Item_Responses!E27+Item_Responses!E32+Item_Responses!E39+Item_Responses!E45+Item_Responses!E51+Item_Responses!E57+Item_Responses!E63+Item_Responses!H9+Item_Responses!H15+Item_Responses!H21+Item_Responses!H27+Item_Responses!H33+Item_Responses!H39+Item_Responses!H46+Item_Responses!H52+Item_Responses!H58
A12: 4 | B12: Histrionic | C12: Clinical Personality Patterns | D12: [2, 8, 16, 23, 36, 41, 48, 57, 63, 68, 76, 78, 83, 88, 95, 101, 105, 108, 114, 120, 126, 132, 138, 144, 150, 156, 162, 168, 174] | E12: None | F12: =Item_Responses!B10+Item_Responses!B16+Item_Responses!B24+Item_Responses!B31+Item_Responses!B44+Item_Responses!B49+Item_Responses!B56+Item_Responses!B65+Item_Responses!E11+Item_Responses!E16+Item_Responses!E24+Item_Responses!E26+Item_Responses!E31+Item_Responses!E36+Item_Responses!E43+Item_Responses!E49+Item_Responses!E53+Item_Responses!E56+Item_Responses!E62+Item_Responses!E68+Item_Responses!H14+Item_Responses!H20+Item_Responses!H26+Item_Responses!H32+Item_Responses!H38+Item_Responses!H44+Item_Responses!H50+Item_Responses!H56+Item_Responses!H62
A13: 5 | B13: Narcissistic | C13: Clinical Personality Patterns | D13: [2, 8, 16, 23, 30, 36, 41, 48, 57, 63, 68, 76, 78, 83, 88, 95, 101, 105, 108, 114, 120, 126, 132, 138, 144, 150, 156, 162, 168, 174] | E13: [50, 86, 145, 175] | F13: =ROUND((Item_Responses!B10+Item_Responses!B16+Item_Responses!B24+Item_Responses!B31+Item_Responses!B38+Item_Responses!B44+Item_Responses!B49+Item_Responses!B56+Item_Responses!B65+Item_Responses!E11+Item_Responses!E16+Item_Responses!E24+Item_Responses!E26+Item_Responses!E31+Item_Responses!E36+Item_Responses!E43+Item_Responses!E49+Item_Responses!E53+Item_Responses!E56+Item_Responses!E62+Item_Responses!E68+Item_Responses!H14+Item_Responses!H20+Item_Responses!H26+Item_Responses!H32+Item_Responses!H38+Item_Responses!H44+Item_Responses!H50+Item_Responses!H56+Item_Responses!H62+(1-Item_Responses!B58)+(1-Item_Responses!E34)+(1-Item_Responses!H33)+(1-Item_Responses!H63))*2/3, 0)
A14: 6A | B14: Antisocial | C14: Clinical Personality Patterns | D14: [5, 15, 21, 27, 35, 42, 44, 53, 60, 64, 69, 73, 77, 82, 87, 93, 98, 102, 106, 111, 117, 123, 129, 134, 140, 146, 152, 159, 165, 171] | E14: None | F14: =Item_Responses!B13+Item_Responses!B23+Item_Responses!B29+Item_Responses!B35+Item_Responses!B43+Item_Responses!B50+Item_Responses!B52+Item_Responses!B61+Item_Responses!B68+Item_Responses!E12+Item_Responses!E17+Item_Responses!E21+Item_Responses!E25+Item_Responses!E30+Item_Responses!E35+Item_Responses!E41+Item_Responses!E46+Item_Responses!E50+Item_Responses!E54+Item_Responses!E59+Item_Responses!E65+Item_Responses!H11+Item_Responses!H17+Item_Responses!H22+Item_Responses!H28+Item_Responses!H34+Item_Responses!H40+Item_Responses!H47+Item_Responses!H53+Item_Responses!H59
A15: 6B | B15: Sadistic (Aggressive) | C15: Clinical Personality Patterns | D15: [5, 15, 21, 27, 35, 42, 44, 53, 60, 64, 69, 73, 77, 82, 87, 93, 98, 102, 106, 111, 117, 123, 129, 140, 146, 152] | E15: None | F15: =Item_Responses!B13+Item_Responses!B23+Item_Responses!B29+Item_Responses!B35+Item_Responses!B43+Item_Responses!B50+Item_Responses!B52+Item_Responses!B61+Item_Responses!B68+Item_Responses!E12+Item_Responses!E17+Item_Responses!E21+Item_Responses!E25+Item_Responses!E30+Item_Responses!E35+Item_Responses!E41+Item_Responses!E46+Item_Responses!E50+Item_Responses!E54+Item_Responses!E59+Item_Responses!E65+Item_Responses!H11+Item_Responses!H17+Item_Responses!H28+Item_Responses!H34+Item_Responses!H40
A16: 7 | B16: Compulsive | C16: Clinical Personality Patterns | D16: [2, 8, 16, 36, 41, 57, 68, 78, 105] | E16: [5, 15, 21, 27, 35, 42, 44, 53, 60, 64, 69, 73, 77, 82, 87, 93] | F16: =Item_Responses!B10+Item_Responses!B16+Item_Responses!B24+Item_Responses!B44+Item_Responses!B49+Item_Responses!B65+Item_Responses!E16+Item_Responses!E26+Item_Responses!E53+(1-Item_Responses!B13)+(1-Item_Responses!B23)+(1-Item_Responses!B29)+(1-Item_Responses!B35)+(1-Item_Responses!B43)+(1-Item_Responses!B50)+(1-Item_Responses!B52)+(1-Item_Responses!B61)+(1-Item_Responses!B68)+(1-Item_Responses!E12)+(1-Item_Responses!E17)+(1-Item_Responses!E21)+(1-Item_Responses!E25)+(1-Item_Responses!E30)+(1-Item_Responses!E35)+(1-Item_Responses!E41)
A17: 8A | B17: Negativistic (Passive-Aggressive) | C17: Clinical Personality Patterns | D17: [5, 7, 15, 21, 27, 30, 35, 37, 42, 44, 51, 53, 56, 60, 64, 66, 69, 73, 75, 77, 80, 82, 85, 87, 89, 93, 96, 98, 100, 102, 104, 106, 111, 113, 116, 117, 119, 123, 125, 129, 131, 134, 137, 140, 143, 146, | E17: None | F17: =Item_Responses!B13+Item_Responses!B15+Item_Responses!B23+Item_Responses!B29+Item_Responses!B35+Item_Responses!B38+Item_Responses!B43+Item_Responses!B45+Item_Responses!B50+Item_Responses!B52+Item_Responses!B59+Item_Responses!B61+Item_Responses!B64+Item_Responses!B68+Item_Responses!E12+Item_Responses!E14+Item_Responses!E17+Item_Responses!E21+Item_Responses!E23+Item_Responses!E25+Item_Responses!E28+Item_Responses!E30+Item_Responses!E33+Item_Responses!E35+Item_Responses!E37+Item_Responses!E41+Item_Responses!E44+Item_Responses!E46+Item_Responses!E48+Item_Responses!E50+Item_Responses!E52+Item_Responses!E54+Item_Responses!E59+Item_Responses!E61+Item_Responses!E64+Item_Responses!E65+Item_Responses!E67+Item_Responses!H11+Item_Responses!H13+Item_Responses!H17+Item_Responses!H19+Item_Responses!H22+Item_Responses!H25+Item_Responses!H28+Item_Responses!H31+Item_Responses!H34+Item_Responses!H37+Item_Responses!H40+Item_Responses!H43+Item_Responses!H47+Item_Responses!H49+Item_Responses!H53+Item_Responses!H55+Item_Responses!H59+Item_Responses!H61
A18: 8B | B18: Masochistic (Self-Defeating) | C18: Clinical Personality Patterns | D18: [1, 10, 14, 24, 25, 31, 40, 46, 50, 55, 62, 70, 75, 81, 84, 86, 89, 92, 97, 99, 103, 107, 109, 112, 115, 118, 121, 124, 127, 130, 133, 135, 139, 141, 145, 148, 151, 154, 158, 160, 164, 166, 170, 172, | E18: None | F18: =Item_Responses!B9+Item_Responses!B18+Item_Responses!B22+Item_Responses!B32+Item_Responses!B33+Item_Responses!B39+Item_Responses!B48+Item_Responses!B54+Item_Responses!B58+Item_Responses!B63+Item_Responses!E10+Item_Responses!E18+Item_Responses!E23+Item_Responses!E29+Item_Responses!E32+Item_Responses!E34+Item_Responses!E37+Item_Responses!E40+Item_Responses!E45+Item_Responses!E47+Item_Responses!E51+Item_Responses!E55+Item_Responses!E57+Item_Responses!E60+Item_Responses!E63+Item_Responses!E66+Item_Responses!H9+Item_Responses!H12+Item_Responses!H15+Item_Responses!H18+Item_Responses!H21+Item_Responses!H23+Item_Responses!H27+Item_Responses!H29+Item_Responses!H33+Item_Responses!H36+Item_Responses!H39+Item_Responses!H42+Item_Responses!H46+Item_Responses!H48+Item_Responses!H52+Item_Responses!H54+Item_Responses!H58+Item_Responses!H60+Item_Responses!H63
A19: S | B19: Schizotypal | C19: Severe Personality Pathology | D19: [1, 14, 25, 40, 46, 55, 62, 70, 81, 86, 90, 92, 94, 99, 107, 112, 118, 124, 130, 135, 136, 141, 148, 154, 160, 166] | E19: [57, 78, 105] | F19: =Item_Responses!B9+Item_Responses!B22+Item_Responses!B33+Item_Responses!B48+Item_Responses!B54+Item_Responses!B63+Item_Responses!E10+Item_Responses!E18+Item_Responses!E29+Item_Responses!E34+Item_Responses!E38+Item_Responses!E40+Item_Responses!E42+Item_Responses!E47+Item_Responses!E55+Item_Responses!E60+Item_Responses!E66+Item_Responses!H12+Item_Responses!H18+Item_Responses!H23+Item_Responses!H24+Item_Responses!H29+Item_Responses!H36+Item_Responses!H42+Item_Responses!H48+Item_Responses!H54+(1-Item_Responses!B65)+(1-Item_Responses!E26)+(1-Item_Responses!E53)
A20: C | B20: Borderline | C20: Severe Personality Pathology | D20: [5, 7, 15, 21, 27, 30, 35, 37, 42, 44, 51, 53, 56, 60, 62, 64, 66, 69, 73, 75, 77, 80, 82, 85, 87, 89, 93, 96, 98, 100, 102, 104, 106, 111, 113, 116, 117, 119, 123, 125, 129, 131, 134, 137, 140, 143, | E20: None | F20: =Item_Responses!B13+Item_Responses!B15+Item_Responses!B23+Item_Responses!B29+Item_Responses!B35+Item_Responses!B38+Item_Responses!B43+Item_Responses!B45+Item_Responses!B50+Item_Responses!B52+Item_Responses!B59+Item_Responses!B61+Item_Responses!B64+Item_Responses!B68+Item_Responses!E10+Item_Responses!E12+Item_Responses!E14+Item_Responses!E17+Item_Responses!E21+Item_Responses!E23+Item_Responses!E25+Item_Responses!E28+Item_Responses!E30+Item_Responses!E33+Item_Responses!E35+Item_Responses!E37+Item_Responses!E41+Item_Responses!E44+Item_Responses!E46+Item_Responses!E48+Item_Responses!E50+Item_Responses!E52+Item_Responses!E54+Item_Responses!E59+Item_Responses!E61+Item_Responses!E64+Item_Responses!E65+Item_Responses!E67+Item_Responses!H11+Item_Responses!H13+Item_Responses!H17+Item_Responses!H19+Item_Responses!H22+Item_Responses!H25+Item_Responses!H28+Item_Responses!H31+Item_Responses!H34+Item_Responses!H37+Item_Responses!H40+Item_Responses!H43+Item_Responses!H47+Item_Responses!H49+Item_Responses!H53+Item_Responses!H55+Item_Responses!H59+Item_Responses!H61
A21: P | B21: Paranoid | C21: Severe Personality Pathology | D21: [5, 15, 21, 27, 30, 35, 42, 44, 48, 53, 60, 63, 64, 69, 73, 76, 77, 82, 83, 87, 88, 93, 95, 98, 101, 102, 106, 108, 111, 114, 117, 120, 123, 126, 129, 132, 138, 140, 144, 146, 150, 152, 156, 159, 162, | E21: None | F21: =Item_Responses!B13+Item_Responses!B23+Item_Responses!B29+Item_Responses!B35+Item_Responses!B38+Item_Responses!B43+Item_Responses!B50+Item_Responses!B52+Item_Responses!B56+Item_Responses!B61+Item_Responses!B68+Item_Responses!E11+Item_Responses!E12+Item_Responses!E17+Item_Responses!E21+Item_Responses!E24+Item_Responses!E25+Item_Responses!E30+Item_Responses!E31+Item_Responses!E35+Item_Responses!E36+Item_Responses!E41+Item_Responses!E43+Item_Responses!E46+Item_Responses!E49+Item_Responses!E50+Item_Responses!E54+Item_Responses!E56+Item_Responses!E59+Item_Responses!E62+Item_Responses!E65+Item_Responses!E68+Item_Responses!H11+Item_Responses!H14+Item_Responses!H17+Item_Responses!H20+Item_Responses!H26+Item_Responses!H28+Item_Responses!H32+Item_Responses!H34+Item_Responses!H38+Item_Responses!H40+Item_Responses!H44+Item_Responses!H47+Item_Responses!H50+Item_Responses!H53+Item_Responses!H56+Item_Responses!H59+Item_Responses!H62
A22: A | B22: Anxiety | C22: Clinical Syndromes | D22: [6, 10, 17, 24, 29, 34, 43, 50, 51, 54, 56, 62, 66, 71, 74, 79, 82, 84, 89, 91, 97, 100, 103, 107, 109, 113, 115, 118, 121, 127, 131, 133, 139, 145, 151, 158, 164, 170, 172, 175] | E22: None | F22: =Item_Responses!B14+Item_Responses!B18+Item_Responses!B25+Item_Responses!B32+Item_Responses!B37+Item_Responses!B42+Item_Responses!B51+Item_Responses!B58+Item_Responses!B59+Item_Responses!B62+Item_Responses!B64+Item_Responses!E10+Item_Responses!E14+Item_Responses!E19+Item_Responses!E22+Item_Responses!E27+Item_Responses!E30+Item_Responses!E32+Item_Responses!E37+Item_Responses!E39+Item_Responses!E45+Item_Responses!E48+Item_Responses!E51+Item_Responses!E55+Item_Responses!E57+Item_Responses!E61+Item_Responses!E63+Item_Responses!E66+Item_Responses!H9+Item_Responses!H15+Item_Responses!H19+Item_Responses!H21+Item_Responses!H27+Item_Responses!H33+Item_Responses!H39+Item_Responses!H46+Item_Responses!H52+Item_Responses!H58+Item_Responses!H60+Item_Responses!H63
A23: H | B23: Somatoform | C23: Clinical Syndromes | D23: [6, 17, 24, 29, 34, 43, 46, 52, 54, 58, 62, 66, 74, 79, 84, 86, 91, 92, 97, 103, 109, 112, 115, 118, 121, 124, 127, 130, 133, 139, 145, 151, 158, 164, 170] | E23: None | F23: =Item_Responses!B14+Item_Responses!B25+Item_Responses!B32+Item_Responses!B37+Item_Responses!B42+Item_Responses!B51+Item_Responses!B54+Item_Responses!B60+Item_Responses!B62+Item_Responses!B66+Item_Responses!E10+Item_Responses!E14+Item_Responses!E22+Item_Responses!E27+Item_Responses!E32+Item_Responses!E34+Item_Responses!E39+Item_Responses!E40+Item_Responses!E45+Item_Responses!E51+Item_Responses!E57+Item_Responses!E60+Item_Responses!E63+Item_Responses!E66+Item_Responses!H9+Item_Responses!H12+Item_Responses!H15+Item_Responses!H18+Item_Responses!H21+Item_Responses!H27+Item_Responses!H33+Item_Responses!H39+Item_Responses!H46+Item_Responses!H52+Item_Responses!H58
A24: N | B24: Bipolar: Manic | C24: Clinical Syndromes | D24: [2, 8, 16, 23, 30, 36, 41, 48, 57, 63, 68, 76, 78, 83, 88, 95, 101, 105, 108, 114, 120, 126, 132, 138, 144, 150, 156, 162, 168, 174] | E24: None | F24: =Item_Responses!B10+Item_Responses!B16+Item_Responses!B24+Item_Responses!B31+Item_Responses!B38+Item_Responses!B44+Item_Responses!B49+Item_Responses!B56+Item_Responses!B65+Item_Responses!E11+Item_Responses!E16+Item_Responses!E24+Item_Responses!E26+Item_Responses!E31+Item_Responses!E36+Item_Responses!E43+Item_Responses!E49+Item_Responses!E53+Item_Responses!E56+Item_Responses!E62+Item_Responses!E68+Item_Responses!H14+Item_Responses!H20+Item_Responses!H26+Item_Responses!H32+Item_Responses!H38+Item_Responses!H44+Item_Responses!H50+Item_Responses!H56+Item_Responses!H62
A25: D | B25: Dysthymia | C25: Clinical Syndromes | D25: [1, 10, 14, 24, 25, 31, 40, 46, 50, 55, 62, 70, 75, 81, 84, 86, 89, 92, 99, 107, 112, 118, 121, 124, 127, 130, 135, 139, 141, 145, 148, 151, 154, 158, 160, 164, 166, 170, 172, 175] | E25: None | F25: =Item_Responses!B9+Item_Responses!B18+Item_Responses!B22+Item_Responses!B32+Item_Responses!B33+Item_Responses!B39+Item_Responses!B48+Item_Responses!B54+Item_Responses!B58+Item_Responses!B63+Item_Responses!E10+Item_Responses!E18+Item_Responses!E23+Item_Responses!E29+Item_Responses!E32+Item_Responses!E34+Item_Responses!E37+Item_Responses!E40+Item_Responses!E47+Item_Responses!E55+Item_Responses!E60+Item_Responses!E66+Item_Responses!H9+Item_Responses!H12+Item_Responses!H15+Item_Responses!H18+Item_Responses!H23+Item_Responses!H27+Item_Responses!H29+Item_Responses!H33+Item_Responses!H36+Item_Responses!H39+Item_Responses!H42+Item_Responses!H46+Item_Responses!H48+Item_Responses!H52+Item_Responses!H54+Item_Responses!H58+Item_Responses!H60+Item_Responses!H63
A26: B | B26: Alcohol Dependence | C26: Clinical Syndromes | D26: [5, 15, 21, 27, 35, 42, 44, 53, 60, 64, 69, 73, 77, 82, 87, 93, 98, 106, 117, 123, 129, 134, 140, 146, 152, 159, 165, 171] | E26: None | F26: =Item_Responses!B13+Item_Responses!B23+Item_Responses!B29+Item_Responses!B35+Item_Responses!B43+Item_Responses!B50+Item_Responses!B52+Item_Responses!B61+Item_Responses!B68+Item_Responses!E12+Item_Responses!E17+Item_Responses!E21+Item_Responses!E25+Item_Responses!E30+Item_Responses!E35+Item_Responses!E41+Item_Responses!E46+Item_Responses!E54+Item_Responses!E65+Item_Responses!H11+Item_Responses!H17+Item_Responses!H22+Item_Responses!H28+Item_Responses!H34+Item_Responses!H40+Item_Responses!H47+Item_Responses!H53+Item_Responses!H59
A27: T | B27: Drug Dependence | C27: Clinical Syndromes | D27: [5, 15, 21, 27, 35, 42, 44, 53, 60, 64, 69, 73, 77, 82, 87, 93, 98, 102, 106, 111, 117, 123, 129, 134, 140, 146, 152, 159, 165, 171] | E27: None | F27: =Item_Responses!B13+Item_Responses!B23+Item_Responses!B29+Item_Responses!B35+Item_Responses!B43+Item_Responses!B50+Item_Responses!B52+Item_Responses!B61+Item_Responses!B68+Item_Responses!E12+Item_Responses!E17+Item_Responses!E21+Item_Responses!E25+Item_Responses!E30+Item_Responses!E35+Item_Responses!E41+Item_Responses!E46+Item_Responses!E50+Item_Responses!E54+Item_Responses!E59+Item_Responses!E65+Item_Responses!H11+Item_Responses!H17+Item_Responses!H22+Item_Responses!H28+Item_Responses!H34+Item_Responses!H40+Item_Responses!H47+Item_Responses!H53+Item_Responses!H59
A28: R | B28: PTSD | C28: Clinical Syndromes | D28: [6, 10, 17, 24, 29, 34, 43, 50, 51, 54, 56, 62, 66, 71, 74, 79, 82, 84, 89, 91, 97, 100, 103, 107, 109, 113, 115, 118, 121, 127, 131, 133, 139, 145, 151, 158, 164, 170, 172, 175] | E28: None | F28: =Item_Responses!B14+Item_Responses!B18+Item_Responses!B25+Item_Responses!B32+Item_Responses!B37+Item_Responses!B42+Item_Responses!B51+Item_Responses!B58+Item_Responses!B59+Item_Responses!B62+Item_Responses!B64+Item_Responses!E10+Item_Responses!E14+Item_Responses!E19+Item_Responses!E22+Item_Responses!E27+Item_Responses!E30+Item_Responses!E32+Item_Responses!E37+Item_Responses!E39+Item_Responses!E45+Item_Responses!E48+Item_Responses!E51+Item_Responses!E55+Item_Responses!E57+Item_Responses!E61+Item_Responses!E63+Item_Responses!E66+Item_Responses!H9+Item_Responses!H15+Item_Responses!H19+Item_Responses!H21+Item_Responses!H27+Item_Responses!H33+Item_Responses!H39+Item_Responses!H46+Item_Responses!H52+Item_Responses!H58+Item_Responses!H60+Item_Responses!H63
A29: SS | B29: Thought Disorder | C29: Severe Clinical Syndromes | D29: [1, 14, 25, 40, 46, 55, 62, 70, 81, 86, 90, 92, 94, 99, 107, 112, 118, 124, 130, 135, 136, 141, 148, 154, 160, 166, 172, 175] | E29: None | F29: =Item_Responses!B9+Item_Responses!B22+Item_Responses!B33+Item_Responses!B48+Item_Responses!B54+Item_Responses!B63+Item_Responses!E10+Item_Responses!E18+Item_Responses!E29+Item_Responses!E34+Item_Responses!E38+Item_Responses!E40+Item_Responses!E42+Item_Responses!E47+Item_Responses!E55+Item_Responses!E60+Item_Responses!E66+Item_Responses!H12+Item_Responses!H18+Item_Responses!H23+Item_Responses!H24+Item_Responses!H29+Item_Responses!H36+Item_Responses!H42+Item_Responses!H48+Item_Responses!H54+Item_Responses!H60+Item_Responses!H63
A30: CC | B30: Major Depression | C30: Severe Clinical Syndromes | D30: [1, 10, 14, 24, 25, 31, 40, 46, 50, 55, 62, 70, 75, 81, 84, 86, 89, 92, 99, 107, 112, 118, 121, 124, 127, 130, 135, 139, 141, 145, 148, 151, 154, 158, 160, 164, 166, 170, 172, 175] | E30: None | F30: =Item_Responses!B9+Item_Responses!B18+Item_Responses!B22+Item_Responses!B32+Item_Responses!B33+Item_Responses!B39+Item_Responses!B48+Item_Responses!B54+Item_Responses!B58+Item_Responses!B63+Item_Responses!E10+Item_Responses!E18+Item_Responses!E23+Item_Responses!E29+Item_Responses!E32+Item_Responses!E34+Item_Responses!E37+Item_Responses!E40+Item_Responses!E47+Item_Responses!E55+Item_Responses!E60+Item_Responses!E66+Item_Responses!H9+Item_Responses!H12+Item_Responses!H15+Item_Responses!H18+Item_Responses!H23+Item_Responses!H27+Item_Responses!H29+Item_Responses!H33+Item_Responses!H36+Item_Responses!H39+Item_Responses!H42+Item_Responses!H46+Item_Responses!H48+Item_Responses!H52+Item_Responses!H54+Item_Responses!H58+Item_Responses!H60+Item_Responses!H63
A31: PP | B31: Delusional Disorder | C31: Severe Clinical Syndromes | D31: [5, 15, 21, 27, 30, 35, 42, 44, 48, 53, 60, 63, 64, 69, 73, 76, 77, 82, 83, 87, 88, 93, 95, 98, 101, 102, 106, 108, 111, 114, 117, 120, 123, 126, 129, 132, 138, 140, 144, 146, 150, 152, 156, 159, 162, | E31: None | F31: =Item_Responses!B13+Item_Responses!B23+Item_Responses!B29+Item_Responses!B35+Item_Responses!B38+Item_Responses!B43+Item_Responses!B50+Item_Responses!B52+Item_Responses!B56+Item_Responses!B61+Item_Responses!B68+Item_Responses!E11+Item_Responses!E12+Item_Responses!E17+Item_Responses!E21+Item_Responses!E24+Item_Responses!E25+Item_Responses!E30+Item_Responses!E31+Item_Responses!E35+Item_Responses!E36+Item_Responses!E41+Item_Responses!E43+Item_Responses!E46+Item_Responses!E49+Item_Responses!E50+Item_Responses!E54+Item_Responses!E56+Item_Responses!E59+Item_Responses!E62+Item_Responses!E65+Item_Responses!E68+Item_Responses!H11+Item_Responses!H14+Item_Responses!H17+Item_Responses!H20+Item_Responses!H26+Item_Responses!H28+Item_Responses!H32+Item_Responses!H34+Item_Responses!H38+Item_Responses!H40+Item_Responses!H44+Item_Responses!H47+Item_Responses!H50+Item_Responses!H53+Item_Responses!H56+Item_Responses!H59+Item_Responses!H62
A32: V | B32: Invalidity | C32: Validity | D32: 65, 110, 157 | F32: =Item_Responses!E13+Item_Responses!E58+Item_Responses!H45

Sheet Disclosure_Table
A1: Scale X Raw Score | B1: 1-8B Adjustment | C1: S-PP Adjustment
A2: 0 | B2: 20 | C2: 10
A3: 1 | B3: 20 | C3: 10
A4: 2 | B4: 20 | C4: 10
A5: 3 | B5: 20 | C5: 10
A6: 4 | B6: 20 | C6: 10
A7: 5 | B7: 20 | C7: 10
A8: 6 | B8: 20 | C8: 10
A9: 7 | B9: 20 | C9: 10
A10: 8 | B10: 20 | C10: 10
A11: 9 | B11: 20 | C11: 10
A12: 10 | B12: 20 | C12: 10
A13: 11 | B13: 20 | C13: 10
... A201: 199 | B201: -20 | C201: -11

Sheet AD_2AS
A1: A/D Value | B1: 2A, S Adjustment
A2: 0 | B2: -1
A3: 1 | B3: -1
A4: 2 | B4: -1
A5: 3 | B5: -1
A6: 4 | B6: -1
A7: 5 | B7: -1
A8: 6 | B8: -1
A9: 7 | B9: -1
A10: 8 | B10: -2
A11: 9 | B11: -2
A12: 10 | B12: -2
A13: 11 | B13: -2
... A82: 80 | B82: -10

Sheet AD_2B8BC
A1: A/D Value | B1: 2B, 8B, C Adjustment
A2: 0 | B2: -1
A3: 1 | B3: -1
A4: 2 | B4: -1
A5: 3 | B5: -1
A6: 4 | B6: -1
A7: 5 | B7: -1
A8: 6 | B8: -1
A9: 7 | B9: -1
A10: 8 | B10: -1
A11: 9 | B11: -1
A12: 10 | B12: -2
A13: 11 | B13: -2
... A82: 80 | B82: -15

Sheet Scoring_Results
A1: MCMI-III COMPLETE SCORING RESULTS
A2: Enter Initial BR Scores from Appendix C (or use BR_Lookup sheet). All adjustments auto-calculated.
A4: VALIDITY CHECKS
A5: V (Invalidity) Score: | B5: =Raw_Scores!F32 | C5: =IF(B5>1,"INVALID - V > 1","VALID")
A6: Scale X Raw Score: | B6: =Raw_Scores!F5 | C6: =IF(OR(B6<34,B6>178),"INVALID - X out of range","VALID")
A7: Protocol Status: | B7: =IF(OR(B5>1,B6<34,B6>178),"INVALID","VALID - Proceed")
A9: Scale Code | B9: Scale Name | C9: Category | D9: RAW SCORE | E9: Initial BR (Enter from Appendix C) | F9: Disclosure Adjustment | G9: A/D Adjustment | H9: Inpatient Adjustment | I9: Denial/Complaint Adj. (manual) | J9: FINAL BR SCORE | K9: Clinical Significance
A10: X | B10: Disclosure | C10: Modifying Indices | D10: =Raw_Scores!F5 | F10: N/A | G10: N/A | H10: 0 | I10: 0 | J10: =IF(E10="","",MIN(MAX(E10,0),115)) | K10: =IF(J10="","",IF(J10>=85,"PROMINENT/PATHOLOGICAL",IF(J10>=75,"PRESENT/TRAIT LEVEL",IF(J10>=60,"Suggestive","Normal/Not Significant"))))
A11: Y | B11: Desirability | C11: Modifying Indices | D11: =Raw_Scores!F6 | F11: N/A | G11: N/A | H11: 0 | I11: 0 | J11: =IF(E11="","",MIN(MAX(E11,0),115)) | K11: =IF(J11="","",IF(J11>=85,"PROMINENT/PATHOLOGICAL",IF(J11>=75,"PRESENT/TRAIT LEVEL",IF(J11>=60,"Suggestive","Normal/Not Significant"))))
A12: Z | B12: Debasement | C12: Modifying Indices | D12: =Raw_Scores!F7 | F12: N/A | G12: N/A | H12: 0 | I12: 0 | J12: =IF(E12="","",MIN(MAX(E12,0),115)) | K12: =IF(J12="","",IF(J12>=85,"PROMINENT/PATHOLOGICAL",IF(J12>=75,"PRESENT/TRAIT LEVEL",IF(J12>=60,"Suggestive","Normal/Not Significant"))))
A13: 1 | B13: Schizoid | C13: Clinical Personality Patterns | D13: =Raw_Scores!F8 | F13: =IF(D10="","",VLOOKUP(MIN(MAX(D10,0),199),Disclosure_Table!A:B,2,TRUE)) | G13: N/A | H13: 0 | I13: 0 | J13: =IF(E13="","",MIN(MAX(E13+IF(ISNUMBER(F13),F13,0)+IF(ISNUMBER(G13),G13,0)+IF(ISNUMBER(H13),H13,0)+IF(ISNUMBER(I13),I13,0),0),115)) | K13: =IF(J13="","",IF(J13>=85,"PROMINENT/PATHOLOGICAL",IF(J13>=75,"PRESENT/TRAIT LEVEL",IF(J13>=60,"Suggestive","Normal/Not Significant"))))
A14: 2A | B14: Avoidant | C14: Clinical Personality Patterns | D14: =Raw_Scores!F9 | F14: =IF(D10="","",VLOOKUP(MIN(MAX(D10,0),199),Disclosure_Table!A:B,2,TRUE)) | G14: =IF(OR(E27="",E30=""),"",IF(AND((E27+IF(ISNUMBER(F27),F27,0))<75,(E30+IF(ISNUMBER(F30),F30,0))<75),0,IF(AND((E27+IF(ISNUMBER(F27),F27,0))>=75,(E30+IF(ISNUMBER(F30),F30,0))<75),VLOOKUP((E27+IF(ISNUMBER(F27),F27,0))-75,AD_2AS!A:B,2,TRUE),IF(AND((E30+IF(ISNUMBER(F30),F30,0))>=75,(E27+IF(ISNUMBER(F27),F27,0))<75),VLOOKUP((E30+IF(ISNUMBER(F30),F30,0))-75,AD_2AS!A:B,2,TRUE),VLOOKUP(MIN(((E27+IF(ISNUMBER(F27),F27,0))-75)+((E30+IF(ISNUMBER(F30),F30,0))-75),80),AD_2AS!A:B,2,TRUE))))) | H14: 0 | I14: 0 | J14: =IF(E14="","",MIN(MAX(E14+IF(ISNUMBER(F14),F14,0)+IF(ISNUMBER(G14),G14,0)+IF(ISNUMBER(H14),H14,0)+IF(ISNUMBER(I14),I14,0),0),115)) | K14: =IF(J14="","",IF(J14>=85,"PROMINENT/PATHOLOGICAL",IF(J14>=75,"PRESENT/TRAIT LEVEL",IF(J14>=60,"Suggestive","Normal/Not Significant"))))
A15: 2B | B15: Depressive | C15: Clinical Personality Patterns | D15: =Raw_Scores!F10 | F15: =IF(D10="","",VLOOKUP(MIN(MAX(D10,0),199),Disclosure_Table!A:B,2,TRUE)) | G15: =IF(OR(E27="",E30=""),"",IF(AND((E27+IF(ISNUMBER(F27),F27,0))<75,(E30+IF(ISNUMBER(F30),F30,0))<75),0,IF(AND((E27+IF(ISNUMBER(F27),F27,0))>=75,(E30+IF(ISNUMBER(F30),F30,0))<75),VLOOKUP((E27+IF(ISNUMBER(F27),F27,0))-75,AD_2B8BC!A:B,2,TRUE),IF(AND((E30+IF(ISNUMBER(F30),F30,0))>=75,(E27+IF(ISNUMBER(F27),F27,0))<75),VLOOKUP((E30+IF(ISNUMBER(F30),F30,0))-75,AD_2B8BC!A:B,2,TRUE),VLOOKUP(MIN(((E27+IF(ISNUMBER(F27),F27,0))-75)+((E30+IF(ISNUMBER(F30),F30,0))-75),80),AD_2B8BC!A:B,2,TRUE))))) | H15: 0 | I15: 0 | J15: =IF(E15="","",MIN(MAX(E15+IF(ISNUMBER(F15),F15,0)+IF(ISNUMBER(G15),G15,0)+IF(ISNUMBER(H15),H15,0)+IF(ISNUMBER(I15),I15,0),0),115)) | K15: =IF(J15="","",IF(J15>=85,"PROMINENT/PATHOLOGICAL",IF(J15>=75,"PRESENT/TRAIT LEVEL",IF(J15>=60,"Suggestive","Normal/Not Significant"))))
A16: 3 | B16: Dependent | C16: Clinical Personality Patterns | D16: =Raw_Scores!F11 | F16: =IF(D10="","",VLOOKUP(MIN(MAX(D10,0),199),Disclosure_Table!A:B,2,TRUE)) | G16: N/A | H16: 0 | I16: 0 | J16: =IF(E16="","",MIN(MAX(E16+IF(ISNUMBER(F16),F16,0)+IF(ISNUMBER(G16),G16,0)+IF(ISNUMBER(H16),H16,0)+IF(ISNUMBER(I16),I16,0),0),115)) | K16: =IF(J16="","",IF(J16>=85,"PROMINENT/PATHOLOGICAL",IF(J16>=75,"PRESENT/TRAIT LEVEL",IF(J16>=60,"Suggestive","Normal/Not Significant"))))
A17: 4 | B17: Histrionic | C17: Clinical Personality Patterns | D17: =Raw_Scores!F12 | F17: =IF(D10="","",VLOOKUP(MIN(MAX(D10,0),199),Disclosure_Table!A:B,2,TRUE)) | G17: N/A | H17: 0 | I17: 0 | J17: =IF(E17="","",MIN(MAX(E17+IF(ISNUMBER(F17),F17,0)+IF(ISNUMBER(G17),G17,0)+IF(ISNUMBER(H17),H17,0)+IF(ISNUMBER(I17),I17,0),0),115)) | K17: =IF(J17="","",IF(J17>=85,"PROMINENT/PATHOLOGICAL",IF(J17>=75,"PRESENT/TRAIT LEVEL",IF(J17>=60,"Suggestive","Normal/Not Significant"))))
A18: 5 | B18: Narcissistic | C18: Clinical Personality Patterns | D18: =Raw_Scores!F13 | F18: =IF(D10="","",VLOOKUP(MIN(MAX(D10,0),199),Disclosure_Table!A:B,2,TRUE)) | G18: N/A | H18: 0 | I18: 0 | J18: =IF(E18="","",MIN(MAX(E18+IF(ISNUMBER(F18),F18,0)+IF(ISNUMBER(G18),G18,0)+IF(ISNUMBER(H18),H18,0)+IF(ISNUMBER(I18),I18,0),0),115)) | K18: =IF(J18="","",IF(J18>=85,"PROMINENT/PATHOLOGICAL",IF(J18>=75,"PRESENT/TRAIT LEVEL",IF(J18>=60,"Suggestive","Normal/Not Significant"))))
A19: 6A | B19: Antisocial | C19: Clinical Personality Patterns | D19: =Raw_Scores!F14 | F19: =IF(D10="","",VLOOKUP(MIN(MAX(D10,0),199),Disclosure_Table!A:B,2,TRUE)) | G19: N/A | H19: 0 | I19: 0 | J19: =IF(E19="","",MIN(MAX(E19+IF(ISNUMBER(F19),F19,0)+IF(ISNUMBER(G19),G19,0)+IF(ISNUMBER(H19),H19,0)+IF(ISNUMBER(I19),I19,0),0),115)) | K19: =IF(J19="","",IF(J19>=85,"PROMINENT/PATHOLOGICAL",IF(J19>=75,"PRESENT/TRAIT LEVEL",IF(J19>=60,"Suggestive","Normal/Not Significant"))))
A20: 6B | B20: Sadistic (Aggressive) | C20: Clinical Personality Patterns | D20: =Raw_Scores!F15 | F20: =IF(D10="","",VLOOKUP(MIN(MAX(D10,0),199),Disclosure_Table!A:B,2,TRUE)) | G20: N/A | H20: 0 | I20: 0 | J20: =IF(E20="","",MIN(MAX(E20+IF(ISNUMBER(F20),F20,0)+IF(ISNUMBER(G20),G20,0)+IF(ISNUMBER(H20),H20,0)+IF(ISNUMBER(I20),I20,0),0),115)) | K20: =IF(J20="","",IF(J20>=85,"PROMINENT/PATHOLOGICAL",IF(J20>=75,"PRESENT/TRAIT LEVEL",IF(J20>=60,"Suggestive","Normal/Not Significant"))))
A21: 7 | B21: Compulsive | C21: Clinical Personality Patterns | D21: =Raw_Scores!F16 | F21: =IF(D10="","",VLOOKUP(MIN(MAX(D10,0),199),Disclosure_Table!A:B,2,TRUE)) | G21: N/A | H21: 0 | I21: 0 | J21: =IF(E21="","",MIN(MAX(E21+IF(ISNUMBER(F21),F21,0)+IF(ISNUMBER(G21),G21,0)+IF(ISNUMBER(H21),H21,0)+IF(ISNUMBER(I21),I21,0),0),115)) | K21: =IF(J21="","",IF(J21>=85,"PROMINENT/PATHOLOGICAL",IF(J21>=75,"PRESENT/TRAIT LEVEL",IF(J21>=60,"Suggestive","Normal/Not Significant"))))
A22: 8A | B22: Negativistic (Passive-Aggressive) | C22: Clinical Personality Patterns | D22: =Raw_Scores!F17 | F22: =IF(D10="","",VLOOKUP(MIN(MAX(D10,0),199),Disclosure_Table!A:B,2,TRUE)) | G22: N/A | H22: 0 | I22: 0 | J22: =IF(E22="","",MIN(MAX(E22+IF(ISNUMBER(F22),F22,0)+IF(ISNUMBER(G22),G22,0)+IF(ISNUMBER(H22),H22,0)+IF(ISNUMBER(I22),I22,0),0),115)) | K22: =IF(J22="","",IF(J22>=85,"PROMINENT/PATHOLOGICAL",IF(J22>=75,"PRESENT/TRAIT LEVEL",IF(J22>=60,"Suggestive","Normal/Not Significant"))))
A23: 8B | B23: Masochistic (Self-Defeating) | C23: Clinical Personality Patterns | D23: =Raw_Scores!F18 | F23: =IF(D10="","",VLOOKUP(MIN(MAX(D10,0),199),Disclosure_Table!A:B,2,TRUE)) | G23: =IF(OR(E27="",E30=""),"",IF(AND((E27+IF(ISNUMBER(F27),F27,0))<75,(E30+IF(ISNUMBER(F30),F30,0))<75),0,IF(AND((E27+IF(ISNUMBER(F27),F27,0))>=75,(E30+IF(ISNUMBER(F30),F30,0))<75),VLOOKUP((E27+IF(ISNUMBER(F27),F27,0))-75,AD_2B8BC!A:B,2,TRUE),IF(AND((E30+IF(ISNUMBER(F30),F30,0))>=75,(E27+IF(ISNUMBER(F27),F27,0))<75),VLOOKUP((E30+IF(ISNUMBER(F30),F30,0))-75,AD_2B8BC!A:B,2,TRUE),VLOOKUP(MIN(((E27+IF(ISNUMBER(F27),F27,0))-75)+((E30+IF(ISNUMBER(F30),F30,0))-75),80),AD_2B8BC!A:B,2,TRUE))))) | H23: 0 | I23: 0 | J23: =IF(E23="","",MIN(MAX(E23+IF(ISNUMBER(F23),F23,0)+IF(ISNUMBER(G23),G23,0)+IF(ISNUMBER(H23),H23,0)+IF(ISNUMBER(I23),I23,0),0),115)) | K23: =IF(J23="","",IF(J23>=85,"PROMINENT/PATHOLOGICAL",IF(J23>=75,"PRESENT/TRAIT LEVEL",IF(J23>=60,"Suggestive","Normal/Not Significant"))))
A24: S | B24: Schizotypal | C24: Severe Personality Pathology | D24: =Raw_Scores!F19 | F24: =IF(D10="","",VLOOKUP(MIN(MAX(D10,0),199),Disclosure_Table!A:C,3,TRUE)) | G24: =IF(OR(E27="",E30=""),"",IF(AND((E27+IF(ISNUMBER(F27),F27,0))<75,(E30+IF(ISNUMBER(F30),F30,0))<75),0,IF(AND((E27+IF(ISNUMBER(F27),F27,0))>=75,(E30+IF(ISNUMBER(F30),F30,0))<75),VLOOKUP((E27+IF(ISNUMBER(F27),F27,0))-75,AD_2AS!A:B,2,TRUE),IF(AND((E30+IF(ISNUMBER(F30),F30,0))>=75,(E27+IF(ISNUMBER(F27),F27,0))<75),VLOOKUP((E30+IF(ISNUMBER(F30),F30,0))-75,AD_2AS!A:B,2,TRUE),VLOOKUP(MIN(((E27+IF(ISNUMBER(F27),F27,0))-75)+((E30+IF(ISNUMBER(F30),F30,0))-75),80),AD_2AS!A:B,2,TRUE))))) | H24: 0 | I24: 0 | J24: =IF(E24="","",MIN(MAX(E24+IF(ISNUMBER(F24),F24,0)+IF(ISNUMBER(G24),G24,0)+IF(ISNUMBER(H24),H24,0)+IF(ISNUMBER(I24),I24,0),0),115)) | K24: =IF(J24="","",IF(J24>=85,"PROMINENT/PATHOLOGICAL",IF(J24>=75,"PRESENT/TRAIT LEVEL",IF(J24>=60,"Suggestive","Normal/Not Significant"))))
A25: C | B25: Borderline | C25: Severe Personality Pathology | D25: =Raw_Scores!F20 | F25: =IF(D10="","",VLOOKUP(MIN(MAX(D10,0),199),Disclosure_Table!A:C,3,TRUE)) | G25: =IF(OR(E27="",E30=""),"",IF(AND((E27+IF(ISNUMBER(F27),F27,0))<75,(E30+IF(ISNUMBER(F30),F30,0))<75),0,IF(AND((E27+IF(ISNUMBER(F27),F27,0))>=75,(E30+IF(ISNUMBER(F30),F30,0))<75),VLOOKUP((E27+IF(ISNUMBER(F27),F27,0))-75,AD_2B8BC!A:B,2,TRUE),IF(AND((E30+IF(ISNUMBER(F30),F30,0))>=75,(E27+IF(ISNUMBER(F27),F27,0))<75),VLOOKUP((E30+IF(ISNUMBER(F30),F30,0))-75,AD_2B8BC!A:B,2,TRUE),VLOOKUP(MIN(((E27+IF(ISNUMBER(F27),F27,0))-75)+((E30+IF(ISNUMBER(F30),F30,0))-75),80),AD_2B8BC!A:B,2,TRUE))))) | H25: 0 | I25: 0 | J25: =IF(E25="","",MIN(MAX(E25+IF(ISNUMBER(F25),F25,0)+IF(ISNUMBER(G25),G25,0)+IF(ISNUMBER(H25),H25,0)+IF(ISNUMBER(I25),I25,0),0),115)) | K25: =IF(J25="","",IF(J25>=85,"PROMINENT/PATHOLOGICAL",IF(J25>=75,"PRESENT/TRAIT LEVEL",IF(J25>=60,"Suggestive","Normal/Not Significant"))))
A26: P | B26: Paranoid | C26: Severe Personality Pathology | D26: =Raw_Scores!F21 | F26: =IF(D10="","",VLOOKUP(MIN(MAX(D10,0),199),Disclosure_Table!A:C,3,TRUE)) | G26: N/A | H26: 0 | I26: 0 | J26: =IF(E26="","",MIN(MAX(E26+IF(ISNUMBER(F26),F26,0)+IF(ISNUMBER(G26),G26,0)+IF(ISNUMBER(H26),H26,0)+IF(ISNUMBER(I26),I26,0),0),115)) | K26: =IF(J26="","",IF(J26>=85,"PROMINENT/PATHOLOGICAL",IF(J26>=75,"PRESENT/TRAIT LEVEL",IF(J26>=60,"Suggestive","Normal/Not Significant"))))
A27: A | B27: Anxiety | C27: Clinical Syndromes | D27: =Raw_Scores!F22 | F27: =IF(D10="","",VLOOKUP(MIN(MAX(D10,0),199),Disclosure_Table!A:C,3,TRUE)) | G27: N/A | H27: 0 | I27: 0 | J27: =IF(E27="","",MIN(MAX(E27+IF(ISNUMBER(F27),F27,0)+IF(ISNUMBER(G27),G27,0)+IF(ISNUMBER(H27),H27,0)+IF(ISNUMBER(I27),I27,0),0),115)) | K27: =IF(J27="","",IF(J27>=85,"PROMINENT/PATHOLOGICAL",IF(J27>=75,"PRESENT/TRAIT LEVEL",IF(J27>=60,"Suggestive","Normal/Not Significant"))))
A28: H | B28: Somatoform | C28: Clinical Syndromes | D28: =Raw_Scores!F23 | F28: =IF(D10="","",VLOOKUP(MIN(MAX(D10,0),199),Disclosure_Table!A:C,3,TRUE)) | G28: N/A | H28: 0 | I28: 0 | J28: =IF(E28="","",MIN(MAX(E28+IF(ISNUMBER(F28),F28,0)+IF(ISNUMBER(G28),G28,0)+IF(ISNUMBER(H28),H28,0)+IF(ISNUMBER(I28),I28,0),0),115)) | K28: =IF(J28="","",IF(J28>=85,"PROMINENT/PATHOLOGICAL",IF(J28>=75,"PRESENT/TRAIT LEVEL",IF(J28>=60,"Suggestive","Normal/Not Significant"))))
A29: N | B29: Bipolar: Manic | C29: Clinical Syndromes | D29: =Raw_Scores!F24 | F29: =IF(D10="","",VLOOKUP(MIN(MAX(D10,0),199),Disclosure_Table!A:C,3,TRUE)) | G29: N/A | H29: 0 | I29: 0 | J29: =IF(E29="","",MIN(MAX(E29+IF(ISNUMBER(F29),F29,0)+IF(ISNUMBER(G29),G29,0)+IF(ISNUMBER(H29),H29,0)+IF(ISNUMBER(I29),I29,0),0),115)) | K29: =IF(J29="","",IF(J29>=85,"PROMINENT/PATHOLOGICAL",IF(J29>=75,"PRESENT/TRAIT LEVEL",IF(J29>=60,"Suggestive","Normal/Not Significant"))))
A30: D | B30: Dysthymia | C30: Clinical Syndromes | D30: =Raw_Scores!F25 | F30: =IF(D10="","",VLOOKUP(MIN(MAX(D10,0),199),Disclosure_Table!A:C,3,TRUE)) | G30: N/A | H30: 0 | I30: 0 | J30: =IF(E30="","",MIN(MAX(E30+IF(ISNUMBER(F30),F30,0)+IF(ISNUMBER(G30),G30,0)+IF(ISNUMBER(H30),H30,0)+IF(ISNUMBER(I30),I30,0),0),115)) | K30: =IF(J30="","",IF(J30>=85,"PROMINENT/PATHOLOGICAL",IF(J30>=75,"PRESENT/TRAIT LEVEL",IF(J30>=60,"Suggestive","Normal/Not Significant"))))
A31: B | B31: Alcohol Dependence | C31: Clinical Syndromes | D31: =Raw_Scores!F26 | F31: =IF(D10="","",VLOOKUP(MIN(MAX(D10,0),199),Disclosure_Table!A:C,3,TRUE)) | G31: N/A | H31: 0 | I31: 0 | J31: =IF(E31="","",MIN(MAX(E31+IF(ISNUMBER(F31),F31,0)+IF(ISNUMBER(G31),G31,0)+IF(ISNUMBER(H31),H31,0)+IF(ISNUMBER(I31),I31,0),0),115)) | K31: =IF(J31="","",IF(J31>=85,"PROMINENT/PATHOLOGICAL",IF(J31>=75,"PRESENT/TRAIT LEVEL",IF(J31>=60,"Suggestive","Normal/Not Significant"))))
A32: T | B32: Drug Dependence | C32: Clinical Syndromes | D32: =Raw_Scores!F27 | F32: =IF(D10="","",VLOOKUP(MIN(MAX(D10,0),199),Disclosure_Table!A:C,3,TRUE)) | G32: N/A | H32: 0 | I32: 0 | J32: =IF(E32="","",MIN(MAX(E32+IF(ISNUMBER(F32),F32,0)+IF(ISNUMBER(G32),G32,0)+IF(ISNUMBER(H32),H32,0)+IF(ISNUMBER(I32),I32,0),0),115)) | K32: =IF(J32="","",IF(J32>=85,"PROMINENT/PATHOLOGICAL",IF(J32>=75,"PRESENT/TRAIT LEVEL",IF(J32>=60,"Suggestive","Normal/Not Significant"))))
A33: R | B33: PTSD | C33: Clinical Syndromes | D33: =Raw_Scores!F28 | F33: =IF(D10="","",VLOOKUP(MIN(MAX(D10,0),199),Disclosure_Table!A:C,3,TRUE)) | G33: N/A | H33: 0 | I33: 0 | J33: =IF(E33="","",MIN(MAX(E33+IF(ISNUMBER(F33),F33,0)+IF(ISNUMBER(G33),G33,0)+IF(ISNUMBER(H33),H33,0)+IF(ISNUMBER(I33),I33,0),0),115)) | K33: =IF(J33="","",IF(J33>=85,"PROMINENT/PATHOLOGICAL",IF(J33>=75,"PRESENT/TRAIT LEVEL",IF(J33>=60,"Suggestive","Normal/Not Significant"))))
A34: SS | B34: Thought Disorder | C34: Severe Clinical Syndromes | D34: =Raw_Scores!F29 | F34: =IF(D10="","",VLOOKUP(MIN(MAX(D10,0),199),Disclosure_Table!A:C,3,TRUE)) | G34: N/A | H34: =IF(Item_Responses!B6="Y",IF(Item_Responses!E6<1,6,IF(Item_Responses!E6<=4,4,0)),0) | I34: 0 | J34: =IF(E34="","",MIN(MAX(E34+IF(ISNUMBER(F34),F34,0)+IF(ISNUMBER(G34),G34,0)+IF(ISNUMBER(H34),H34,0)+IF(ISNUMBER(I34),I34,0),0),115)) | K34: =IF(J34="","",IF(J34>=85,"PROMINENT/PATHOLOGICAL",IF(J34>=75,"PRESENT/TRAIT LEVEL",IF(J34>=60,"Suggestive","Normal/Not Significant"))))
A35: CC | B35: Major Depression | C35: Severe Clinical Syndromes | D35: =Raw_Scores!F30 | F35: =IF(D10="","",VLOOKUP(MIN(MAX(D10,0),199),Disclosure_Table!A:C,3,TRUE)) | G35: N/A | H35: =IF(Item_Responses!B6="Y",IF(Item_Responses!E6<1,10,IF(Item_Responses!E6<=4,8,0)),0) | I35: 0 | J35: =IF(E35="","",MIN(MAX(E35+IF(ISNUMBER(F35),F35,0)+IF(ISNUMBER(G35),G35,0)+IF(ISNUMBER(H35),H35,0)+IF(ISNUMBER(I35),I35,0),0),115)) | K35: =IF(J35="","",IF(J35>=85,"PROMINENT/PATHOLOGICAL",IF(J35>=75,"PRESENT/TRAIT LEVEL",IF(J35>=60,"Suggestive","Normal/Not Significant"))))
A36: PP | B36: Delusional Disorder | C36: Severe Clinical Syndromes | D36: =Raw_Scores!F31 | F36: =IF(D10="","",VLOOKUP(MIN(MAX(D10,0),199),Disclosure_Table!A:C,3,TRUE)) | G36: N/A | H36: =IF(Item_Responses!B6="Y",IF(Item_Responses!E6<1,4,IF(Item_Responses!E6<=4,2,0)),0) | I36: 0 | J36: =IF(E36="","",MIN(MAX(E36+IF(ISNUMBER(F36),F36,0)+IF(ISNUMBER(G36),G36,0)+IF(ISNUMBER(H36),H36,0)+IF(ISNUMBER(I36),I36,0),0),115)) | K36: =IF(J36="","",IF(J36>=85,"PROMINENT/PATHOLOGICAL",IF(J36>=75,"PRESENT/TRAIT LEVEL",IF(J36>=60,"Suggestive","Normal/Not Significant"))))

Sheet Grossman_Facets
A1: MCMI-III GROSSMAN FACET SCALE SCORES
A2: Facet scores calculated automatically from item responses
A4: Parent Scale | B4: Facet Code | C4: Facet Name | D4: Items | E4: Raw Score | F4: Interpretation
A5: 1 - Schizoid | B5: 1A | C5: Expressively Impassive | D5: [1, 14, 40, 70, 112] | E5: =Item_Responses!B9+Item_Responses!B22+Item_Responses!B48+Item_Responses!E18+Item_Responses!E60 | F5: =IF(E5="","",IF(E5>=5*0.7,"Elevated",IF(E5>=5*0.4,"Moderate","Low")))
A6: 1 - Schizoid | B6: 1B | C6: Interpersonally Unengaged | D6: [25, 46, 81, 118, 136] | E6: =Item_Responses!B33+Item_Responses!B54+Item_Responses!E29+Item_Responses!E66+Item_Responses!H24 | F6: =IF(E6="","",IF(E6>=5*0.7,"Elevated",IF(E6>=5*0.4,"Moderate","Low")))
A7: 1 - Schizoid | B7: 1C | C7: Cognitively Impoverished | D7: [55, 86, 92, 124, 130] | E7: =Item_Responses!B63+Item_Responses!E34+Item_Responses!E40+Item_Responses!H12+Item_Responses!H18 | F7: =IF(E7="","",IF(E7>=5*0.7,"Elevated",IF(E7>=5*0.4,"Moderate","Low")))
A8: 2A - Avoidant | B8: 2A-A | C8: Expressively Fretful | D8: [1, 14, 40, 70, 112] | E8: =Item_Responses!B9+Item_Responses!B22+Item_Responses!B48+Item_Responses!E18+Item_Responses!E60 | F8: =IF(E8="","",IF(E8>=5*0.7,"Elevated",IF(E8>=5*0.4,"Moderate","Low")))
A9: 2A - Avoidant | B9: 2A-B | C9: Interpersonally Aversive | D9: [25, 46, 81, 118, 135] | E9: =Item_Responses!B33+Item_Responses!B54+Item_Responses!E29+Item_Responses!E66+Item_Responses!H23 | F9: =IF(E9="","",IF(E9>=5*0.7,"Elevated",IF(E9>=5*0.4,"Moderate","Low")))
A10: 2A - Avoidant | B10: 2A-C | C10: Cognitively Distracted | D10: [55, 86, 92, 124, 141] | E10: =Item_Responses!B63+Item_Responses!E34+Item_Responses!E40+Item_Responses!H12+Item_Responses!H29 | F10: =IF(E10="","",IF(E10>=5*0.7,"Elevated",IF(E10>=5*0.4,"Moderate","Low")))
A11: 2B - Depressive | B11: 2B-A | C11: Expressively Disconsolate | D11: [10, 24, 50, 75, 121] | E11: =Item_Responses!B18+Item_Responses!B32+Item_Responses!B58+Item_Responses!E23+Item_Responses!H9 | F11: =IF(E11="","",IF(E11>=5*0.7,"Elevated",IF(E11>=5*0.4,"Moderate","Low")))
A12: 2B - Depressive | B12: 2B-B | C12: Interpersonally Defenseless | D12: [31, 62, 99, 135, 160] | E12: =Item_Responses!B39+Item_Responses!E10+Item_Responses!E47+Item_Responses!H23+Item_Responses!H48 | F12: =IF(E12="","",IF(E12>=5*0.7,"Elevated",IF(E12>=5*0.4,"Moderate","Low")))
A13: 2B - Depressive | B13: 2B-C | C13: Cognitively Fatalistic | D13: [14, 55, 92, 130, 166] | E13: =Item_Responses!B22+Item_Responses!B63+Item_Responses!E40+Item_Responses!H18+Item_Responses!H54 | F13: =IF(E13="","",IF(E13>=5*0.7,"Elevated",IF(E13>=5*0.4,"Moderate","Low")))
A14: 3 - Dependent | B14: 3A | C14: Expressively Incompetent | D14: [4, 17, 34, 52, 74] | E14: =Item_Responses!B12+Item_Responses!B25+Item_Responses!B42+Item_Responses!B60+Item_Responses!E22 | F14: =IF(E14="","",IF(E14>=5*0.7,"Elevated",IF(E14>=5*0.4,"Moderate","Low")))
A15: 3 - Dependent | B15: 3B | C15: Interpersonally Submissive | D15: [10, 29, 58, 79, 103] | E15: =Item_Responses!B18+Item_Responses!B37+Item_Responses!B66+Item_Responses!E27+Item_Responses!E51 | F15: =IF(E15="","",IF(E15>=5*0.7,"Elevated",IF(E15>=5*0.4,"Moderate","Low")))
A16: 3 - Dependent | B16: 3C | C16: Cognitively Naive | D16: [24, 46, 66, 91, 115] | E16: =Item_Responses!B32+Item_Responses!B54+Item_Responses!E14+Item_Responses!E39+Item_Responses!E63 | F16: =IF(E16="","",IF(E16>=5*0.7,"Elevated",IF(E16>=5*0.4,"Moderate","Low")))
A17: 4 - Histrionic | B17: 4A | C17: Expressively Dramatic | D17: [2, 23, 48, 76, 108] | E17: =Item_Responses!B10+Item_Responses!B31+Item_Responses!B56+Item_Responses!E24+Item_Responses!E56 | F17: =IF(E17="","",IF(E17>=5*0.7,"Elevated",IF(E17>=5*0.4,"Moderate","Low")))
A18: 4 - Histrionic | B18: 4B | C18: Interpersonally Attention-Seeking | D18: [8, 36, 63, 88, 120] | E18: =Item_Responses!B16+Item_Responses!B44+Item_Responses!E11+Item_Responses!E36+Item_Responses!E68 | F18: =IF(E18="","",IF(E18>=5*0.7,"Elevated",IF(E18>=5*0.4,"Moderate","Low")))
A19: 4 - Histrionic | B19: 4C | C19: Cognitively Flighty | D19: [16, 41, 68, 95, 132] | E19: =Item_Responses!B24+Item_Responses!B49+Item_Responses!E16+Item_Responses!E43+Item_Responses!H20 | F19: =IF(E19="","",IF(E19>=5*0.7,"Elevated",IF(E19>=5*0.4,"Moderate","Low")))
A20: 5 - Narcissistic | B20: 5A | C20: Expressively Haughty | D20: [2, 23, 48, 76, 108] | E20: =Item_Responses!B10+Item_Responses!B31+Item_Responses!B56+Item_Responses!E24+Item_Responses!E56 | F20: =IF(E20="","",IF(E20>=5*0.7,"Elevated",IF(E20>=5*0.4,"Moderate","Low")))
A21: 5 - Narcissistic | B21: 5B | C21: Interpersonally Exploitative | D21: [8, 30, 63, 88, 114] | E21: =Item_Responses!B16+Item_Responses!B38+Item_Responses!E11+Item_Responses!E36+Item_Responses!E62 | F21: =IF(E21="","",IF(E21>=5*0.7,"Elevated",IF(E21>=5*0.4,"Moderate","Low")))
A22: 5 - Narcissistic | B22: 5C | C22: Cognitively Expansive | D22: [16, 41, 68, 95, 132] | E22: =Item_Responses!B24+Item_Responses!B49+Item_Responses!E16+Item_Responses!E43+Item_Responses!H20 | F22: =IF(E22="","",IF(E22>=5*0.7,"Elevated",IF(E22>=5*0.4,"Moderate","Low")))
A23: 6A - Antisocial | B23: 6A-A | C23: Expressively Impulsive | D23: [5, 21, 42, 64, 87] | E23: =Item_Responses!B13+Item_Responses!B29+Item_Responses!B50+Item_Responses!E12+Item_Responses!E35 | F23: =IF(E23="","",IF(E23>=5*0.7,"Elevated",IF(E23>=5*0.4,"Moderate","Low")))
A24: 6A - Antisocial | B24: 6A-B | C24: Interpersonally Irresponsible | D24: [15, 35, 60, 82, 106] | E24: =Item_Responses!B23+Item_Responses!B43+Item_Responses!B68+Item_Responses!E30+Item_Responses!E54 | F24: =IF(E24="","",IF(E24>=5*0.7,"Elevated",IF(E24>=5*0.4,"Moderate","Low")))
A25: 6A - Antisocial | B25: 6A-C | C25: Cognitively Deviant | D25: [27, 44, 69, 93, 117] | E25: =Item_Responses!B35+Item_Responses!B52+Item_Responses!E17+Item_Responses!E41+Item_Responses!E65 | F25: =IF(E25="","",IF(E25>=5*0.7,"Elevated",IF(E25>=5*0.4,"Moderate","Low")))
A26: 6B - Sadistic (Aggressive) | B26: 6B-A | C26: Expressively Precipitate | D26: [5, 21, 42, 64, 87] | E26: =Item_Responses!B13+Item_Responses!B29+Item_Responses!B50+Item_Responses!E12+Item_Responses!E35 | F26: =IF(E26="","",IF(E26>=5*0.7,"Elevated",IF(E26>=5*0.4,"Moderate","Low")))
A27: 6B - Sadistic (Aggressive) | B27: 6B-B | C27: Interpersonally Abrasive | D27: [15, 35, 60, 82, 106] | E27: =Item_Responses!B23+Item_Responses!B43+Item_Responses!B68+Item_Responses!E30+Item_Responses!E54 | F27: =IF(E27="","",IF(E27>=5*0.7,"Elevated",IF(E27>=5*0.4,"Moderate","Low")))
A28: 6B - Sadistic (Aggressive) | B28: 6B-C | C28: Cognitively Dogmatic | D28: [27, 44, 69, 93, 117] | E28: =Item_Responses!B35+Item_Responses!B52+Item_Responses!E17+Item_Responses!E41+Item_Responses!E65 | F28: =IF(E28="","",IF(E28>=5*0.7,"Elevated",IF(E28>=5*0.4,"Moderate","Low")))
A29: 7 - Compulsive | B29: 7A | C29: Expressively Disciplined | D29: [2, 16, 41, 68, 105] | E29: =Item_Responses!B10+Item_Responses!B24+Item_Responses!B49+Item_Responses!E16+Item_Responses!E53 | F29: =IF(E29="","",IF(E29>=5*0.7,"Elevated",IF(E29>=5*0.4,"Moderate","Low")))
A30: 7 - Compulsive | B30: 7B | C30: Interpersonally Respectful | D30: [8, 36, 57, 78] | E30: =Item_Responses!B16+Item_Responses!B44+Item_Responses!B65+Item_Responses!E26 | F30: =IF(E30="","",IF(E30>=4*0.7,"Elevated",IF(E30>=4*0.4,"Moderate","Low")))
A31: 7 - Compulsive | B31: 7C | C31: Cognitively Constricted | D31: [2, 8, 16, 36, 41] | E31: =Item_Responses!B10+Item_Responses!B16+Item_Responses!B24+Item_Responses!B44+Item_Responses!B49 | F31: =IF(E31="","",IF(E31>=5*0.7,"Elevated",IF(E31>=5*0.4,"Moderate","Low")))
A32: 8A - Negativistic (Passive-Aggressive) | B32: 8A-A | C32: Expressively Resentful | D32: [7, 30, 51, 75, 100] | E32: =Item_Responses!B15+Item_Responses!B38+Item_Responses!B59+Item_Responses!E23+Item_Responses!E48 | F32: =IF(E32="","",IF(E32>=5*0.7,"Elevated",IF(E32>=5*0.4,"Moderate","Low")))
A33: 8A - Negativistic (Passive-Aggressive) | B33: 8A-B | C33: Interpersonally Contrary | D33: [37, 56, 80, 104, 125] | E33: =Item_Responses!B45+Item_Responses!B64+Item_Responses!E28+Item_Responses!E52+Item_Responses!H13 | F33: =IF(E33="","",IF(E33>=5*0.7,"Elevated",IF(E33>=5*0.4,"Moderate","Low")))
A34: 8A - Negativistic (Passive-Aggressive) | B34: 8A-C | C34: Cognitively Skeptical | D34: [66, 85, 96, 113, 137] | E34: =Item_Responses!E14+Item_Responses!E33+Item_Responses!E44+Item_Responses!E61+Item_Responses!H25 | F34: =IF(E34="","",IF(E34>=5*0.7,"Elevated",IF(E34>=5*0.4,"Moderate","Low")))
A35: 8B - Masochistic (Self-Defeating) | B35: 8B-A | C35: Expressively Abstinent | D35: [10, 50, 89, 121, 151] | E35: =Item_Responses!B18+Item_Responses!B58+Item_Responses!E37+Item_Responses!H9+Item_Responses!H39 | F35: =IF(E35="","",IF(E35>=5*0.7,"Elevated",IF(E35>=5*0.4,"Moderate","Low")))
A36: 8B - Masochistic (Self-Defeating) | B36: 8B-B | C36: Interpersonally Deferential | D36: [24, 62, 97, 133, 164] | E36: =Item_Responses!B32+Item_Responses!E10+Item_Responses!E45+Item_Responses!H21+Item_Responses!H52 | F36: =IF(E36="","",IF(E36>=5*0.7,"Elevated",IF(E36>=5*0.4,"Moderate","Low")))
A37: 8B - Masochistic (Self-Defeating) | B37: 8B-C | C37: Cognitively Diffident | D37: [31, 75, 107, 139, 172] | E37: =Item_Responses!B39+Item_Responses!E23+Item_Responses!E55+Item_Responses!H27+Item_Responses!H60 | F37: =IF(E37="","",IF(E37>=5*0.7,"Elevated",IF(E37>=5*0.4,"Moderate","Low")))

Sheet Inconsistency_W
A1: MCMI-III INCONSISTENCY SCALE (W)
A2: Counts item pairs where responses are inconsistent
A4: Pair # | B4: Item A | C4: Item B | D4: Response A | E4: Response B | F4: Inconsistent?
A5: 1 | B5: 5 | C5: 105 | D5: =Item_Responses!B13 | E5: =Item_Responses!E53 | F5: =IF(OR(AND(Item_Responses!B13=1,Item_Responses!E53=1),AND(Item_Responses!B13=0,Item_Responses!E53=0)),1,0)
A6: 2 | B6: 6 | C6: 86 | D6: =Item_Responses!B14 | E6: =Item_Responses!E34 | F6: =IF(OR(AND(Item_Responses!B14=1,Item_Responses!E34=1),AND(Item_Responses!B14=0,Item_Responses!E34=0)),1,0)
A7: 3 | B7: 14 | C7: 55 | D7: =Item_Responses!B22 | E7: =Item_Responses!B63 | F7: =IF(OR(AND(Item_Responses!B22=1,Item_Responses!B63=1),AND(Item_Responses!B22=0,Item_Responses!B63=0)),1,0)
A8: 4 | B8: 15 | C8: 78 | D8: =Item_Responses!B23 | E8: =Item_Responses!E26 | F8: =IF(OR(AND(Item_Responses!B23=1,Item_Responses!E26=1),AND(Item_Responses!B23=0,Item_Responses!E26=0)),1,0)
A9: 5 | B9: 21 | C9: 57 | D9: =Item_Responses!B29 | E9: =Item_Responses!B65 | F9: =IF(OR(AND(Item_Responses!B29=1,Item_Responses!B65=1),AND(Item_Responses!B29=0,Item_Responses!B65=0)),1,0)
A10: 6 | B10: 27 | C10: 68 | D10: =Item_Responses!B35 | E10: =Item_Responses!E16 | F10: =IF(OR(AND(Item_Responses!B35=1,Item_Responses!E16=1),AND(Item_Responses!B35=0,Item_Responses!E16=0)),1,0)
A11: 7 | B11: 31 | C11: 95 | D11: =Item_Responses!B39 | E11: =Item_Responses!E43 | F11: =IF(OR(AND(Item_Responses!B39=1,Item_Responses!E43=1),AND(Item_Responses!B39=0,Item_Responses!E43=0)),1,0)
A12: 8 | B12: 34 | C12: 114 | D12: =Item_Responses!B42 | E12: =Item_Responses!E62 | F12: =IF(OR(AND(Item_Responses!B42=1,Item_Responses!E62=1),AND(Item_Responses!B42=0,Item_Responses!E62=0)),1,0)
A13: 9 | B13: 35 | C13: 36 | D13: =Item_Responses!B43 | E13: =Item_Responses!B44 | F13: =IF(OR(AND(Item_Responses!B43=1,Item_Responses!B44=1),AND(Item_Responses!B43=0,Item_Responses!B44=0)),1,0)
A14: 10 | B14: 37 | C14: 101 | D14: =Item_Responses!B45 | E14: =Item_Responses!E49 | F14: =IF(OR(AND(Item_Responses!B45=1,Item_Responses!E49=1),AND(Item_Responses!B45=0,Item_Responses!E49=0)),1,0)
A15: 11 | B15: 40 | C15: 63 | D15: =Item_Responses!B48 | E15: =Item_Responses!E11 | F15: =IF(OR(AND(Item_Responses!B48=1,Item_Responses!E11=1),AND(Item_Responses!B48=0,Item_Responses!E11=0)),1,0)
A16: 12 | B16: 42 | C16: 132 | D16: =Item_Responses!B50 | E16: =Item_Responses!H20 | F16: =IF(OR(AND(Item_Responses!B50=1,Item_Responses!H20=1),AND(Item_Responses!B50=0,Item_Responses!H20=0)),1,0)
A17: 13 | B17: 44 | C17: 120 | D17: =Item_Responses!B52 | E17: =Item_Responses!E68 | F17: =IF(OR(AND(Item_Responses!B52=1,Item_Responses!E68=1),AND(Item_Responses!B52=0,Item_Responses!E68=0)),1,0)
A18: 14 | B18: 46 | C18: 88 | D18: =Item_Responses!B54 | E18: =Item_Responses!E36 | F18: =IF(OR(AND(Item_Responses!B54=1,Item_Responses!E36=1),AND(Item_Responses!B54=0,Item_Responses!E36=0)),1,0)
A19: 15 | B19: 50 | C19: 144 | D19: =Item_Responses!B58 | E19: =Item_Responses!H32 | F19: =IF(OR(AND(Item_Responses!B58=1,Item_Responses!H32=1),AND(Item_Responses!B58=0,Item_Responses!H32=0)),1,0)
A20: 16 | B20: 51 | C20: 138 | D20: =Item_Responses!B59 | E20: =Item_Responses!H26 | F20: =IF(OR(AND(Item_Responses!B59=1,Item_Responses!H26=1),AND(Item_Responses!B59=0,Item_Responses!H26=0)),1,0)
A21: 17 | B21: 53 | C21: 76 | D21: =Item_Responses!B61 | E21: =Item_Responses!E24 | F21: =IF(OR(AND(Item_Responses!B61=1,Item_Responses!E24=1),AND(Item_Responses!B61=0,Item_Responses!E24=0)),1,0)
A22: 18 | B22: 54 | C22: 150 | D22: =Item_Responses!B62 | E22: =Item_Responses!H38 | F22: =IF(OR(AND(Item_Responses!B62=1,Item_Responses!H38=1),AND(Item_Responses!B62=0,Item_Responses!H38=0)),1,0)
A23: 19 | B23: 56 | C23: 162 | D23: =Item_Responses!B64 | E23: =Item_Responses!H50 | F23: =IF(OR(AND(Item_Responses!B64=1,Item_Responses!H50=1),AND(Item_Responses!B64=0,Item_Responses!H50=0)),1,0)
A24: 20 | B24: 58 | C24: 156 | D24: =Item_Responses!B66 | E24: =Item_Responses!H44 | F24: =IF(OR(AND(Item_Responses!B66=1,Item_Responses!H44=1),AND(Item_Responses!B66=0,Item_Responses!H44=0)),1,0)
A25: 21 | B25: 60 | C25: 168 | D25: =Item_Responses!B68 | E25: =Item_Responses!H56 | F25: =IF(OR(AND(Item_Responses!B68=1,Item_Responses!H56=1),AND(Item_Responses!B68=0,Item_Responses!H56=0)),1,0)
A26: 22 | B26: 62 | C26: 174 | D26: =Item_Responses!E10 | E26: =Item_Responses!H62 | F26: =IF(OR(AND(Item_Responses!E10=1,Item_Responses!H62=1),AND(Item_Responses!E10=0,Item_Responses!H62=0)),1,0)
A27: 23 | B27: 64 | C27: 126 | D27: =Item_Responses!E12 | E27: =Item_Responses!H14 | F27: =IF(OR(AND(Item_Responses!E12=1,Item_Responses!H14=1),AND(Item_Responses!E12=0,Item_Responses!H14=0)),1,0)
A28: 24 | B28: 66 | C28: 108 | D28: =Item_Responses!E14 | E28: =Item_Responses!E56 | F28: =IF(OR(AND(Item_Responses!E14=1,Item_Responses!E56=1),AND(Item_Responses!E14=0,Item_Responses!E56=0)),1,0)
A29: 25 | B29: 69 | C29: 83 | D29: =Item_Responses!E17 | E29: =Item_Responses!E31 | F29: =IF(OR(AND(Item_Responses!E17=1,Item_Responses!E31=1),AND(Item_Responses!E17=0,Item_Responses!E31=0)),1,0)
A31: TOTAL W SCORE: | F31: =SUM(F5:F29)
A32: Interpretation: | B32: =IF(F31>12,"INVALID - W too high (>12), consider random responding",IF(F31>8,"CAUTION - Elevated inconsistency","VALID - Acceptable consistency"))

Sheet Profile_Summary
A1: MCMI-III PROFILE SUMMARY
A2: Summary of all scales with final BR scores and clinical interpretation
A4: Patient: | B4: =Item_Responses!B4 | D4: Date: | E4: =Item_Responses!E4
A5: Validity: | B5: =Scoring_Results!B7
A7: Scale | B7: Name | C7: Final BR | D7: Significance | E7: BR Level
A8: X | B8: Disclosure | C8: =Scoring_Results!J10 | D8: =Scoring_Results!K10 | E8: =IF(C8="","",REPT("|",MIN(INT(C8/5),23)))
A9: Y | B9: Desirability | C9: =Scoring_Results!J11 | D9: =Scoring_Results!K11 | E9: =IF(C9="","",REPT("|",MIN(INT(C9/5),23)))
A10: Z | B10: Debasement | C10: =Scoring_Results!J12 | D10: =Scoring_Results!K12 | E10: =IF(C10="","",REPT("|",MIN(INT(C10/5),23)))
A11: 1 | B11: Schizoid | C11: =Scoring_Results!J13 | D11: =Scoring_Results!K13 | E11: =IF(C11="","",REPT("|",MIN(INT(C11/5),23)))
A12: 2A | B12: Avoidant | C12: =Scoring_Results!J14 | D12: =Scoring_Results!K14 | E12: =IF(C12="","",REPT("|",MIN(INT(C12/5),23)))
A13: 2B | B13: Depressive | C13: =Scoring_Results!J15 | D13: =Scoring_Results!K15 | E13: =IF(C13="","",REPT("|",MIN(INT(C13/5),23)))
A14: 3 | B14: Dependent | C14: =Scoring_Results!J16 | D14: =Scoring_Results!K16 | E14: =IF(C14="","",REPT("|",MIN(INT(C14/5),23)))
A15: 4 | B15: Histrionic | C15: =Scoring_Results!J17 | D15: =Scoring_Results!K17 | E15: =IF(C15="","",REPT("|",MIN(INT(C15/5),23)))
