Workbook

Sheet Patient Information
A1: MCMI-III SCORING SOFTWARE
A2: Millon Clinical Multiaxial Inventory - Third Edition
A4: PATIENT DEMOGRAPHICS
A5: Patient Name: | D5: Case Number:
A6: Age: | D6: Date of Testing:
A7: Gender: | D7: Referred By:
A8: Date of Birth: | D8: Examiner:
A9: Education: | D9: Diagnosis (Provisional):
A10: Marital Status: | D10: Setting:
A11: Occupation: | D11: Reason for Referral:
A13: INSTRUCTIONS
A14: 1. Fill in Patient Information above. 2. Go to "Raw Score Entry" sheet and enter the raw scores for each scale. 3. Go to "BR Scores & Interpretation" sheet - BR scores and interpretations are auto-calculated. 4. Check "Profile Summary" sheet for visual profile and clinical significance overview.
A17: BR SCORE INTERPRETATION GUIDE
A18: BR Score Range | B18: Classification | C18: Clinical Meaning
A19: 0 - 34 | B19: Not Significant | C19: No clinical relevance; trait not present
A20: 35 - 59 | B20: Normal Range | C20: Within normal limits; no clinical concern
A21: 60 - 74 | B21: Suggestive | C21: Mild features present; monitor clinically
A22: 75 - 84 | B22: Trait Level / Presence | C22: Clinically significant trait; syndrome features present
A23: 85 - 115 | B23: Pathological / Disorder | C23: Prominent disorder; syndrome confirmed

Sheet Raw Score Entry
A1: MCMI-III RAW SCORE ENTRY
A2: Enter the Raw Scores for each scale in the highlighted cells (Column D)
A4: Scale Code | B4: Scale Name | C4: Category | D4: Raw Score | E4: Max Possible
A5: MODIFYING INDICES
A6: X | B6: Disclosure | C6: Modifying Index | E6: 645
A7: Y | B7: Desirability | C7: Modifying Index | E7: 21
A8: Z | B8: Debasement | C8: Modifying Index | E8: 33
A9: V | B9: Invalidity | C9: Modifying Index | E9: 3
A11: CLINICAL PERSONALITY PATTERNS
A12: 1 | B12: Schizoid | C12: Clinical Personality
A13: 2A | B13: Avoidant | C13: Clinical Personality
A14: 2B | B14: Depressive | C14: Clinical Personality
A15: 3 | B15: Dependent | C15: Clinical Personality
A16: 4 | B16: Histrionic | C16: Clinical Personality
A17: 5 | B17: Narcissistic | C17: Clinical Personality
A18: 6A | B18: Antisocial | C18: Clinical Personality
A19: 6B | B19: Sadistic (Aggressive) | C19: Clinical Personality
A20: 7 | B20: Compulsive | C20: Clinical Personality
A21: 8A | B21: Negativistic (Passive-Aggressive) | C21: Clinical Personality
A22: 8B | B22: Masochistic (Self-Defeating) | C22: Clinical Personality
A24: SEVERE PERSONALITY PATHOLOGY
A25: S | B25: Schizotypal | C25: Severe Personality
A26: C | B26: Borderline | C26: Severe Personality
A27: P | B27: Paranoid | C27: Severe Personality
A29: CLINICAL SYNDROMES
A30: A | B30: Anxiety | C30: Clinical Syndrome
A31: H | B31: Somatoform | C31: Clinical Syndrome
A32: N | B32: Bipolar: Manic | C32: Clinical Syndrome
A33: D | B33: Dysthymia | C33: Clinical Syndrome
A34: B | B34: Alcohol Dependence | C34: Clinical Syndrome
A35: T | B35: Drug Dependence | C35: Clinical Syndrome
A36: R | B36: Post-Traumatic Stress Disorder | C36: Clinical Syndrome
A38: SEVERE CLINICAL SYNDROMES
A39: SS | B39: Thought Disorder | C39: Severe Clinical
A40: CC | B40: Major Depression | C40: Severe Clinical
A41: PP | B41: Delusional Disorder | C41: Severe Clinical

Sheet BR Scores & Interpretation
A1: MCMI-III BR SCORES & CLINICAL INTERPRETATION
A2: Enter BR Scores in Column D. Clinical Significance is auto-calculated.
A4: Scale Code | B4: Scale Name | C4: Category | D4: BR Score | E4: Clinical Significance | F4: Interpretation Level | G4: Description
A5: MODIFYING INDICES
A6: X | B6: Disclosure | C6: Modifying Index | E6: =IF(D6="","",IF(D6>=85,"Pathological Level / Disorder",IF(D6>=75,"Trait Level / Presence of Syndrome",IF(D6>=60,"Suggestive (Monitor)",IF(D6>=35,"Normal Range","Not Significant"))))) | F6: =IF(D6="",0,IF(D6>=85,4,IF(D6>=75,3,IF(D6>=60,2,IF(D6>=35,1,0))))) | G6: Openness/willingness to reveal personal information
A7: Y | B7: Desirability | C7: Modifying Index | E7: =IF(D7="","",IF(D7>=85,"Pathological Level / Disorder",IF(D7>=75,"Trait Level / Presence of Syndrome",IF(D7>=60,"Suggestive (Monitor)",IF(D7>=35,"Normal Range","Not Significant"))))) | F7: =IF(D7="",0,IF(D7>=85,4,IF(D7>=75,3,IF(D7>=60,2,IF(D7>=35,1,0))))) | G7: Tendency to present oneself in a favorable light
A8: Z | B8: Debasement | C8: Modifying Index | E8: =IF(D8="","",IF(D8>=85,"Pathological Level / Disorder",IF(D8>=75,"Trait Level / Presence of Syndrome",IF(D8>=60,"Suggestive (Monitor)",IF(D8>=35,"Normal Range","Not Significant"))))) | F8: =IF(D8="",0,IF(D8>=85,4,IF(D8>=75,3,IF(D8>=60,2,IF(D8>=35,1,0))))) | G8: Tendency to deprecate or devalue oneself
A9: V | B9: Invalidity | C9: Modifying Index | E9: =IF(D9="","",IF(D9>=85,"Pathological Level / Disorder",IF(D9>=75,"Trait Level / Presence of Syndrome",IF(D9>=60,"Suggestive (Monitor)",IF(D9>=35,"Normal Range","Not Significant"))))) | F9: =IF(D9="",0,IF(D9>=85,4,IF(D9>=75,3,IF(D9>=60,2,IF(D9>=35,1,0))))) | G9: Random or confused responding (>1 invalidates)
A11: CLINICAL PERSONALITY PATTERNS
A12: 1 | B12: Schizoid | C12: Clinical Personality | E12: =IF(D12="","",IF(D12>=85,"Pathological Level / Disorder",IF(D12>=75,"Trait Level / Presence of Syndrome",IF(D12>=60,"Suggestive (Monitor)",IF(D12>=35,"Normal Range","Not Significant"))))) | F12: =IF(D12="",0,IF(D12>=85,4,IF(D12>=75,3,IF(D12>=60,2,IF(D12>=35,1,0))))) | G12: Emotional detachment, social withdrawal, limited affect
A13: 2A | B13: Avoidant | C13: Clinical Personality | E13: =IF(D13="","",IF(D13>=85,"Pathological Level / Disorder",IF(D13>=75,"Trait Level / Presence of Syndrome",IF(D13>=60,"Suggestive (Monitor)",IF(D13>=35,"Normal Range","Not Significant"))))) | F13: =IF(D13="",0,IF(D13>=85,4,IF(D13>=75,3,IF(D13>=60,2,IF(D13>=35,1,0))))) | G13: Social inhibition, fear of rejection, hypersensitivity
A14: 2B | B14: Depressive | C14: Clinical Personality | E14: =IF(D14="","",IF(D14>=85,"Pathological Level / Disorder",IF(D14>=75,"Trait Level / Presence of Syndrome",IF(D14>=60,"Suggestive (Monitor)",IF(D14>=35,"Normal Range","Not Significant"))))) | F14: =IF(D14="",0,IF(D14>=85,4,IF(D14>=75,3,IF(D14>=60,2,IF(D14>=35,1,0))))) | G14: Chronic pessimism, low mood, hopelessness
A15: 3 | B15: Dependent | C15: Clinical Personality | E15: =IF(D15="","",IF(D15>=85,"Pathological Level / Disorder",IF(D15>=75,"Trait Level / Presence of Syndrome",IF(D15>=60,"Suggestive (Monitor)",IF(D15>=35,"Normal Range","Not Significant"))))) | F15: =IF(D15="",0,IF(D15>=85,4,IF(D15>=75,3,IF(D15>=60,2,IF(D15>=35,1,0))))) | G15: Submissiveness, need for reassurance, clinging behavior
A16: 4 | B16: Histrionic | C16: Clinical Personality | E16: =IF(D16="","",IF(D16>=85,"Pathological Level / Disorder",IF(D16>=75,"Trait Level / Presence of Syndrome",IF(D16>=60,"Suggestive (Monitor)",IF(D16>=35,"Normal Range","Not Significant"))))) | F16: =IF(D16="",0,IF(D16>=85,4,IF(D16>=75,3,IF(D16>=60,2,IF(D16>=35,1,0))))) | G16: Attention-seeking, emotional lability, superficiality
A17: 5 | B17: Narcissistic | C17: Clinical Personality | E17: =IF(D17="","",IF(D17>=85,"Pathological Level / Disorder",IF(D17>=75,"Trait Level / Presence of Syndrome",IF(D17>=60,"Suggestive (Monitor)",IF(D17>=35,"Normal Range","Not Significant"))))) | F17: =IF(D17="",0,IF(D17>=85,4,IF(D17>=75,3,IF(D17>=60,2,IF(D17>=35,1,0))))) | G17: Grandiosity, entitlement, lack of empathy
A18: 6A | B18: Antisocial | C18: Clinical Personality | E18: =IF(D18="","",IF(D18>=85,"Pathological Level / Disorder",IF(D18>=75,"Trait Level / Presence of Syndrome",IF(D18>=60,"Suggestive (Monitor)",IF(D18>=35,"Normal Range","Not Significant"))))) | F18: =IF(D18="",0,IF(D18>=85,4,IF(D18>=75,3,IF(D18>=60,2,IF(D18>=35,1,0))))) | G18: Disregard for rules, impulsivity, exploitation
A19: 6B | B19: Sadistic (Aggressive) | C19: Clinical Personality | E19: =IF(D19="","",IF(D19>=85,"Pathological Level / Disorder",IF(D19>=75,"Trait Level / Presence of Syndrome",IF(D19>=60,"Suggestive (Monitor)",IF(D19>=35,"Normal Range","Not Significant"))))) | F19: =IF(D19="",0,IF(D19>=85,4,IF(D19>=75,3,IF(D19>=60,2,IF(D19>=35,1,0))))) | G19: Hostile, domineering, pleasure in others pain
A20: 7 | B20: Compulsive | C20: Clinical Personality | E20: =IF(D20="","",IF(D20>=85,"Pathological Level / Disorder",IF(D20>=75,"Trait Level / Presence of Syndrome",IF(D20>=60,"Suggestive (Monitor)",IF(D20>=35,"Normal Range","Not Significant"))))) | F20: =IF(D20="",0,IF(D20>=85,4,IF(D20>=75,3,IF(D20>=60,2,IF(D20>=35,1,0))))) | G20: Perfectionism, rigidity, emotional constriction
A21: 8A | B21: Negativistic (Passive-Aggressive) | C21: Clinical Personality | E21: =IF(D21="","",IF(D21>=85,"Pathological Level / Disorder",IF(D21>=75,"Trait Level / Presence of Syndrome",IF(D21>=60,"Suggestive (Monitor)",IF(D21>=35,"Normal Range","Not Significant"))))) | F21: =IF(D21="",0,IF(D21>=85,4,IF(D21>=75,3,IF(D21>=60,2,IF(D21>=35,1,0))))) | G21: Ambivalence, irritability, oppositional behavior
A22: 8B | B22: Masochistic (Self-Defeating) | C22: Clinical Personality | E22: =IF(D22="","",IF(D22>=85,"Pathological Level / Disorder",IF(D22>=75,"Trait Level / Presence of Syndrome",IF(D22>=60,"Suggestive (Monitor)",IF(D22>=35,"Normal Range","Not Significant"))))) | F22: =IF(D22="",0,IF(D22>=85,4,IF(D22>=75,3,IF(D22>=60,2,IF(D22>=35,1,0))))) | G22: Self-sacrifice, acceptance of suffering, guilt
A24: SEVERE PERSONALITY PATHOLOGY
A25: S | B25: Schizotypal | C25: Severe Personality | E25: =IF(D25="","",IF(D25>=85,"Pathological Level / Disorder",IF(D25>=75,"Trait Level / Presence of Syndrome",IF(D25>=60,"Suggestive (Monitor)",IF(D25>=35,"Normal Range","Not Significant"))))) | F25: =IF(D25="",0,IF(D25>=85,4,IF(D25>=75,3,IF(D25>=60,2,IF(D25>=35,1,0))))) | G25: Eccentric behavior, cognitive slippage, social detachment
A26: C | B26: Borderline | C26: Severe Personality | E26: =IF(D26="","",IF(D26>=85,"Pathological Level / Disorder",IF(D26>=75,"Trait Level / Presence of Syndrome",IF(D26>=60,"Suggestive (Monitor)",IF(D26>=35,"Normal Range","Not Significant"))))) | F26: =IF(D26="",0,IF(D26>=85,4,IF(D26>=75,3,IF(D26>=60,2,IF(D26>=35,1,0))))) | G26: Emotional instability, identity diffusion, self-harm risk
A27: P | B27: Paranoid | C27: Severe Personality | E27: =IF(D27="","",IF(D27>=85,"Pathological Level / Disorder",IF(D27>=75,"Trait Level / Presence of Syndrome",IF(D27>=60,"Suggestive (Monitor)",IF(D27>=35,"Normal Range","Not Significant"))))) | F27: =IF(D27="",0,IF(D27>=85,4,IF(D27>=75,3,IF(D27>=60,2,IF(D27>=35,1,0))))) | G27: Suspiciousness, mistrust, hypervigilance
A29: CLINICAL SYNDROMES
A30: A | B30: Anxiety | C30: Clinical Syndrome | E30: =IF(D30="","",IF(D30>=85,"Pathological Level / Disorder",IF(D30>=75,"Trait Level / Presence of Syndrome",IF(D30>=60,"Suggestive (Monitor)",IF(D30>=35,"Normal Range","Not Significant"))))) | F30: =IF(D30="",0,IF(D30>=85,4,IF(D30>=75,3,IF(D30>=60,2,IF(D30>=35,1,0))))) | G30: Excessive worry, tension, apprehension, somatic anxiety
A31: H | B31: Somatoform | C31: Clinical Syndrome | E31: =IF(D31="","",IF(D31>=85,"Pathological Level / Disorder",IF(D31>=75,"Trait Level / Presence of Syndrome",IF(D31>=60,"Suggestive (Monitor)",IF(D31>=35,"Normal Range","Not Significant"))))) | F31: =IF(D31="",0,IF(D31>=85,4,IF(D31>=75,3,IF(D31>=60,2,IF(D31>=35,1,0))))) | G31: Somatic complaints, health preoccupation
A32: N | B32: Bipolar: Manic | C32: Clinical Syndrome | E32: =IF(D32="","",IF(D32>=85,"Pathological Level / Disorder",IF(D32>=75,"Trait Level / Presence of Syndrome",IF(D32>=60,"Suggestive (Monitor)",IF(D32>=35,"Normal Range","Not Significant"))))) | F32: =IF(D32="",0,IF(D32>=85,4,IF(D32>=75,3,IF(D32>=60,2,IF(D32>=35,1,0))))) | G32: Elevated mood, pressured speech, grandiosity
A33: D | B33: Dysthymia | C33: Clinical Syndrome | E33: =IF(D33="","",IF(D33>=85,"Pathological Level / Disorder",IF(D33>=75,"Trait Level / Presence of Syndrome",IF(D33>=60,"Suggestive (Monitor)",IF(D33>=35,"Normal Range","Not Significant"))))) | F33: =IF(D33="",0,IF(D33>=85,4,IF(D33>=75,3,IF(D33>=60,2,IF(D33>=35,1,0))))) | G33: Chronic mild depression, low energy, pessimism
A34: B | B34: Alcohol Dependence | C34: Clinical Syndrome | E34: =IF(D34="","",IF(D34>=85,"Pathological Level / Disorder",IF(D34>=75,"Trait Level / Presence of Syndrome",IF(D34>=60,"Suggestive (Monitor)",IF(D34>=35,"Normal Range","Not Significant"))))) | F34: =IF(D34="",0,IF(D34>=85,4,IF(D34>=75,3,IF(D34>=60,2,IF(D34>=35,1,0))))) | G34: Problematic alcohol use pattern
A35: T | B35: Drug Dependence | C35: Clinical Syndrome | E35: =IF(D35="","",IF(D35>=85,"Pathological Level / Disorder",IF(D35>=75,"Trait Level / Presence of Syndrome",IF(D35>=60,"Suggestive (Monitor)",IF(D35>=35,"Normal Range","Not Significant"))))) | F35: =IF(D35="",0,IF(D35>=85,4,IF(D35>=75,3,IF(D35>=60,2,IF(D35>=35,1,0))))) | G35: Problematic drug use pattern
A36: R | B36: Post-Traumatic Stress Disorder | C36: Clinical Syndrome | E36: =IF(D36="","",IF(D36>=85,"Pathological Level / Disorder",IF(D36>=75,"Trait Level / Presence of Syndrome",IF(D36>=60,"Suggestive (Monitor)",IF(D36>=35,"Normal Range","Not Significant"))))) | F36: =IF(D36="",0,IF(D36>=85,4,IF(D36>=75,3,IF(D36>=60,2,IF(D36>=35,1,0))))) | G36: Trauma-related distress, hyperarousal, avoidance
A38: SEVERE CLINICAL SYNDROMES
A39: SS | B39: Thought Disorder | C39: Severe Clinical | E39: =IF(D39="","",IF(D39>=85,"Pathological Level / Disorder",IF(D39>=75,"Trait Level / Presence of Syndrome",IF(D39>=60,"Suggestive (Monitor)",IF(D39>=35,"Normal Range","Not Significant"))))) | F39: =IF(D39="",0,IF(D39>=85,4,IF(D39>=75,3,IF(D39>=60,2,IF(D39>=35,1,0))))) | G39: Disorganized thinking, possible psychotic features
A40: CC | B40: Major Depression | C40: Severe Clinical | E40: =IF(D40="","",IF(D40>=85,"Pathological Level / Disorder",IF(D40>=75,"Trait Level / Presence of Syndrome",IF(D40>=60,"Suggestive (Monitor)",IF(D40>=35,"Normal Range","Not Significant"))))) | F40: =IF(D40="",0,IF(D40>=85,4,IF(D40>=75,3,IF(D40>=60,2,IF(D40>=35,1,0))))) | G40: Severe depressive episode, hopelessness, anhedonia
A41: PP | B41: Delusional Disorder | C41: Severe Clinical | E41: =IF(D41="","",IF(D41>=85,"Pathological Level / Disorder",IF(D41>=75,"Trait Level / Presence of Syndrome",IF(D41>=60,"Suggestive (Monitor)",IF(D41>=35,"Normal Range","Not Significant"))))) | F41: =IF(D41="",0,IF(D41>=85,4,IF(D41>=75,3,IF(D41>=60,2,IF(D41>=35,1,0))))) | G41: Fixed false beliefs, paranoid ideation

Sheet Profile Summary
A1: MCMI-III PROFILE SUMMARY
A2: Visual Profile Overview - BR Scores by Scale
A4: Scale | B4: Scale Name | C4: BR Score | D4: Bar (Visual) | E4: Significance | F4: Notes
A5: X | B5: Disclosure | C5: ='BR Scores & Interpretation'!D6 | D5: =IF(C5="","",REPT("█",INT(C5/5))) | E5: =IF(C5="","",IF(C5>=85,"⚠ PATHOLOGICAL",IF(C5>=75,"● TRAIT LEVEL",IF(C5>=60,"○ Suggestive","— Normal"))))
A6: Y | B6: Desirability | C6: ='BR Scores & Interpretation'!D7 | D6: =IF(C6="","",REPT("█",INT(C6/5))) | E6: =IF(C6="","",IF(C6>=85,"⚠ PATHOLOGICAL",IF(C6>=75,"● TRAIT LEVEL",IF(C6>=60,"○ Suggestive","— Normal"))))
A7: Z | B7: Debasement | C7: ='BR Scores & Interpretation'!D8 | D7: =IF(C7="","",REPT("█",INT(C7/5))) | E7: =IF(C7="","",IF(C7>=85,"⚠ PATHOLOGICAL",IF(C7>=75,"● TRAIT LEVEL",IF(C7>=60,"○ Suggestive","— Normal"))))
A8: V | B8: Invalidity | C8: ='BR Scores & Interpretation'!D9 | D8: =IF(C8="","",REPT("█",INT(C8/5))) | E8: =IF(C8="","",IF(C8>=85,"⚠ PATHOLOGICAL",IF(C8>=75,"● TRAIT LEVEL",IF(C8>=60,"○ Suggestive","— Normal"))))
A9: 1 | B9: Schizoid | C9: ='BR Scores & Interpretation'!D12 | D9: =IF(C9="","",REPT("█",INT(C9/5))) | E9: =IF(C9="","",IF(C9>=85,"⚠ PATHOLOGICAL",IF(C9>=75,"● TRAIT LEVEL",IF(C9>=60,"○ Suggestive","— Normal"))))
A10: 2A | B10: Avoidant | C10: ='BR Scores & Interpretation'!D13 | D10: =IF(C10="","",REPT("█",INT(C10/5))) | E10: =IF(C10="","",IF(C10>=85,"⚠ PATHOLOGICAL",IF(C10>=75,"● TRAIT LEVEL",IF(C10>=60,"○ Suggestive","— Normal"))))
A11: 2B | B11: Depressive | C11: ='BR Scores & Interpretation'!D14 | D11: =IF(C11="","",REPT("█",INT(C11/5))) | E11: =IF(C11="","",IF(C11>=85,"⚠ PATHOLOGICAL",IF(C11>=75,"● TRAIT LEVEL",IF(C11>=60,"○ Suggestive","— Normal"))))
A12: 3 | B12: Dependent | C12: ='BR Scores & Interpretation'!D15 | D12: =IF(C12="","",REPT("█",INT(C12/5))) | E12: =IF(C12="","",IF(C12>=85,"⚠ PATHOLOGICAL",IF(C12>=75,"● TRAIT LEVEL",IF(C12>=60,"○ Suggestive","— Normal"))))
A13: 4 | B13: Histrionic | C13: ='BR Scores & Interpretation'!D16 | D13: =IF(C13="","",REPT("█",INT(C13/5))) | E13: =IF(C13="","",IF(C13>=85,"⚠ PATHOLOGICAL",IF(C13>=75,"● TRAIT LEVEL",IF(C13>=60,"○ Suggestive","— Normal"))))
A14: 5 | B14: Narcissistic | C14: ='BR Scores & Interpretation'!D17 | D14: =IF(C14="","",REPT("█",INT(C14/5))) | E14: =IF(C14="","",IF(C14>=85,"⚠ PATHOLOGICAL",IF(C14>=75,"● TRAIT LEVEL",IF(C14>=60,"○ Suggestive","— Normal"))))
A15: 6A | B15: Antisocial | C15: ='BR Scores & Interpretation'!D18 | D15: =IF(C15="","",REPT("█",INT(C15/5))) | E15: =IF(C15="","",IF(C15>=85,"⚠ PATHOLOGICAL",IF(C15>=75,"● TRAIT LEVEL",IF(C15>=60,"○ Suggestive","— Normal"))))
A16: 6B | B16: Sadistic (Aggressive) | C16: ='BR Scores & Interpretation'!D19 | D16: =IF(C16="","",REPT("█",INT(C16/5))) | E16: =IF(C16="","",IF(C16>=85,"⚠ PATHOLOGICAL",IF(C16>=75,"● TRAIT LEVEL",IF(C16>=60,"○ Suggestive","— Normal"))))
A17: 7 | B17: Compulsive | C17: ='BR Scores & Interpretation'!D20 | D17: =IF(C17="","",REPT("█",INT(C17/5))) | E17: =IF(C17="","",IF(C17>=85,"⚠ PATHOLOGICAL",IF(C17>=75,"● TRAIT LEVEL",IF(C17>=60,"○ Suggestive","— Normal"))))
A18: 8A | B18: Negativistic (Passive-Aggressive) | C18: ='BR Scores & Interpretation'!D21 | D18: =IF(C18="","",REPT("█",INT(C18/5))) | E18: =IF(C18="","",IF(C18>=85,"⚠ PATHOLOGICAL",IF(C18>=75,"● TRAIT LEVEL",IF(C18>=60,"○ Suggestive","— Normal"))))
A19: 8B | B19: Masochistic (Self-Defeating) | C19: ='BR Scores & Interpretation'!D22 | D19: =IF(C19="","",REPT("█",INT(C19/5))) | E19: =IF(C19="","",IF(C19>=85,"⚠ PATHOLOGICAL",IF(C19>=75,"● TRAIT LEVEL",IF(C19>=60,"○ Suggestive","— Normal"))))
A20: S | B20: Schizotypal | C20: ='BR Scores & Interpretation'!D25 | D20: =IF(C20="","",REPT("█",INT(C20/5))) | E20: =IF(C20="","",IF(C20>=85,"⚠ PATHOLOGICAL",IF(C20>=75,"● TRAIT LEVEL",IF(C20>=60,"○ Suggestive","— Normal"))))
A21: C | B21: Borderline | C21: ='BR Scores & Interpretation'!D26 | D21: =IF(C21="","",REPT("█",INT(C21/5))) | E21: =IF(C21="","",IF(C21>=85,"⚠ PATHOLOGICAL",IF(C21>=75,"● TRAIT LEVEL",IF(C21>=60,"○ Suggestive","— Normal"))))
A22: P | B22: Paranoid | C22: ='BR Scores & Interpretation'!D27 | D22: =IF(C22="","",REPT("█",INT(C22/5))) | E22: =IF(C22="","",IF(C22>=85,"⚠ PATHOLOGICAL",IF(C22>=75,"● TRAIT LEVEL",IF(C22>=60,"○ Suggestive","— Normal"))))
A23: A | B23: Anxiety | C23: ='BR Scores & Interpretation'!D30 | D23: =IF(C23="","",REPT("█",INT(C23/5))) | E23: =IF(C23="","",IF(C23>=85,"⚠ PATHOLOGICAL",IF(C23>=75,"● TRAIT LEVEL",IF(C23>=60,"○ Suggestive","— Normal"))))
A24: H | B24: Somatoform | C24: ='BR Scores & Interpretation'!D31 | D24: =IF(C24="","",REPT("█",INT(C24/5))) | E24: =IF(C24="","",IF(C24>=85,"⚠ PATHOLOGICAL",IF(C24>=75,"● TRAIT LEVEL",IF(C24>=60,"○ Suggestive","— Normal"))))
A25: N | B25: Bipolar: Manic | C25: ='BR Scores & Interpretation'!D32 | D25: =IF(C25="","",REPT("█",INT(C25/5))) | E25: =IF(C25="","",IF(C25>=85,"⚠ PATHOLOGICAL",IF(C25>=75,"● TRAIT LEVEL",IF(C25>=60,"○ Suggestive","— Normal"))))
A26: D | B26: Dysthymia | C26: ='BR Scores & Interpretation'!D33 | D26: =IF(C26="","",REPT("█",INT(C26/5))) | E26: =IF(C26="","",IF(C26>=85,"⚠ PATHOLOGICAL",IF(C26>=75,"● TRAIT LEVEL",IF(C26>=60,"○ Suggestive","— Normal"))))
A27: B | B27: Alcohol Dependence | C27: ='BR Scores & Interpretation'!D34 | D27: =IF(C27="","",REPT("█",INT(C27/5))) | E27: =IF(C27="","",IF(C27>=85,"⚠ PATHOLOGICAL",IF(C27>=75,"● TRAIT LEVEL",IF(C27>=60,"○ Suggestive","— Normal"))))
A28: T | B28: Drug Dependence | C28: ='BR Scores & Interpretation'!D35 | D28: =IF(C28="","",REPT("█",INT(C28/5))) | E28: =IF(C28="","",IF(C28>=85,"⚠ PATHOLOGICAL",IF(C28>=75,"● TRAIT LEVEL",IF(C28>=60,"○ Suggestive","— Normal"))))
A29: R | B29: Post-Traumatic Stress Disorder | C29: ='BR Scores & Interpretation'!D36 | D29: =IF(C29="","",REPT("█",INT(C29/5))) | E29: =IF(C29="","",IF(C29>=85,"⚠ PATHOLOGICAL",IF(C29>=75,"● TRAIT LEVEL",IF(C29>=60,"○ Suggestive","— Normal"))))
A30: SS | B30: Thought Disorder | C30: ='BR Scores & Interpretation'!D39 | D30: =IF(C30="","",REPT("█",INT(C30/5))) | E30: =IF(C30="","",IF(C30>=85,"⚠ PATHOLOGICAL",IF(C30>=75,"● TRAIT LEVEL",IF(C30>=60,"○ Suggestive","— Normal"))))
A31: CC | B31: Major Depression | C31: ='BR Scores & Interpretation'!D40 | D31: =IF(C31="","",REPT("█",INT(C31/5))) | E31: =IF(C31="","",IF(C31>=85,"⚠ PATHOLOGICAL",IF(C31>=75,"● TRAIT LEVEL",IF(C31>=60,"○ Suggestive","— Normal"))))
A32: PP | B32: Delusional Disorder | C32: ='BR Scores & Interpretation'!D41 | D32: =IF(C32="","",REPT("█",INT(C32/5))) | E32: =IF(C32="","",IF(C32>=85,"⚠ PATHOLOGICAL",IF(C32>=75,"● TRAIT LEVEL",IF(C32>=60,"○ Suggestive","— Normal"))))

Sheet Clinical Report
A1: MCMI-III CLINICAL REPORT TEMPLATE
A3: TEST VALIDITY
A4: Based on the Modifying Indices, the protocol is [VALID/INVALID]. The Disclosure score (X) suggests [interpretation]. The Desirability score (Y) indicates [interpretation]. The Debasement score (Z) reflects [interpretation].
A6: CLINICAL PERSONALITY PATTERN
A7: The personality profile reveals predominant features of [scale names with BR≥75]. These elevations suggest [personality description]. The individual demonstrates [behavioral patterns].
A9: SEVERE PERSONALITY PATHOLOGY
A10: Regarding severe personality pathology, the profile [shows/does not show] significant elevations. [If elevated: The elevation on Scale [X] suggests...]. Features include [description].
A12: CLINICAL SYNDROMES
A13: The clinical syndrome scales indicate [elevated scales]. The individual experiences [symptom descriptions]. These findings are consistent with [clinical observations].
A15: SEVERE CLINICAL SYNDROMES
A16: Severe clinical syndrome analysis [reveals/does not reveal] significant concerns. [If elevated: The elevation on [Scale] suggests...]. Clinical implications include [description].
A18: INTEGRATION & RECOMMENDATIONS
A19: Overall, the MCMI-III profile suggests [integrated summary]. Key clinical concerns include: [list]. Treatment recommendations: [list]. Prognosis considerations: [description].

Sheet Item Response Entry
A1: MCMI-III ITEM RESPONSES (175 Items)
A2: Enter T (True) or F (False) for each item
A4: Item # | B4: Response (T/F) | C4: Item # | D4: Response (T/F)
A5: 1 | C5: 89
A6: 2 | C6: 90
A7: 3 | C7: 91
A8: 4 | C8: 92
A9: 5 | C9: 93
A10: 6 | C10: 94
A11: 7 | C11: 95
A12: 8 | C12: 96
A13: 9 | C13: 97
A14: 10 | C14: 98
A15: 11 | C15: 99
A16: 12 | C16: 100
... A91: 87 | C91: 175
A92: 88

Sheet Scoring Reference
A1: MCMI-III SCORING REFERENCE & SCALE DESCRIPTIONS
A3: Scale Code | B3: Scale Name | C3: Category | D3: Items | E3: Description
A4: MODIFYING INDICES
A5: X | B5: Disclosure | C5: Validity | D5: ~178 items | E5: Openness/willingness to reveal personal information
A6: Y | B6: Desirability | C6: Validity | D6: 21 items | E6: Tendency to present oneself in a favorable light
A7: Z | B7: Debasement | C7: Validity | D7: 33 items | E7: Tendency to deprecate or devalue oneself
A8: V | B8: Invalidity | C8: Validity | D8: 3 items | E8: Random or confused responding (>1 invalidates)
A10: CLINICAL PERSONALITY PATTERNS
A11: 1 | B11: Schizoid | C11: Personality | D11: 16 items | E11: Emotional detachment, social withdrawal, limited affect
A12: 2A | B12: Avoidant | C12: Personality | D12: 16 items | E12: Social inhibition, fear of rejection, hypersensitivity
A13: 2B | B13: Depressive | C13: Personality | D13: 15 items | E13: Chronic pessimism, low mood, hopelessness
A14: 3 | B14: Dependent | C14: Personality | D14: 16 items | E14: Submissiveness, need for reassurance, clinging behavior
A15: 4 | B15: Histrionic | C15: Personality | D15: 17 items | E15: Attention-seeking, emotional lability, superficiality
A16: 5 | B16: Narcissistic | C16: Personality | D16: 24 items | E16: Grandiosity, entitlement, lack of empathy
A17: 6A | B17: Antisocial | C17: Personality | D17: 17 items | E17: Disregard for rules, impulsivity, exploitation
A18: 6B | B18: Sadistic (Aggressive) | C18: Personality | D18: 20 items | E18: Hostile, domineering, pleasure in others pain
A19: 7 | B19: Compulsive | C19: Personality | D19: 17 items | E19: Perfectionism, rigidity, emotional constriction
A20: 8A | B20: Negativistic (Passive-Aggressive) | C20: Personality | D20: 16 items | E20: Ambivalence, irritability, oppositional behavior
A21: 8B | B21: Masochistic (Self-Defeating) | C21: Personality | D21: 15 items | E21: Self-sacrifice, acceptance of suffering, guilt
A23: SEVERE PERSONALITY PATHOLOGY
A24: S | B24: Schizotypal | C24: Severe Pers. | D24: 16 items | E24: Eccentric behavior, cognitive slippage, social detachment
A25: C | B25: Borderline | C25: Severe Pers. | D25: 16 items | E25: Emotional instability, identity diffusion, self-harm risk
A26: P | B26: Paranoid | C26: Severe Pers. | D26: 17 items | E26: Suspiciousness, mistrust, hypervigilance
A28: CLINICAL SYNDROMES
A29: A | B29: Anxiety | C29: Syndrome | D29: 14 items | E29: Excessive worry, tension, apprehension, somatic anxiety
A30: H | B30: Somatoform | C30: Syndrome | D30: 12 items | E30: Somatic complaints, health preoccupation
A31: N | B31: Bipolar: Manic | C31: Syndrome | D31: 13 items | E31: Elevated mood, pressured speech, grandiosity
A32: D | B32: Dysthymia | C32: Syndrome | D32: 14 items | E32: Chronic mild depression, low energy, pessimism
A33: B | B33: Alcohol Dependence | C33: Syndrome | D33: 15 items | E33: Problematic alcohol use pattern
A34: T | B34: Drug Dependence | C34: Syndrome | D34: 14 items | E34: Problematic drug use pattern
A35: R | B35: Post-Traumatic Stress Disorder | C35: Syndrome | D35: 16 items | E35: Trauma-related distress, hyperarousal, avoidance
A37: SEVERE CLINICAL SYNDROMES
A38: SS | B38: Thought Disorder | C38: Severe Syn. | D38: 17 items | E38: Disorganized thinking, possible psychotic features
A39: CC | B39: Major Depression | C39: Severe Syn. | D39: 17 items | E39: Severe depressive episode, hopelessness, anhedonia
A40: PP | B40: Delusional Disorder | C40: Severe Syn. | D40: 13 items | E40: Fixed false beliefs, paranoid ideation
A44: INTERPRETATION GUIDELINES
A45: BR Score ≥ 85: Indicates the presence of a disorder or pathological level of the trait.
A46: BR Score 75-84: Suggests clinically significant features (trait level or syndrome presence).
A47: BR Score 60-74: Suggestive features that warrant monitoring but not diagnosis.
A48: BR Score 35-59: Within normal limits; features are within normative expectations.
...
