Workbook

Sheet DATA ENTRY
A1: MCMI-III AUTO-SCORING TOOL
A2: Enter TRUE or FALSE for each item below. Scoring is AUTOMATIC.
A3: Patient Age: | C3: Setting (OPD/IPD): | D3: OPD
A4: Gender (M/F): | C4: Axis I Duration: | E4: (weeks, for IPD only)
A6: Item # | B6: Response (TRUE/FALSE) | C6: Status | E6: Item # | F6: Response (TRUE/FALSE) | G6: Status
A7: 1 | C7: =IF(B7="","","✓") | E7: 89 | G7: =IF(F7="","","✓")
A8: 2 | C8: =IF(B8="","","✓") | E8: 90 | G8: =IF(F8="","","✓")
A9: 3 | C9: =IF(B9="","","✓") | E9: 91 | G9: =IF(F9="","","✓")
A10: 4 | C10: =IF(B10="","","✓") | E10: 92 | G10: =IF(F10="","","✓")
A11: 5 | C11: =IF(B11="","","✓") | E11: 93 | G11: =IF(F11="","","✓")
A12: 6 | C12: =IF(B12="","","✓") | E12: 94 | G12: =IF(F12="","","✓")
A13: 7 | C13: =IF(B13="","","✓") | E13: 95 | G13: =IF(F13="","","✓")
A14: 8 | C14: =IF(B14="","","✓") | E14: 96 | G14: =IF(F14="","","✓")
A15: 9 | C15: =IF(B15="","","✓") | E15: 97 | G15: =IF(F15="","","✓")
A16: 10 | C16: =IF(B16="","","✓") | E16: 98 | G16: =IF(F16="","","✓")
A17: 11 | C17: =IF(B17="","","✓") | E17: 99 | G17: =IF(F17="","","✓")
A18: 12 | C18: =IF(B18="","","✓") | E18: 100 | G18: =IF(F18="","","✓")
... A93: 87 | C93: =IF(B93="","","✓") | E93: 175 | G93: =IF(F93="","","✓")
A94: 88 | C94: =IF(B94="","","✓")
A96: SUMMARY:
A97: Items Answered: | B97: =COUNTA(B7:B94)+COUNTA(F7:F93)
A98: Items Omitted: | B98: =175-(COUNTA(B7:B94)+COUNTA(F7:F93))
A99: Status: | B99: =IF((COUNTA(B7:B94)+COUNTA(F7:F93))=175,"COMPLETE","INCOMPLETE - "&175-(COUNTA(B7:B94)+COUNTA(F7:F93))&" items remaining")

Sheet AUTO-SCORING
A1: MCMI-III AUTOMATIC SCORING RESULTS
A2: All scores calculated automatically from your DATA ENTRY responses
A4: VALIDITY CHECKS
A5: Scale | B5: Name | C5: Score | D5: Threshold | E5: Result
A6: - | B6: Omitted Items | C6: =175-(COUNTA('DATA ENTRY'!B7:B94)+COUNTA('DATA ENTRY'!F7:F93)) | D6: <= 11 | E6: =IF(C6>11,"INVALID","VALID")
A7: V | B7: Invalidity (Items 65, 110, 157) | C7: =IF('DATA ENTRY'!B71="TRUE",1,0)+IF('DATA ENTRY'!F28="TRUE",1,0)+IF('DATA ENTRY'!F75="TRUE",1,0) | D7: < 2 | E7: =IF(C7>=2,"INVALID",IF(C7=1,"QUESTIONABLE","VALID"))
A8: W | B8: Inconsistency (44 item pairs) | C8: =IF(AND('DATA ENTRY'!B9<>"",'DATA ENTRY'!F67<>"",'DATA ENTRY'!B9<>'DATA ENTRY'!F67),1,0)+IF(AND('DATA ENTRY'!B16<>"",'DATA ENTRY'!F83<>"",'DATA ENTRY'!B16<>'DATA ENTRY'!F83),1,0)+IF(AND('DATA ENTRY'!B20<>"",'DATA ENTRY'!F12<>"",'DATA ENTRY'!B20<>'DATA ENTRY'!F12),1,0)+IF(AND('DATA ENTRY'!B21<>"",'DATA ENTRY'!B67<>"",'DATA ENTRY'!B21<>'DATA ENTRY'!B67),1,0)+IF(AND('DATA ENTRY'!B25<>"",'DATA ENTRY'!F68<>"",'DATA ENTRY'!B25<>'DATA ENTRY'!F68),1,0)+IF(AND('DATA ENTRY'!B31<>"",'DATA ENTRY'!F48<>"",'DATA ENTRY'!B31<>'DATA ENTRY'!F48),1,0)+IF(AND('DATA ENTRY'!B45<>"",'DATA ENTRY'!F74<>"",'DATA ENTRY'!B45<>'DATA ENTRY'!F74),1,0)+IF(AND('DATA ENTRY'!B48<>"",'DATA ENTRY'!F11<>"",'DATA ENTRY'!B48<>'DATA ENTRY'!F11),1,0)+IF(AND('DATA ENTRY'!B55<>"",'DATA ENTRY'!F70<>"",'DATA ENTRY'!B55<>'DATA ENTRY'!F70),1,0)+IF(AND('DATA ENTRY'!B63<>"",'DATA ENTRY'!F15<>"",'DATA ENTRY'!B63<>'DATA ENTRY'!F15),1,0)+IF(AND('DATA ENTRY'!B66<>"",'DATA ENTRY'!F23<>"",'DATA ENTRY'!B66<>'DATA ENTRY'!F23),1,0)+IF(AND('DATA ENTRY'!B68<>"",'DATA ENTRY'!F29<>"",'DATA ENTRY'!B68<>'DATA ENTRY'!F29),1,0)+IF(AND('DATA ENTRY'!B72<>"",'DATA ENTRY'!F35<>"",'DATA ENTRY'!B72<>'DATA ENTRY'!F35),1,0)+IF(AND('DATA ENTRY'!B73<>"",'DATA ENTRY'!F73<>"",'DATA ENTRY'!B73<>'DATA ENTRY'!F73),1,0)+IF(AND('DATA ENTRY'!B76<>"",'DATA ENTRY'!F37<>"",'DATA ENTRY'!B76<>'DATA ENTRY'!F37),1,0)+IF(AND('DATA ENTRY'!B79<>"",'DATA ENTRY'!F38<>"",'DATA ENTRY'!B79<>'DATA ENTRY'!F38),1,0)+IF(AND('DATA ENTRY'!B81<>"",'DATA ENTRY'!F78<>"",'DATA ENTRY'!B81<>'DATA ENTRY'!F78),1,0)+IF(AND('DATA ENTRY'!B85<>"",'DATA ENTRY'!F43<>"",'DATA ENTRY'!B85<>'DATA ENTRY'!F43),1,0)+IF(AND('DATA ENTRY'!B86<>"",'DATA ENTRY'!F84<>"",'DATA ENTRY'!B86<>'DATA ENTRY'!F84),1,0)+IF(AND('DATA ENTRY'!B90<>"",'DATA ENTRY'!F45<>"",'DATA ENTRY'!B90<>'DATA ENTRY'!F45),1,0)+IF(AND('DATA ENTRY'!B92<>"",'DATA ENTRY'!F46<>"",'DATA ENTRY'!B92<>'DATA ENTRY'!F46),1,0)+IF(AND('DATA ENTRY'!F7<>"",'DATA ENTRY'!F52<>"",'DATA ENTRY'!F7<>'DATA ENTRY'!F52),1,0)+IF(AND('DATA ENTRY'!F9<>"",'DATA ENTRY'!F87<>"",'DATA ENTRY'!F9<>'DATA ENTRY'!F87),1,0)+IF(AND('DATA ENTRY'!F16<>"",'DATA ENTRY'!F56<>"",'DATA ENTRY'!F16<>'DATA ENTRY'!F56),1,0)+IF(AND('DATA ENTRY'!F19<>"",'DATA ENTRY'!F60<>"",'DATA ENTRY'!F19<>'DATA ENTRY'!F60),1,0)+IF(AND('DATA ENTRY'!F20<>"",'DATA ENTRY'!F61<>"",'DATA ENTRY'!F20<>'DATA ENTRY'!F61),1,0)+IF(AND('DATA ENTRY'!F22<>"",'DATA ENTRY'!F62<>"",'DATA ENTRY'!F22<>'DATA ENTRY'!F62),1,0)+IF(AND('DATA ENTRY'!F26<>"",'DATA ENTRY'!F65<>"",'DATA ENTRY'!F26<>'DATA ENTRY'!F65),1,0)+IF(AND('DATA ENTRY'!F30<>"",'DATA ENTRY'!F69<>"",'DATA ENTRY'!F30<>'DATA ENTRY'!F69),1,0)+IF(AND('DATA ENTRY'!F34<>"",'DATA ENTRY'!F71<>"",'DATA ENTRY'!F34<>'DATA ENTRY'!F71),1,0)+IF(AND('DATA ENTRY'!B8<>"",'DATA ENTRY'!B94<>"",'DATA ENTRY'!B8<>'DATA ENTRY'!B94),1,0)+IF(AND('DATA ENTRY'!B11<>"",'DATA ENTRY'!B83<>"",'DATA ENTRY'!B11<>'DATA ENTRY'!B83),1,0)+IF(AND('DATA ENTRY'!B17<>"",'DATA ENTRY'!B60<>"",'DATA ENTRY'!B17<>'DATA ENTRY'!B60),1,0)+IF(AND('DATA ENTRY'!B26<>"",'DATA ENTRY'!F55<>"",'DATA ENTRY'!B26<>'DATA ENTRY'!F55),1,0)+IF(AND('DATA ENTRY'!B28<>"",'DATA ENTRY'!F39<>"",'DATA ENTRY'!B28<>'DATA ENTRY'!F39),1,0)+IF(AND('DATA ENTRY'!B37<>"",'DATA ENTRY'!F79<>"",'DATA ENTRY'!B37<>'DATA ENTRY'!F79),1,0)+IF(AND('DATA ENTRY'!B43<>"",'DATA ENTRY'!B69<>"",'DATA ENTRY'!B43<>'DATA ENTRY'!B69),1,0)+IF(AND('DATA ENTRY'!B46<>"",'DATA ENTRY'!F82<>"",'DATA ENTRY'!B46<>'DATA ENTRY'!F82),1,0)+IF(AND('DATA ENTRY'!B47<>"",'DATA ENTRY'!F57<>"",'DATA ENTRY'!B47<>'DATA ENTRY'!F57),1,0)+IF(AND('DATA ENTRY'!B51<>"",'DATA ENTRY'!B87<>"",'DATA ENTRY'!B51<>'DATA ENTRY'!B87),1,0)+IF(AND('DATA ENTRY'!B52<>"",'DATA ENTRY'!B84<>"",'DATA ENTRY'!B52<>'DATA ENTRY'!B84),1,0)+IF(AND('DATA ENTRY'!B57<>"",'DATA ENTRY'!F76<>"",'DATA ENTRY'!B57<>'DATA ENTRY'!F76),1,0)+IF(AND('DATA ENTRY'!B59<>"",'DATA ENTRY'!F53<>"",'DATA ENTRY'!B59<>'DATA ENTRY'!F53),1,0)+IF(AND('DATA ENTRY'!B61<>"",'DATA ENTRY'!F90<>"",'DATA ENTRY'!B61<>'DATA ENTRY'!F90),1,0) | D8: < 10 | E8: =IF(C8>=10,"INVALID",IF(C8>=8,"QUESTIONABLE","VALID"))
B9: OVERALL VALIDITY | E9: =IF(OR(E6="INVALID",E7="INVALID",E8="INVALID"),"INVALID",IF(OR(E7="QUESTIONABLE",E8="QUESTIONABLE"),"QUESTIONABLE","VALID"))
A11: COMPLETE SCALE SCORES
A12: Scale | B12: Name | C12: Raw Score | D12: Initial BR | E12: Adjusted BR | F12: Final BR | G12: Interpretation | H12: Level
A13: Modifying Index
A14: Y | B14: Desirability | C14: =IF('DATA ENTRY'!B10="TRUE",1,0)+IF('DATA ENTRY'!B13="TRUE",2,0)+IF('DATA ENTRY'!B32="TRUE",2,0)+IF('DATA ENTRY'!B74="TRUE",1,0)+IF('DATA ENTRY'!B80="TRUE",1,0)+IF('DATA ENTRY'!B88="TRUE",1,0)+IF('DATA ENTRY'!B94="TRUE",2,0)+IF('DATA ENTRY'!F8="TRUE",1,0)+IF('DATA ENTRY'!F13="TRUE",1,0)+IF('DATA ENTRY'!F17="TRUE",1,0)+IF('DATA ENTRY'!F21="TRUE",2,0)+IF('DATA ENTRY'!F24="TRUE",1,0)+IF('DATA ENTRY'!F31="TRUE",1,0)+IF('DATA ENTRY'!F49="TRUE",1,0)+IF('DATA ENTRY'!F51="TRUE",2,0)+IF('DATA ENTRY'!F58="TRUE",1,0)+IF('DATA ENTRY'!F63="TRUE",1,0)+IF('DATA ENTRY'!F71="TRUE",1,0)+IF('DATA ENTRY'!F80="TRUE",1,0)+IF('DATA ENTRY'!F85="TRUE",1,0)+IF('DATA ENTRY'!F88="TRUE",1,0) | D14: =C14*3 | E14: =D14 | F14: =MIN(115,MAX(0,E14)) | G14: =IF(F14>=85,"PROMINENT (Disorder)",IF(F14>=75,"CLINICALLY SIGNIFICANT",IF(F14>=60,"Trait Present","Not Significant"))) | H14: =IF(F14>=85,"***",IF(F14>=75,"**",IF(F14>=60,"*","")))
A15: Z | B15: Debasement | C15: =IF('DATA ENTRY'!B15="TRUE",2,0)+IF('DATA ENTRY'!B22="TRUE",1,0)+IF('DATA ENTRY'!B36="TRUE",2,0)+IF('DATA ENTRY'!B41="TRUE",1,0)+IF('DATA ENTRY'!B50="TRUE",1,0)+IF('DATA ENTRY'!B54="TRUE",1,0)+IF('DATA ENTRY'!B56="TRUE",1,0)+IF('DATA ENTRY'!B62="TRUE",1,0)+IF('DATA ENTRY'!B67="TRUE",1,0)+IF('DATA ENTRY'!B78="TRUE",2,0)+IF('DATA ENTRY'!B82="TRUE",1,0)+IF('DATA ENTRY'!B89="TRUE",1,0)+IF('DATA ENTRY'!B93="TRUE",1,0)+IF('DATA ENTRY'!F10="TRUE",1,0)+IF('DATA ENTRY'!F14="TRUE",1,0)+IF('DATA ENTRY'!F18="TRUE",1,0)+IF('DATA ENTRY'!F25="TRUE",1,0)+IF('DATA ENTRY'!F27="TRUE",2,0)+IF('DATA ENTRY'!F32="TRUE",1,0)+IF('DATA ENTRY'!F36="TRUE",1,0)+IF('DATA ENTRY'!F40="TRUE",1,0)+IF('DATA ENTRY'!F44="TRUE",1,0)+IF('DATA ENTRY'!F50="TRUE",1,0)+IF('DATA ENTRY'!F54="TRUE",1,0)+IF('DATA ENTRY'!F59="TRUE",1,0)+IF('DATA ENTRY'!F64="TRUE",1,0)+IF('DATA ENTRY'!F66="TRUE",2,0)+IF('DATA ENTRY'!F72="TRUE",1,0)+IF('DATA ENTRY'!F77="TRUE",1,0)+IF('DATA ENTRY'!F81="TRUE",1,0)+IF('DATA ENTRY'!F86="TRUE",1,0)+IF('DATA ENTRY'!F89="TRUE",1,0)+IF('DATA ENTRY'!F93="TRUE",2,0) | D15: =C15*3 | E15: =D15 | F15: =MIN(115,MAX(0,E15)) | G15: =IF(F15>=85,"PROMINENT (Disorder)",IF(F15>=75,"CLINICALLY SIGNIFICANT",IF(F15>=60,"Trait Present","Not Significant"))) | H15: =IF(F15>=85,"***",IF(F15>=75,"**",IF(F15>=60,"*","")))
A16: Clinical Personality
A17: 1 | B17: Schizoid | C17: =IF('DATA ENTRY'!B8="TRUE",1,0)+IF('DATA ENTRY'!B28="TRUE",1,0)+IF('DATA ENTRY'!B30="TRUE",2,0)+IF('DATA ENTRY'!B47="TRUE",1,0)+IF('DATA ENTRY'!B51="TRUE",1,0)+IF('DATA ENTRY'!B59="TRUE",1,0)+IF('DATA ENTRY'!B62="TRUE",1,0)+IF('DATA ENTRY'!B63="TRUE",2,0)+IF('DATA ENTRY'!B77="TRUE",1,0)+IF('DATA ENTRY'!B87="TRUE",1,0)+IF('DATA ENTRY'!F16="TRUE",1,0)+IF('DATA ENTRY'!F39="TRUE",1,0)+IF('DATA ENTRY'!F53="TRUE",1,0)+IF('DATA ENTRY'!F65="TRUE",2,0)+IF('DATA ENTRY'!F76="TRUE",1,0)+IF('DATA ENTRY'!F90="TRUE",1,0) | D17: =C17*3 | E17: =MIN(115,MAX(0,D17+C49)) | F17: =MIN(115,MAX(0,E17)) | G17: =IF(F17>=85,"PROMINENT (Disorder)",IF(F17>=75,"CLINICALLY SIGNIFICANT",IF(F17>=60,"Trait Present","Not Significant"))) | H17: =IF(F17>=85,"***",IF(F17>=75,"**",IF(F17>=60,"*","")))
A18: 2A | B18: Avoidant | C18: =IF('DATA ENTRY'!B8="TRUE",1,0)+IF('DATA ENTRY'!B26="TRUE",1,0)+IF('DATA ENTRY'!B28="TRUE",1,0)+IF('DATA ENTRY'!B47="TRUE",1,0)+IF('DATA ENTRY'!B52="TRUE",2,0)+IF('DATA ENTRY'!B59="TRUE",1,0)+IF('DATA ENTRY'!B62="TRUE",1,0)+IF('DATA ENTRY'!B77="TRUE",1,0)+IF('DATA ENTRY'!B84="TRUE",2,0)+IF('DATA ENTRY'!B87="TRUE",1,0)+IF('DATA ENTRY'!F16="TRUE",1,0)+IF('DATA ENTRY'!F39="TRUE",1,0)+IF('DATA ENTRY'!F53="TRUE",1,0)+IF('DATA ENTRY'!F65="TRUE",2,0)+IF('DATA ENTRY'!F76="TRUE",1,0)+IF('DATA ENTRY'!F90="TRUE",1,0) | D18: =C18*3 | E18: =MIN(115,MAX(0,D18+C49)) | F18: =MIN(115,MAX(0,E18)) | G18: =IF(F18>=85,"PROMINENT (Disorder)",IF(F18>=75,"CLINICALLY SIGNIFICANT",IF(F18>=60,"Trait Present","Not Significant"))) | H18: =IF(F18>=85,"***",IF(F18>=75,"**",IF(F18>=60,"*","")))
A19: 2B | B19: Depressive | C19: =IF('DATA ENTRY'!B8="TRUE",1,0)+IF('DATA ENTRY'!B26="TRUE",2,0)+IF('DATA ENTRY'!B28="TRUE",1,0)+IF('DATA ENTRY'!B47="TRUE",1,0)+IF('DATA ENTRY'!B56="TRUE",2,0)+IF('DATA ENTRY'!B59="TRUE",1,0)+IF('DATA ENTRY'!B62="TRUE",1,0)+IF('DATA ENTRY'!B77="TRUE",1,0)+IF('DATA ENTRY'!B87="TRUE",1,0)+IF('DATA ENTRY'!F16="TRUE",1,0)+IF('DATA ENTRY'!F39="TRUE",1,0)+IF('DATA ENTRY'!F48="TRUE",2,0)+IF('DATA ENTRY'!F53="TRUE",1,0)+IF('DATA ENTRY'!F76="TRUE",1,0)+IF('DATA ENTRY'!F90="TRUE",1,0) | D19: =C19*3 | E19: =MIN(115,MAX(0,D19+C49)) | F19: =MIN(115,MAX(0,E19)) | G19: =IF(F19>=85,"PROMINENT (Disorder)",IF(F19>=75,"CLINICALLY SIGNIFICANT",IF(F19>=60,"Trait Present","Not Significant"))) | H19: =IF(F19>=85,"***",IF(F19>=75,"**",IF(F19>=60,"*","")))
A20: 3 | B20: Dependent | C20: =IF('DATA ENTRY'!B9="TRUE",2,0)+IF('DATA ENTRY'!B11="TRUE",1,0)+IF('DATA ENTRY'!B21="TRUE",1,0)+IF('DATA ENTRY'!B25="TRUE",2,0)+IF('DATA ENTRY'!B28="TRUE",1,0)+IF('DATA ENTRY'!B39="TRUE",1,0)+IF('DATA ENTRY'!B45="TRUE",2,0)+IF('DATA ENTRY'!B51="TRUE",1,0)+IF('DATA ENTRY'!B66="TRUE",1,0)+IF('DATA ENTRY'!B76="TRUE",1,0)+IF('DATA ENTRY'!B81="TRUE",1,0)+IF('DATA ENTRY'!B86="TRUE",1,0)+IF('DATA ENTRY'!B92="TRUE",1,0)+IF('DATA ENTRY'!F9="TRUE",1,0)+IF('DATA ENTRY'!F37="TRUE",1,0)+IF('DATA ENTRY'!F43="TRUE",1,0)+IF('DATA ENTRY'!F78="TRUE",1,0)+IF('DATA ENTRY'!F84="TRUE",1,0)+IF('DATA ENTRY'!F87="TRUE",1,0) | D20: =C20*3 | E20: =MIN(115,MAX(0,D20+C49)) | F20: =MIN(115,MAX(0,E20)) | G20: =IF(F20>=85,"PROMINENT (Disorder)",IF(F20>=75,"CLINICALLY SIGNIFICANT",IF(F20>=60,"Trait Present","Not Significant"))) | H20: =IF(F20>=85,"***",IF(F20>=75,"**",IF(F20>=60,"*","")))
A21: 4 | B21: Histrionic | C21: =IF('DATA ENTRY'!B13="TRUE",1,0)+IF('DATA ENTRY'!B20="TRUE",1,0)+IF('DATA ENTRY'!B32="TRUE",1,0)+IF('DATA ENTRY'!B38="TRUE",1,0)+IF('DATA ENTRY'!B43="TRUE",2,0)+IF('DATA ENTRY'!B46="TRUE",1,0)+IF('DATA ENTRY'!B48="TRUE",1,0)+IF('DATA ENTRY'!B63="TRUE",1,0)+IF('DATA ENTRY'!B72="TRUE",1,0)+IF('DATA ENTRY'!B84="TRUE",1,0)+IF('DATA ENTRY'!B94="TRUE",1,0)+IF('DATA ENTRY'!F11="TRUE",1,0)+IF('DATA ENTRY'!F13="TRUE",2,0)+IF('DATA ENTRY'!F21="TRUE",1,0)+IF('DATA ENTRY'!F24="TRUE",1,0)+IF('DATA ENTRY'!F29="TRUE",1,0)+IF('DATA ENTRY'!F49="TRUE",1,0)+IF('DATA ENTRY'!F73="TRUE",2,0)+IF('DATA ENTRY'!F82="TRUE",1,0) | D21: =C21*3 | E21: =MIN(115,MAX(0,D21+C49)) | F21: =MIN(115,MAX(0,E21)) | G21: =IF(F21>=85,"PROMINENT (Disorder)",IF(F21>=75,"CLINICALLY SIGNIFICANT",IF(F21>=60,"Trait Present","Not Significant"))) | H21: =IF(F21>=85,"***",IF(F21>=75,"**",IF(F21>=60,"*","")))
A22: 5 | B22: Narcissistic | C22: =IF('DATA ENTRY'!B7="TRUE",1,0)+IF('DATA ENTRY'!B13="TRUE",1,0)+IF('DATA ENTRY'!B20="TRUE",1,0)+IF('DATA ENTRY'!B32="TRUE",1,0)+IF('DATA ENTRY'!B38="TRUE",1,0)+IF('DATA ENTRY'!B43="TRUE",2,0)+IF('DATA ENTRY'!B46="TRUE",1,0)+IF('DATA ENTRY'!B48="TRUE",1,0)+IF('DATA ENTRY'!B63="TRUE",1,0)+IF('DATA ENTRY'!B69="TRUE",1,0)+IF('DATA ENTRY'!B72="TRUE",1,0)+IF('DATA ENTRY'!B73="TRUE",2,0)+IF('DATA ENTRY'!B84="TRUE",1,0)+IF('DATA ENTRY'!B91="TRUE",1,0)+IF('DATA ENTRY'!B94="TRUE",1,0)+IF('DATA ENTRY'!F11="TRUE",1,0)+IF('DATA ENTRY'!F21="TRUE",1,0)+IF('DATA ENTRY'!F29="TRUE",1,0)+IF('DATA ENTRY'!F35="TRUE",2,0)+IF('DATA ENTRY'!F49="TRUE",1,0)+IF('DATA ENTRY'!F58="TRUE",1,0)+IF('DATA ENTRY'!F63="TRUE",1,0)+IF('DATA ENTRY'!F73="TRUE",1,0)+IF('DATA ENTRY'!F82="TRUE",1,0) | D22: =C22*3 | E22: =MIN(115,MAX(0,D22+C49)) | F22: =MIN(115,MAX(0,E22)) | G22: =IF(F22>=85,"PROMINENT (Disorder)",IF(F22>=75,"CLINICALLY SIGNIFICANT",IF(F22>=60,"Trait Present","Not Significant"))) | H22: =IF(F22>=85,"***",IF(F22>=75,"**",IF(F22>=60,"*","")))
A23: 6A | B23: Antisocial | C23: =IF('DATA ENTRY'!B12="TRUE",1,0)+IF('DATA ENTRY'!B18="TRUE",1,0)+IF('DATA ENTRY'!B20="TRUE",1,0)+IF('DATA ENTRY'!B34="TRUE",1,0)+IF('DATA ENTRY'!B38="TRUE",1,0)+IF('DATA ENTRY'!B40="TRUE",2,0)+IF('DATA ENTRY'!B46="TRUE",1,0)+IF('DATA ENTRY'!B53="TRUE",2,0)+IF('DATA ENTRY'!B64="TRUE",1,0)+IF('DATA ENTRY'!B69="TRUE",1,0)+IF('DATA ENTRY'!B72="TRUE",1,0)+IF('DATA ENTRY'!B83="TRUE",1,0)+IF('DATA ENTRY'!B91="TRUE",1,0)+IF('DATA ENTRY'!F11="TRUE",1,0)+IF('DATA ENTRY'!F22="TRUE",2,0)+IF('DATA ENTRY'!F29="TRUE",1,0)+IF('DATA ENTRY'!F49="TRUE",1,0)+IF('DATA ENTRY'!F73="TRUE",1,0)+IF('DATA ENTRY'!F82="TRUE",1,0) | D23: =C23*3 | E23: =MIN(115,MAX(0,D23+C49)) | F23: =MIN(115,MAX(0,E23)) | G23: =IF(F23>=85,"PROMINENT (Disorder)",IF(F23>=75,"CLINICALLY SIGNIFICANT",IF(F23>=60,"Trait Present","Not Significant"))) | H23: =IF(F23>=85,"***",IF(F23>=75,"**",IF(F23>=60,"*","")))
A24: 6B | B24: Aggressive (Sadistic) | C24: =IF('DATA ENTRY'!B12="TRUE",1,0)+IF('DATA ENTRY'!B18="TRUE",1,0)+IF('DATA ENTRY'!B23="TRUE",2,0)+IF('DATA ENTRY'!B34="TRUE",1,0)+IF('DATA ENTRY'!B38="TRUE",1,0)+IF('DATA ENTRY'!B40="TRUE",1,0)+IF('DATA ENTRY'!B53="TRUE",1,0)+IF('DATA ENTRY'!B64="TRUE",1,0)+IF('DATA ENTRY'!B69="TRUE",1,0)+IF('DATA ENTRY'!B72="TRUE",1,0)+IF('DATA ENTRY'!B73="TRUE",2,0)+IF('DATA ENTRY'!B83="TRUE",1,0)+IF('DATA ENTRY'!B91="TRUE",1,0)+IF('DATA ENTRY'!F11="TRUE",1,0)+IF('DATA ENTRY'!F22="TRUE",1,0)+IF('DATA ENTRY'!F29="TRUE",1,0)+IF('DATA ENTRY'!F35="TRUE",2,0)+IF('DATA ENTRY'!F49="TRUE",1,0)+IF('DATA ENTRY'!F73="TRUE",1,0)+IF('DATA ENTRY'!F82="TRUE",1,0) | D24: =C24*3 | E24: =MIN(115,MAX(0,D24+C49)) | F24: =MIN(115,MAX(0,E24)) | G24: =IF(F24>=85,"PROMINENT (Disorder)",IF(F24>=75,"CLINICALLY SIGNIFICANT",IF(F24>=60,"Trait Present","Not Significant"))) | H24: =IF(F24>=85,"***",IF(F24>=75,"**",IF(F24>=60,"*","")))
A25: 7 | B25: Compulsive | C25: =IF('DATA ENTRY'!B10="TRUE",1,0)+IF('DATA ENTRY'!B13="TRUE",1,0)+IF('DATA ENTRY'!B32="TRUE",1,0)+IF('DATA ENTRY'!B38="TRUE",1,0)+IF('DATA ENTRY'!B43="TRUE",1,0)+IF('DATA ENTRY'!B46="TRUE",1,0)+IF('DATA ENTRY'!B63="TRUE",1,0)+IF('DATA ENTRY'!B69="TRUE",1,0)+IF('DATA ENTRY'!B74="TRUE",1,0)+IF('DATA ENTRY'!B80="TRUE",1,0)+IF('DATA ENTRY'!B88="TRUE",1,0)+IF('DATA ENTRY'!B94="TRUE",1,0)+IF('DATA ENTRY'!F13="TRUE",1,0)+IF('DATA ENTRY'!F17="TRUE",2,0)+IF('DATA ENTRY'!F21="TRUE",1,0)+IF('DATA ENTRY'!F51="TRUE",1,0)+IF('DATA ENTRY'!F58="TRUE",2,0)+IF('DATA ENTRY'!F63="TRUE",1,0)+IF('DATA ENTRY'!F80="TRUE",2,0)+IF('DATA ENTRY'!F82="TRUE",1,0) | D25: =C25*3 | E25: =MIN(115,MAX(0,D25+C49)) | F25: =MIN(115,MAX(0,E25)) | G25: =IF(F25>=85,"PROMINENT (Disorder)",IF(F25>=75,"CLINICALLY SIGNIFICANT",IF(F25>=60,"Trait Present","Not Significant"))) | H25: =IF(F25>=85,"***",IF(F25>=75,"**",IF(F25>=60,"*","")))
A26: 8A | B26: Negativistic | C26: =IF('DATA ENTRY'!B11="TRUE",1,0)+IF('DATA ENTRY'!B16="TRUE",2,0)+IF('DATA ENTRY'!B21="TRUE",1,0)+IF('DATA ENTRY'!B26="TRUE",1,0)+IF('DATA ENTRY'!B39="TRUE",1,0)+IF('DATA ENTRY'!B45="TRUE",2,0)+IF('DATA ENTRY'!B52="TRUE",1,0)+IF('DATA ENTRY'!B66="TRUE",1,0)+IF('DATA ENTRY'!B76="TRUE",1,0)+IF('DATA ENTRY'!B81="TRUE",1,0)+IF('DATA ENTRY'!B86="TRUE",1,0)+IF('DATA ENTRY'!B92="TRUE",1,0)+IF('DATA ENTRY'!F9="TRUE",1,0)+IF('DATA ENTRY'!F37="TRUE",1,0)+IF('DATA ENTRY'!F43="TRUE",1,0)+IF('DATA ENTRY'!F78="TRUE",1,0)+IF('DATA ENTRY'!F83="TRUE",2,0)+IF('DATA ENTRY'!F84="TRUE",1,0)+IF('DATA ENTRY'!F87="TRUE",1,0) | D26: =C26*3 | E26: =MIN(115,MAX(0,D26+C49)) | F26: =MIN(115,MAX(0,E26)) | G26: =IF(F26>=85,"PROMINENT (Disorder)",IF(F26>=75,"CLINICALLY SIGNIFICANT",IF(F26>=60,"Trait Present","Not Significant"))) | H26: =IF(F26>=85,"***",IF(F26>=75,"**",IF(F26>=60,"*","")))
A27: 8B | B27: Masochistic | C27: =IF('DATA ENTRY'!B11="TRUE",1,0)+IF('DATA ENTRY'!B21="TRUE",1,0)+IF('DATA ENTRY'!B26="TRUE",1,0)+IF('DATA ENTRY'!B31="TRUE",2,0)+IF('DATA ENTRY'!B39="TRUE",1,0)+IF('DATA ENTRY'!B52="TRUE",1,0)+IF('DATA ENTRY'!B55="TRUE",2,0)+IF('DATA ENTRY'!B66="TRUE",1,0)+IF('DATA ENTRY'!B76="TRUE",1,0)+IF('DATA ENTRY'!B81="TRUE",1,0)+IF('DATA ENTRY'!B86="TRUE",1,0)+IF('DATA ENTRY'!B92="TRUE",1,0)+IF('DATA ENTRY'!F9="TRUE",1,0)+IF('DATA ENTRY'!F37="TRUE",1,0)+IF('DATA ENTRY'!F43="TRUE",1,0)+IF('DATA ENTRY'!F68="TRUE",2,0)+IF('DATA ENTRY'!F78="TRUE",1,0)+IF('DATA ENTRY'!F87="TRUE",1,0) | D27: =C27*3 | E27: =MIN(115,MAX(0,D27+C49)) | F27: =MIN(115,MAX(0,E27)) | G27: =IF(F27>=85,"PROMINENT (Disorder)",IF(F27>=75,"CLINICALLY SIGNIFICANT",IF(F27>=60,"Trait Present","Not Significant"))) | H27: =IF(F27>=85,"***",IF(F27>=75,"**",IF(F27>=60,"*","")))
A28: Severe Personality
A29: S | B29: Schizotypal | C29: =IF('DATA ENTRY'!B8="TRUE",1,0)+IF('DATA ENTRY'!B26="TRUE",1,0)+IF('DATA ENTRY'!B28="TRUE",1,0)+IF('DATA ENTRY'!B30="TRUE",2,0)+IF('DATA ENTRY'!B47="TRUE",1,0)+IF('DATA ENTRY'!B52="TRUE",1,0)+IF('DATA ENTRY'!B59="TRUE",1,0)+IF('DATA ENTRY'!B62="TRUE",1,0)+IF('DATA ENTRY'!B63="TRUE",2,0)+IF('DATA ENTRY'!B77="TRUE",1,0)+IF('DATA ENTRY'!B84="TRUE",1,0)+IF('DATA ENTRY'!B87="TRUE",1,0)+IF('DATA ENTRY'!F16="TRUE",1,0)+IF('DATA ENTRY'!F39="TRUE",1,0)+IF('DATA ENTRY'!F53="TRUE",1,0)+IF('DATA ENTRY'!F65="TRUE",2,0)+IF('DATA ENTRY'!F76="TRUE",1,0)+IF('DATA ENTRY'!F90="TRUE",1,0) | D29: =C29*3 | E29: =MIN(115,MAX(0,D29+C50)) | F29: =MIN(115,MAX(0,E29)) | G29: =IF(F29>=85,"PROMINENT (Disorder)",IF(F29>=75,"CLINICALLY SIGNIFICANT",IF(F29>=60,"Trait Present","Not Significant"))) | H29: =IF(F29>=85,"***",IF(F29>=75,"**",IF(F29>=60,"*","")))
A30: C | B30: Borderline | C30: =IF('DATA ENTRY'!B11="TRUE",1,0)+IF('DATA ENTRY'!B16="TRUE",1,0)+IF('DATA ENTRY'!B21="TRUE",1,0)+IF('DATA ENTRY'!B26="TRUE",1,0)+IF('DATA ENTRY'!B31="TRUE",2,0)+IF('DATA ENTRY'!B39="TRUE",1,0)+IF('DATA ENTRY'!B45="TRUE",1,0)+IF('DATA ENTRY'!B52="TRUE",1,0)+IF('DATA ENTRY'!B55="TRUE",2,0)+IF('DATA ENTRY'!B66="TRUE",1,0)+IF('DATA ENTRY'!B76="TRUE",1,0)+IF('DATA ENTRY'!B81="TRUE",1,0)+IF('DATA ENTRY'!B86="TRUE",1,0)+IF('DATA ENTRY'!B92="TRUE",1,0)+IF('DATA ENTRY'!F9="TRUE",1,0)+IF('DATA ENTRY'!F37="TRUE",1,0)+IF('DATA ENTRY'!F43="TRUE",1,0)+IF('DATA ENTRY'!F78="TRUE",1,0)+IF('DATA ENTRY'!F83="TRUE",2,0) | D30: =C30*3 | E30: =MIN(115,MAX(0,D30+C50)) | F30: =MIN(115,MAX(0,E30)) | G30: =IF(F30>=85,"PROMINENT (Disorder)",IF(F30>=75,"CLINICALLY SIGNIFICANT",IF(F30>=60,"Trait Present","Not Significant"))) | H30: =IF(F30>=85,"***",IF(F30>=75,"**",IF(F30>=60,"*","")))
A31: P | B31: Paranoid | C31: =IF('DATA ENTRY'!B12="TRUE",1,0)+IF('DATA ENTRY'!B14="TRUE",2,0)+IF('DATA ENTRY'!B18="TRUE",1,0)+IF('DATA ENTRY'!B23="TRUE",1,0)+IF('DATA ENTRY'!B34="TRUE",1,0)+IF('DATA ENTRY'!B35="TRUE",2,0)+IF('DATA ENTRY'!B38="TRUE",1,0)+IF('DATA ENTRY'!B40="TRUE",1,0)+IF('DATA ENTRY'!B53="TRUE",1,0)+IF('DATA ENTRY'!B64="TRUE",1,0)+IF('DATA ENTRY'!B69="TRUE",1,0)+IF('DATA ENTRY'!B73="TRUE",1,0)+IF('DATA ENTRY'!B83="TRUE",1,0)+IF('DATA ENTRY'!B91="TRUE",1,0)+IF('DATA ENTRY'!F11="TRUE",1,0)+IF('DATA ENTRY'!F22="TRUE",1,0)+IF('DATA ENTRY'!F29="TRUE",1,0)+IF('DATA ENTRY'!F35="TRUE",1,0)+IF('DATA ENTRY'!F61="TRUE",2,0)+IF('DATA ENTRY'!F73="TRUE",1,0) | D31: =C31*3 | E31: =MIN(115,MAX(0,D31+C50)) | F31: =MIN(115,MAX(0,E31)) | G31: =IF(F31>=85,"PROMINENT (Disorder)",IF(F31>=75,"CLINICALLY SIGNIFICANT",IF(F31>=60,"Trait Present","Not Significant"))) | H31: =IF(F31>=85,"***",IF(F31>=75,"**",IF(F31>=60,"*","")))
A32: Clinical Syndrome
A33: A | B33: Anxiety | C33: =IF('DATA ENTRY'!B22="TRUE",1,0)+IF('DATA ENTRY'!B41="TRUE",1,0)+IF('DATA ENTRY'!B50="TRUE",2,0)+IF('DATA ENTRY'!B54="TRUE",1,0)+IF('DATA ENTRY'!B62="TRUE",1,0)+IF('DATA ENTRY'!B89="TRUE",1,0)+IF('DATA ENTRY'!B93="TRUE",1,0)+IF('DATA ENTRY'!F10="TRUE",1,0)+IF('DATA ENTRY'!F25="TRUE",1,0)+IF('DATA ENTRY'!F32="TRUE",1,0)+IF('DATA ENTRY'!F36="TRUE",2,0)+IF('DATA ENTRY'!F40="TRUE",1,0)+IF('DATA ENTRY'!F54="TRUE",1,0)+IF('DATA ENTRY'!F72="TRUE",1,0)+IF('DATA ENTRY'!F81="TRUE",1,0) | D33: =C33*3 | E33: =MIN(115,MAX(0,D33+C50)) | F33: =MIN(115,MAX(0,E33)) | G33: =IF(F33>=85,"PROMINENT (Disorder)",IF(F33>=75,"CLINICALLY SIGNIFICANT",IF(F33>=60,"Trait Present","Not Significant"))) | H33: =IF(F33>=85,"***",IF(F33>=75,"**",IF(F33>=60,"*","")))
A34: H | B34: Somatoform | C34: =IF('DATA ENTRY'!B22="TRUE",1,0)+IF('DATA ENTRY'!B41="TRUE",1,0)+IF('DATA ENTRY'!B54="TRUE",1,0)+IF('DATA ENTRY'!B67="TRUE",1,0)+IF('DATA ENTRY'!B82="TRUE",2,0)+IF('DATA ENTRY'!B93="TRUE",1,0)+IF('DATA ENTRY'!F10="TRUE",1,0)+IF('DATA ENTRY'!F18="TRUE",1,0)+IF('DATA ENTRY'!F25="TRUE",1,0)+IF('DATA ENTRY'!F32="TRUE",1,0)+IF('DATA ENTRY'!F50="TRUE",2,0)+IF('DATA ENTRY'!F54="TRUE",1,0)+IF('DATA ENTRY'!F81="TRUE",1,0) | D34: =C34*3 | E34: =MIN(115,MAX(0,D34+C50)) | F34: =MIN(115,MAX(0,E34)) | G34: =IF(F34>=85,"PROMINENT (Disorder)",IF(F34>=75,"CLINICALLY SIGNIFICANT",IF(F34>=60,"Trait Present","Not Significant"))) | H34: =IF(F34>=85,"***",IF(F34>=75,"**",IF(F34>=60,"*","")))
A35: N | B35: Bipolar: Manic | C35: =IF('DATA ENTRY'!B12="TRUE",1,0)+IF('DATA ENTRY'!B18="TRUE",1,0)+IF('DATA ENTRY'!B20="TRUE",1,0)+IF('DATA ENTRY'!B34="TRUE",1,0)+IF('DATA ENTRY'!B38="TRUE",1,0)+IF('DATA ENTRY'!B40="TRUE",1,0)+IF('DATA ENTRY'!B43="TRUE",2,0)+IF('DATA ENTRY'!B53="TRUE",1,0)+IF('DATA ENTRY'!B64="TRUE",1,0)+IF('DATA ENTRY'!B69="TRUE",1,0)+IF('DATA ENTRY'!B83="TRUE",1,0)+IF('DATA ENTRY'!B91="TRUE",1,0)+IF('DATA ENTRY'!F13="TRUE",2,0) | D35: =C35*3 | E35: =MIN(115,MAX(0,D35+C50)) | F35: =MIN(115,MAX(0,E35)) | G35: =IF(F35>=85,"PROMINENT (Disorder)",IF(F35>=75,"CLINICALLY SIGNIFICANT",IF(F35>=60,"Trait Present","Not Significant"))) | H35: =IF(F35>=85,"***",IF(F35>=75,"**",IF(F35>=60,"*","")))
A36: D | B36: Dysthymia | C36: =IF('DATA ENTRY'!B22="TRUE",1,0)+IF('DATA ENTRY'!B41="TRUE",1,0)+IF('DATA ENTRY'!B50="TRUE",1,0)+IF('DATA ENTRY'!B54="TRUE",1,0)+IF('DATA ENTRY'!B56="TRUE",2,0)+IF('DATA ENTRY'!B62="TRUE",1,0)+IF('DATA ENTRY'!B89="TRUE",1,0)+IF('DATA ENTRY'!B93="TRUE",1,0)+IF('DATA ENTRY'!F10="TRUE",1,0)+IF('DATA ENTRY'!F14="TRUE",1,0)+IF('DATA ENTRY'!F25="TRUE",1,0)+IF('DATA ENTRY'!F40="TRUE",1,0)+IF('DATA ENTRY'!F48="TRUE",2,0)+IF('DATA ENTRY'!F54="TRUE",1,0)+IF('DATA ENTRY'!F81="TRUE",1,0) | D36: =C36*3 | E36: =MIN(115,MAX(0,D36+C50)) | F36: =MIN(115,MAX(0,E36)) | G36: =IF(F36>=85,"PROMINENT (Disorder)",IF(F36>=75,"CLINICALLY SIGNIFICANT",IF(F36>=60,"Trait Present","Not Significant"))) | H36: =IF(F36>=85,"***",IF(F36>=75,"**",IF(F36>=60,"*","")))
A37: B | B37: Alcohol Dependence | C37: =IF('DATA ENTRY'!B12="TRUE",1,0)+IF('DATA ENTRY'!B18="TRUE",1,0)+IF('DATA ENTRY'!B34="TRUE",1,0)+IF('DATA ENTRY'!B40="TRUE",1,0)+IF('DATA ENTRY'!B53="TRUE",1,0)+IF('DATA ENTRY'!B58="TRUE",2,0)+IF('DATA ENTRY'!B64="TRUE",1,0)+IF('DATA ENTRY'!B69="TRUE",1,0)+IF('DATA ENTRY'!B83="TRUE",1,0)+IF('DATA ENTRY'!B91="TRUE",1,0)+IF('DATA ENTRY'!F22="TRUE",1,0)+IF('DATA ENTRY'!F29="TRUE",1,0)+IF('DATA ENTRY'!F47="TRUE",2,0)+IF('DATA ENTRY'!F49="TRUE",1,0)+IF('DATA ENTRY'!F73="TRUE",1,0) | D37: =C37*3 | E37: =MIN(115,MAX(0,D37+C50)) | F37: =MIN(115,MAX(0,E37)) | G37: =IF(F37>=85,"PROMINENT (Disorder)",IF(F37>=75,"CLINICALLY SIGNIFICANT",IF(F37>=60,"Trait Present","Not Significant"))) | H37: =IF(F37>=85,"***",IF(F37>=75,"**",IF(F37>=60,"*","")))
A38: T | B38: Drug Dependence | C38: =IF('DATA ENTRY'!B12="TRUE",1,0)+IF('DATA ENTRY'!B18="TRUE",1,0)+IF('DATA ENTRY'!B34="TRUE",1,0)+IF('DATA ENTRY'!B40="TRUE",1,0)+IF('DATA ENTRY'!B44="TRUE",2,0)+IF('DATA ENTRY'!B53="TRUE",1,0)+IF('DATA ENTRY'!B64="TRUE",1,0)+IF('DATA ENTRY'!B69="TRUE",1,0)+IF('DATA ENTRY'!B70="TRUE",2,0)+IF('DATA ENTRY'!B83="TRUE",1,0)+IF('DATA ENTRY'!B91="TRUE",1,0)+IF('DATA ENTRY'!F22="TRUE",1,0)+IF('DATA ENTRY'!F29="TRUE",1,0)+IF('DATA ENTRY'!F49="TRUE",1,0) | D38: =C38*3 | E38: =MIN(115,MAX(0,D38+C50)) | F38: =MIN(115,MAX(0,E38)) | G38: =IF(F38>=85,"PROMINENT (Disorder)",IF(F38>=75,"CLINICALLY SIGNIFICANT",IF(F38>=60,"Trait Present","Not Significant"))) | H38: =IF(F38>=85,"***",IF(F38>=75,"**",IF(F38>=60,"*","")))
A39: R | B39: PTSD | C39: =IF('DATA ENTRY'!B15="TRUE",2,0)+IF('DATA ENTRY'!B22="TRUE",1,0)+IF('DATA ENTRY'!B36="TRUE",2,0)+IF('DATA ENTRY'!B41="TRUE",1,0)+IF('DATA ENTRY'!B50="TRUE",1,0)+IF('DATA ENTRY'!B54="TRUE",1,0)+IF('DATA ENTRY'!B62="TRUE",1,0)+IF('DATA ENTRY'!B82="TRUE",1,0)+IF('DATA ENTRY'!B89="TRUE",1,0)+IF('DATA ENTRY'!B93="TRUE",1,0)+IF('DATA ENTRY'!F10="TRUE",1,0)+IF('DATA ENTRY'!F14="TRUE",1,0)+IF('DATA ENTRY'!F25="TRUE",1,0)+IF('DATA ENTRY'!F32="TRUE",1,0)+IF('DATA ENTRY'!F36="TRUE",1,0)+IF('DATA ENTRY'!F40="TRUE",1,0)+IF('DATA ENTRY'!F54="TRUE",1,0) | D39: =C39*3 | E39: =MIN(115,MAX(0,D39+C50)) | F39: =MIN(115,MAX(0,E39)) | G39: =IF(F39>=85,"PROMINENT (Disorder)",IF(F39>=75,"CLINICALLY SIGNIFICANT",IF(F39>=60,"Trait Present","Not Significant"))) | H39: =IF(F39>=85,"***",IF(F39>=75,"**",IF(F39>=60,"*","")))
A40: Severe Syndrome
A41: SS | B41: Thought Disorder | C41: =IF('DATA ENTRY'!B22="TRUE",1,0)+IF('DATA ENTRY'!B36="TRUE",2,0)+IF('DATA ENTRY'!B41="TRUE",1,0)+IF('DATA ENTRY'!B50="TRUE",1,0)+IF('DATA ENTRY'!B54="TRUE",1,0)+IF('DATA ENTRY'!B62="TRUE",1,0)+IF('DATA ENTRY'!B78="TRUE",2,0)+IF('DATA ENTRY'!B82="TRUE",1,0)+IF('DATA ENTRY'!B89="TRUE",1,0)+IF('DATA ENTRY'!B93="TRUE",1,0)+IF('DATA ENTRY'!F10="TRUE",1,0)+IF('DATA ENTRY'!F14="TRUE",1,0)+IF('DATA ENTRY'!F18="TRUE",1,0)+IF('DATA ENTRY'!F25="TRUE",1,0)+IF('DATA ENTRY'!F32="TRUE",1,0)+IF('DATA ENTRY'!F36="TRUE",1,0)+IF('DATA ENTRY'!F40="TRUE",1,0)+IF('DATA ENTRY'!F54="TRUE",1,0)+IF('DATA ENTRY'!F93="TRUE",2,0) | D41: =C41*3 | E41: =MIN(115,MAX(0,D41+C50)) | F41: =MIN(115,MAX(0,E41+C52)) | G41: =IF(F41>=85,"PROMINENT (Disorder)",IF(F41>=75,"CLINICALLY SIGNIFICANT",IF(F41>=60,"Trait Present","Not Significant"))) | H41: =IF(F41>=85,"***",IF(F41>=75,"**",IF(F41>=60,"*","")))
A42: CC | B42: Major Depression | C42: =IF('DATA ENTRY'!B15="TRUE",2,0)+IF('DATA ENTRY'!B22="TRUE",1,0)+IF('DATA ENTRY'!B41="TRUE",1,0)+IF('DATA ENTRY'!B50="TRUE",1,0)+IF('DATA ENTRY'!B54="TRUE",1,0)+IF('DATA ENTRY'!B56="TRUE",1,0)+IF('DATA ENTRY'!B62="TRUE",1,0)+IF('DATA ENTRY'!B82="TRUE",1,0)+IF('DATA ENTRY'!B89="TRUE",1,0)+IF('DATA ENTRY'!B93="TRUE",1,0)+IF('DATA ENTRY'!F10="TRUE",1,0)+IF('DATA ENTRY'!F14="TRUE",1,0)+IF('DATA ENTRY'!F18="TRUE",1,0)+IF('DATA ENTRY'!F25="TRUE",1,0)+IF('DATA ENTRY'!F27="TRUE",2,0)+IF('DATA ENTRY'!F40="TRUE",1,0)+IF('DATA ENTRY'!F48="TRUE",1,0)+IF('DATA ENTRY'!F54="TRUE",1,0)+IF('DATA ENTRY'!F66="TRUE",2,0) | D42: =C42*3 | E42: =MIN(115,MAX(0,D42+C50)) | F42: =MIN(115,MAX(0,E42+C53)) | G42: =IF(F42>=85,"PROMINENT (Disorder)",IF(F42>=75,"CLINICALLY SIGNIFICANT",IF(F42>=60,"Trait Present","Not Significant"))) | H42: =IF(F42>=85,"***",IF(F42>=75,"**",IF(F42>=60,"*","")))
...

Sheet PROFILE
A1: MCMI-III CLINICAL PROFILE
A2: Visual Profile - BR Scores with Clinical Thresholds
A4: PROTOCOL VALIDITY: | C4: ='AUTO-SCORING'!E9
A6: LEGEND:
A7: *** | B7: BR >= 85: PROMINENT (Disorder Present)
A8: ** | B8: BR 75-84: CLINICALLY SIGNIFICANT
A9: * | B9: BR 60-74: Trait/Tendency Present
B10: BR < 60: Not Significant
A12: Scale | B12: Name | C12: Raw | D12: Final BR | E12: Interpretation | F12: Lvl | G12: BR Bar Graph (0-115)
A13: X | B13: Disclosure | C13: ='AUTO-SCORING'!C46 | D13: ='AUTO-SCORING'!C46 | E13: =IF(D13>=85,"PROMINENT (Disorder)",IF(D13>=75,"CLINICALLY SIGNIFICANT",IF(D13>=60,"Trait Present","Not Significant"))) | F13: =IF(D13>=85,"***",IF(D13>=75,"**",IF(D13>=60,"*",""))) | G13: =REPT("█",MIN(45,INT(D13/2.5)))&" "&D13
A14: Y | B14: Desirability | C14: ='AUTO-SCORING'!C14 | D14: ='AUTO-SCORING'!F14 | E14: =IF(D14>=85,"PROMINENT (Disorder)",IF(D14>=75,"CLINICALLY SIGNIFICANT",IF(D14>=60,"Trait Present","Not Significant"))) | F14: =IF(D14>=85,"***",IF(D14>=75,"**",IF(D14>=60,"*",""))) | G14: =REPT("█",MIN(45,INT(D14/2.5)))&" "&D14
A15: Z | B15: Debasement | C15: ='AUTO-SCORING'!C15 | D15: ='AUTO-SCORING'!F15 | E15: =IF(D15>=85,"PROMINENT (Disorder)",IF(D15>=75,"CLINICALLY SIGNIFICANT",IF(D15>=60,"Trait Present","Not Significant"))) | F15: =IF(D15>=85,"***",IF(D15>=75,"**",IF(D15>=60,"*",""))) | G15: =REPT("█",MIN(45,INT(D15/2.5)))&" "&D15
A16: 1 | B16: Schizoid | C16: ='AUTO-SCORING'!C17 | D16: ='AUTO-SCORING'!F17 | E16: =IF(D16>=85,"PROMINENT (Disorder)",IF(D16>=75,"CLINICALLY SIGNIFICANT",IF(D16>=60,"Trait Present","Not Significant"))) | F16: =IF(D16>=85,"***",IF(D16>=75,"**",IF(D16>=60,"*",""))) | G16: =REPT("█",MIN(45,INT(D16/2.5)))&" "&D16
A17: 2A | B17: Avoidant | C17: ='AUTO-SCORING'!C18 | D17: ='AUTO-SCORING'!F18 | E17: =IF(D17>=85,"PROMINENT (Disorder)",IF(D17>=75,"CLINICALLY SIGNIFICANT",IF(D17>=60,"Trait Present","Not Significant"))) | F17: =IF(D17>=85,"***",IF(D17>=75,"**",IF(D17>=60,"*",""))) | G17: =REPT("█",MIN(45,INT(D17/2.5)))&" "&D17
A18: 2B | B18: Depressive | C18: ='AUTO-SCORING'!C19 | D18: ='AUTO-SCORING'!F19 | E18: =IF(D18>=85,"PROMINENT (Disorder)",IF(D18>=75,"CLINICALLY SIGNIFICANT",IF(D18>=60,"Trait Present","Not Significant"))) | F18: =IF(D18>=85,"***",IF(D18>=75,"**",IF(D18>=60,"*",""))) | G18: =REPT("█",MIN(45,INT(D18/2.5)))&" "&D18
A19: 3 | B19: Dependent | C19: ='AUTO-SCORING'!C20 | D19: ='AUTO-SCORING'!F20 | E19: =IF(D19>=85,"PROMINENT (Disorder)",IF(D19>=75,"CLINICALLY SIGNIFICANT",IF(D19>=60,"Trait Present","Not Significant"))) | F19: =IF(D19>=85,"***",IF(D19>=75,"**",IF(D19>=60,"*",""))) | G19: =REPT("█",MIN(45,INT(D19/2.5)))&" "&D19
A20: 4 | B20: Histrionic | C20: ='AUTO-SCORING'!C21 | D20: ='AUTO-SCORING'!F21 | E20: =IF(D20>=85,"PROMINENT (Disorder)",IF(D20>=75,"CLINICALLY SIGNIFICANT",IF(D20>=60,"Trait Present","Not Significant"))) | F20: =IF(D20>=85,"***",IF(D20>=75,"**",IF(D20>=60,"*",""))) | G20: =REPT("█",MIN(45,INT(D20/2.5)))&" "&D20
A21: 5 | B21: Narcissistic | C21: ='AUTO-SCORING'!C22 | D21: ='AUTO-SCORING'!F22 | E21: =IF(D21>=85,"PROMINENT (Disorder)",IF(D21>=75,"CLINICALLY SIGNIFICANT",IF(D21>=60,"Trait Present","Not Significant"))) | F21: =IF(D21>=85,"***",IF(D21>=75,"**",IF(D21>=60,"*",""))) | G21: =REPT("█",MIN(45,INT(D21/2.5)))&" "&D21
A22: 6A | B22: Antisocial | C22: ='AUTO-SCORING'!C23 | D22: ='AUTO-SCORING'!F23 | E22: =IF(D22>=85,"PROMINENT (Disorder)",IF(D22>=75,"CLINICALLY SIGNIFICANT",IF(D22>=60,"Trait Present","Not Significant"))) | F22: =IF(D22>=85,"***",IF(D22>=75,"**",IF(D22>=60,"*",""))) | G22: =REPT("█",MIN(45,INT(D22/2.5)))&" "&D22
A23: 6B | B23: Aggressive (Sadistic) | C23: ='AUTO-SCORING'!C24 | D23: ='AUTO-SCORING'!F24 | E23: =IF(D23>=85,"PROMINENT (Disorder)",IF(D23>=75,"CLINICALLY SIGNIFICANT",IF(D23>=60,"Trait Present","Not Significant"))) | F23: =IF(D23>=85,"***",IF(D23>=75,"**",IF(D23>=60,"*",""))) | G23: =REPT("█",MIN(45,INT(D23/2.5)))&" "&D23
A24: 7 | B24: Compulsive | C24: ='AUTO-SCORING'!C25 | D24: ='AUTO-SCORING'!F25 | E24: =IF(D24>=85,"PROMINENT (Disorder)",IF(D24>=75,"CLINICALLY SIGNIFICANT",IF(D24>=60,"Trait Present","Not Significant"))) | F24: =IF(D24>=85,"***",IF(D24>=75,"**",IF(D24>=60,"*",""))) | G24: =REPT("█",MIN(45,INT(D24/2.5)))&" "&D24
A25: 8A | B25: Negativistic | C25: ='AUTO-SCORING'!C26 | D25: ='AUTO-SCORING'!F26 | E25: =IF(D25>=85,"PROMINENT (Disorder)",IF(D25>=75,"CLINICALLY SIGNIFICANT",IF(D25>=60,"Trait Present","Not Significant"))) | F25: =IF(D25>=85,"***",IF(D25>=75,"**",IF(D25>=60,"*",""))) | G25: =REPT("█",MIN(45,INT(D25/2.5)))&" "&D25
A26: 8B | B26: Masochistic | C26: ='AUTO-SCORING'!C27 | D26: ='AUTO-SCORING'!F27 | E26: =IF(D26>=85,"PROMINENT (Disorder)",IF(D26>=75,"CLINICALLY SIGNIFICANT",IF(D26>=60,"Trait Present","Not Significant"))) | F26: =IF(D26>=85,"***",IF(D26>=75,"**",IF(D26>=60,"*",""))) | G26: =REPT("█",MIN(45,INT(D26/2.5)))&" "&D26
A27: S | B27: Schizotypal | C27: ='AUTO-SCORING'!C29 | D27: ='AUTO-SCORING'!F29 | E27: =IF(D27>=85,"PROMINENT (Disorder)",IF(D27>=75,"CLINICALLY SIGNIFICANT",IF(D27>=60,"Trait Present","Not Significant"))) | F27: =IF(D27>=85,"***",IF(D27>=75,"**",IF(D27>=60,"*",""))) | G27: =REPT("█",MIN(45,INT(D27/2.5)))&" "&D27
A28: C | B28: Borderline | C28: ='AUTO-SCORING'!C30 | D28: ='AUTO-SCORING'!F30 | E28: =IF(D28>=85,"PROMINENT (Disorder)",IF(D28>=75,"CLINICALLY SIGNIFICANT",IF(D28>=60,"Trait Present","Not Significant"))) | F28: =IF(D28>=85,"***",IF(D28>=75,"**",IF(D28>=60,"*",""))) | G28: =REPT("█",MIN(45,INT(D28/2.5)))&" "&D28
A29: P | B29: Paranoid | C29: ='AUTO-SCORING'!C31 | D29: ='AUTO-SCORING'!F31 | E29: =IF(D29>=85,"PROMINENT (Disorder)",IF(D29>=75,"CLINICALLY SIGNIFICANT",IF(D29>=60,"Trait Present","Not Significant"))) | F29: =IF(D29>=85,"***",IF(D29>=75,"**",IF(D29>=60,"*",""))) | G29: =REPT("█",MIN(45,INT(D29/2.5)))&" "&D29
A30: A | B30: Anxiety | C30: ='AUTO-SCORING'!C33 | D30: ='AUTO-SCORING'!F33 | E30: =IF(D30>=85,"PROMINENT (Disorder)",IF(D30>=75,"CLINICALLY SIGNIFICANT",IF(D30>=60,"Trait Present","Not Significant"))) | F30: =IF(D30>=85,"***",IF(D30>=75,"**",IF(D30>=60,"*",""))) | G30: =REPT("█",MIN(45,INT(D30/2.5)))&" "&D30
A31: H | B31: Somatoform | C31: ='AUTO-SCORING'!C34 | D31: ='AUTO-SCORING'!F34 | E31: =IF(D31>=85,"PROMINENT (Disorder)",IF(D31>=75,"CLINICALLY SIGNIFICANT",IF(D31>=60,"Trait Present","Not Significant"))) | F31: =IF(D31>=85,"***",IF(D31>=75,"**",IF(D31>=60,"*",""))) | G31: =REPT("█",MIN(45,INT(D31/2.5)))&" "&D31
A32: N | B32: Bipolar: Manic | C32: ='AUTO-SCORING'!C35 | D32: ='AUTO-SCORING'!F35 | E32: =IF(D32>=85,"PROMINENT (Disorder)",IF(D32>=75,"CLINICALLY SIGNIFICANT",IF(D32>=60,"Trait Present","Not Significant"))) | F32: =IF(D32>=85,"***",IF(D32>=75,"**",IF(D32>=60,"*",""))) | G32: =REPT("█",MIN(45,INT(D32/2.5)))&" "&D32
A33: D | B33: Dysthymia | C33: ='AUTO-SCORING'!C36 | D33: ='AUTO-SCORING'!F36 | E33: =IF(D33>=85,"PROMINENT (Disorder)",IF(D33>=75,"CLINICALLY SIGNIFICANT",IF(D33>=60,"Trait Present","Not Significant"))) | F33: =IF(D33>=85,"***",IF(D33>=75,"**",IF(D33>=60,"*",""))) | G33: =REPT("█",MIN(45,INT(D33/2.5)))&" "&D33
A34: B | B34: Alcohol Dependence | C34: ='AUTO-SCORING'!C37 | D34: ='AUTO-SCORING'!F37 | E34: =IF(D34>=85,"PROMINENT (Disorder)",IF(D34>=75,"CLINICALLY SIGNIFICANT",IF(D34>=60,"Trait Present","Not Significant"))) | F34: =IF(D34>=85,"***",IF(D34>=75,"**",IF(D34>=60,"*",""))) | G34: =REPT("█",MIN(45,INT(D34/2.5)))&" "&D34
A35: T | B35: Drug Dependence | C35: ='AUTO-SCORING'!C38 | D35: ='AUTO-SCORING'!F38 | E35: =IF(D35>=85,"PROMINENT (Disorder)",IF(D35>=75,"CLINICALLY SIGNIFICANT",IF(D35>=60,"Trait Present","Not Significant"))) | F35: =IF(D35>=85,"***",IF(D35>=75,"**",IF(D35>=60,"*",""))) | G35: =REPT("█",MIN(45,INT(D35/2.5)))&" "&D35
A36: R | B36: PTSD | C36: ='AUTO-SCORING'!C39 | D36: ='AUTO-SCORING'!F39 | E36: =IF(D36>=85,"PROMINENT (Disorder)",IF(D36>=75,"CLINICALLY SIGNIFICANT",IF(D36>=60,"Trait Present","Not Significant"))) | F36: =IF(D36>=85,"***",IF(D36>=75,"**",IF(D36>=60,"*",""))) | G36: =REPT("█",MIN(45,INT(D36/2.5)))&" "&D36
A37: SS | B37: Thought Disorder | C37: ='AUTO-SCORING'!C41 | D37: ='AUTO-SCORING'!F41 | E37: =IF(D37>=85,"PROMINENT (Disorder)",IF(D37>=75,"CLINICALLY SIGNIFICANT",IF(D37>=60,"Trait Present","Not Significant"))) | F37: =IF(D37>=85,"***",IF(D37>=75,"**",IF(D37>=60,"*",""))) | G37: =REPT("█",MIN(45,INT(D37/2.5)))&" "&D37
A38: CC | B38: Major Depression | C38: ='AUTO-SCORING'!C42 | D38: ='AUTO-SCORING'!F42 | E38: =IF(D38>=85,"PROMINENT (Disorder)",IF(D38>=75,"CLINICALLY SIGNIFICANT",IF(D38>=60,"Trait Present","Not Significant"))) | F38: =IF(D38>=85,"***",IF(D38>=75,"**",IF(D38>=60,"*",""))) | G38: =REPT("█",MIN(45,INT(D38/2.5)))&" "&D38
A39: PP | B39: Delusional Disorder | C39: ='AUTO-SCORING'!C43 | D39: ='AUTO-SCORING'!F43 | E39: =IF(D39>=85,"PROMINENT (Disorder)",IF(D39>=75,"CLINICALLY SIGNIFICANT",IF(D39>=60,"Trait Present","Not Significant"))) | F39: =IF(D39>=85,"***",IF(D39>=75,"**",IF(D39>=60,"*",""))) | G39: =REPT("█",MIN(45,INT(D39/2.5)))&" "&D39
A42: CLINICAL THRESHOLDS:
A43: BR 60 = Clinical threshold for trait presence
A44: BR 75 = Threshold for clinically significant presence
A45: BR 85 = Threshold for prominent/disorder presence
...

Sheet BR REFERENCE
A1: MCMI-III BR SCORING REFERENCE TABLES
A3: BR SCORE INTERPRETATION
A4: BR Range | B4: Level | C4: Meaning
A5: < 60 | B5: Not Significant | C5: No pathological trait
A6: 60-74 | B6: Trait Present | C6: Subclinical trait/tendency
A7: 75-84 | B7: Clinically Significant | C7: Syndrome/disorder present
A8: >= 85 | B8: PROMINENT | C8: Disorder is a prominent feature
A11: DISCLOSURE ADJUSTMENT (Table 1)
A12: Scale X Raw | B12: 1-8B Adj | C12: S-PP Adj
A13: 34-37 | B13: +20 | C13: +10
A14: 38 | B14: +19 | C14: +10
A15: 39 | B15: +18 | C15: +10
A16: 40-41 | B16: +17 | C16: +9
A17: 42 | B17: +16 | C17: +9
A18: 43 | B18: +15 | C18: +8
A19: 44 | B19: +14 | C19: +8
A20: 45 | B20: +13 | C20: +7
A21: 46 | B21: +12 | C21: +7
A22: 47 | B22: +11 | C22: +6
A23: 48 | B23: +10 | C23: +6
... A59: 172-178 | B59: -20 | C59: -13 to -14
A62: INPATIENT ADJUSTMENT (Table 5)
A63: Duration | B63: SS Adj | C63: CC Adj | D63: PP Adj
A64: < 1 week | B64: +6 | C64: +10 | D64: +4
A65: 1-4 weeks | B65: +4 | C65: +8 | D65: +2
A66: > 4 weeks | B66: 0 | C66: 0 | D66: 0
A67: Not inpatient | B67: 0 | C67: 0 | D67: 0
A70: A/D ADJUSTMENT (Tables 2-4)
A71: Affects: Scales 2A, 2B, 8B, S, C
A72: If A BR < 75 AND D BR < 75: No adjustment
A73: If A BR >= 75: A/D value = A - 75
A74: If D BR >= 75: A/D value = D - 75
A75: If both >= 75: A/D value = (A-75) + (D-75)
A76: Use Table 2 for OPD; Table 3 for IPD < 1wk; Table 4 for IPD 1-4wk
