Workbook

Sheet DATA
A1: MCMI-III DATA ENTRY | D1: Age: | F1: Setting: | G1: OPD | H1: AxisI wks:
A2: Type T (True) or F (False) for each item
A3: Item | B3: Response | D3: Answered: | E3: =COUNTA(B4:B178) | F3: /175
A4: 1
A5: 2
A6: 3
A7: 4
A8: 5
A9: 6
A10: 7
A11: 8
A12: 9
A13: 10
A14: 11
A15: 12
... A178: 175

Sheet SCORES
A1: MCMI-III SCORING RESULTS
A3: VALIDITY
C4: Value | D4: Limit | E4: Status
A5: Omits | C5: =175-COUNTA(DATA!B4:B178) | D5: <=11 | E5: =IF(C5>11,"INVALID","OK")
A6: V | C6: =IF(DATA!B68="T",1,0)+IF(DATA!B113="T",1,0)+IF(DATA!B160="T",1,0) | D6: <2 | E6: =IF(C6>=2,"INVALID",IF(C6=1,"CAUTION","OK"))
A7: W | C7: =IF(AND(DATA!B6<>"",DATA!B152<>"",DATA!B6<>DATA!B152),1,0)+IF(AND(DATA!B13<>"",DATA!B168<>"",DATA!B13<>DATA!B168),1,0)+IF(AND(DATA!B17<>"",DATA!B97<>"",DATA!B17<>DATA!B97),1,0)+IF(AND(DATA!B18<>"",DATA!B64<>"",DATA!B18<>DATA!B64),1,0)+IF(AND(DATA!B22<>"",DATA!B153<>"",DATA!B22<>DATA!B153),1,0)+IF(AND(DATA!B28<>"",DATA!B133<>"",DATA!B28<>DATA!B133),1,0)+IF(AND(DATA!B42<>"",DATA!B159<>"",DATA!B42<>DATA!B159),1,0)+IF(AND(DATA!B45<>"",DATA!B96<>"",DATA!B45<>DATA!B96),1,0)+IF(AND(DATA!B52<>"",DATA!B155<>"",DATA!B52<>DATA!B155),1,0)+IF(AND(DATA!B60<>"",DATA!B100<>"",DATA!B60<>DATA!B100),1,0)+IF(AND(DATA!B63<>"",DATA!B108<>"",DATA!B63<>DATA!B108),1,0)+IF(AND(DATA!B65<>"",DATA!B114<>"",DATA!B65<>DATA!B114),1,0)+IF(AND(DATA!B69<>"",DATA!B120<>"",DATA!B69<>DATA!B120),1,0)+IF(AND(DATA!B70<>"",DATA!B158<>"",DATA!B70<>DATA!B158),1,0)+IF(AND(DATA!B73<>"",DATA!B122<>"",DATA!B73<>DATA!B122),1,0)+IF(AND(DATA!B76<>"",DATA!B123<>"",DATA!B76<>DATA!B123),1,0)+IF(AND(DATA!B78<>"",DATA!B163<>"",DATA!B78<>DATA!B163),1,0)+IF(AND(DATA!B82<>"",DATA!B128<>"",DATA!B82<>DATA!B128),1,0)+IF(AND(DATA!B83<>"",DATA!B169<>"",DATA!B83<>DATA!B169),1,0)+IF(AND(DATA!B87<>"",DATA!B130<>"",DATA!B87<>DATA!B130),1,0)+IF(AND(DATA!B89<>"",DATA!B131<>"",DATA!B89<>DATA!B131),1,0)+IF(AND(DATA!B92<>"",DATA!B137<>"",DATA!B92<>DATA!B137),1,0)+IF(AND(DATA!B94<>"",DATA!B172<>"",DATA!B94<>DATA!B172),1,0)+IF(AND(DATA!B101<>"",DATA!B141<>"",DATA!B101<>DATA!B141),1,0)+IF(AND(DATA!B104<>"",DATA!B145<>"",DATA!B104<>DATA!B145),1,0)+IF(AND(DATA!B105<>"",DATA!B146<>"",DATA!B105<>DATA!B146),1,0)+IF(AND(DATA!B107<>"",DATA!B147<>"",DATA!B107<>DATA!B147),1,0)+IF(AND(DATA!B111<>"",DATA!B150<>"",DATA!B111<>DATA!B150),1,0)+IF(AND(DATA!B115<>"",DATA!B154<>"",DATA!B115<>DATA!B154),1,0)+IF(AND(DATA!B119<>"",DATA!B156<>"",DATA!B119<>DATA!B156),1,0)+IF(AND(DATA!B5<>"",DATA!B91<>"",DATA!B5<>DATA!B91),1,0)+IF(AND(DATA!B8<>"",DATA!B80<>"",DATA!B8<>DATA!B80),1,0)+IF(AND(DATA!B14<>"",DATA!B57<>"",DATA!B14<>DATA!B57),1,0)+IF(AND(DATA!B23<>"",DATA!B140<>"",DATA!B23<>DATA!B140),1,0)+IF(AND(DATA!B25<>"",DATA!B124<>"",DATA!B25<>DATA!B124),1,0)+IF(AND(DATA!B34<>"",DATA!B164<>"",DATA!B34<>DATA!B164),1,0)+IF(AND(DATA!B40<>"",DATA!B66<>"",DATA!B40<>DATA!B66),1,0)+IF(AND(DATA!B43<>"",DATA!B167<>"",DATA!B43<>DATA!B167),1,0)+IF(AND(DATA!B44<>"",DATA!B142<>"",DATA!B44<>DATA!B142),1,0)+IF(AND(DATA!B48<>"",DATA!B84<>"",DATA!B48<>DATA!B84),1,0)+IF(AND(DATA!B49<>"",DATA!B81<>"",DATA!B49<>DATA!B81),1,0)+IF(AND(DATA!B54<>"",DATA!B161<>"",DATA!B54<>DATA!B161),1,0)+IF(AND(DATA!B56<>"",DATA!B138<>"",DATA!B56<>DATA!B138),1,0)+IF(AND(DATA!B58<>"",DATA!B175<>"",DATA!B58<>DATA!B175),1,0) | D7: <10 | E7: =IF(C7>=10,"INVALID",IF(C7>=8,"CAUTION","OK"))
B8: OVERALL | E8: =IF(OR(E5="INVALID",E6="INVALID",E7="INVALID"),"INVALID",IF(OR(E6="CAUTION",E7="CAUTION"),"QUESTIONABLE","VALID"))
A10: SCALES
A11: Scale | B11: Name | C11: Raw | D11: BR | E11: Adj | F11: Final BR | H11: Interpretation
A12: Y | B12: Desirability | C12: =IF(DATA!B7="T",1,0)+IF(DATA!B10="T",2,0)+IF(DATA!B29="T",2,0)+IF(DATA!B71="T",1,0)+IF(DATA!B77="T",1,0)+IF(DATA!B85="T",1,0)+IF(DATA!B91="T",2,0)+IF(DATA!B93="T",1,0)+IF(DATA!B98="T",1,0)+IF(DATA!B102="T",1,0)+IF(DATA!B106="T",2,0)+IF(DATA!B109="T",1,0)+IF(DATA!B116="T",1,0)+IF(DATA!B134="T",1,0)+IF(DATA!B136="T",2,0)+IF(DATA!B143="T",1,0)+IF(DATA!B148="T",1,0)+IF(DATA!B156="T",1,0)+IF(DATA!B165="T",1,0)+IF(DATA!B170="T",1,0)+IF(DATA!B173="T",1,0) | D12: =MIN(115,MAX(0,ROUND(IF(C12>=34,110+2.5*(C12-34),IF(C12>=32,105+2.5*(C12-32),IF(C12>=30,100+2.5*(C12-30),IF(C12>=28,95+2.5*(C12-28),IF(C12>=26,90+2.5*(C12-26),IF(C12>=24,85+2.5*(C12-24),IF(C12>=22,80+2.5*(C12-22),IF(C12>=20,75+2.5*(C12-20),IF(C12>=18,70+2.5*(C12-18),IF(C12>=16,65+2.5*(C12-16),IF(C12>=14,60+2.5*(C12-14),IF(C12>=12,55+2.5*(C12-12),IF(C12>=10,50+2.5*(C12-10),IF(C12>=8,40+5.0*(C12-8),IF(C12>=6,30+5.0*(C12-6),IF(C12>=4,20+5.0*(C12-4),IF(C12>=2,10+5.0*(C12-2),IF(C12>=0,0+5.0*(C12-0),0)))))))))))))))))),0))) | E12: 0 | F12: =MIN(115,MAX(0,D12+E12)) | H12: =IF(F12>=85,"PROMINENT",IF(F12>=75,"SIGNIFICANT",IF(F12>=60,"Trait","Not Sig.")))
A13: Z | B13: Debasement | C13: =IF(DATA!B12="T",2,0)+IF(DATA!B19="T",1,0)+IF(DATA!B33="T",2,0)+IF(DATA!B38="T",1,0)+IF(DATA!B47="T",1,0)+IF(DATA!B51="T",1,0)+IF(DATA!B53="T",1,0)+IF(DATA!B59="T",1,0)+IF(DATA!B64="T",1,0)+IF(DATA!B75="T",2,0)+IF(DATA!B79="T",1,0)+IF(DATA!B86="T",1,0)+IF(DATA!B90="T",1,0)+IF(DATA!B95="T",1,0)+IF(DATA!B99="T",1,0)+IF(DATA!B103="T",1,0)+IF(DATA!B110="T",1,0)+IF(DATA!B112="T",2,0)+IF(DATA!B117="T",1,0)+IF(DATA!B121="T",1,0)+IF(DATA!B125="T",1,0)+IF(DATA!B129="T",1,0)+IF(DATA!B135="T",1,0)+IF(DATA!B139="T",1,0)+IF(DATA!B144="T",1,0)+IF(DATA!B149="T",1,0)+IF(DATA!B151="T",2,0)+IF(DATA!B157="T",1,0)+IF(DATA!B162="T",1,0)+IF(DATA!B166="T",1,0)+IF(DATA!B171="T",1,0)+IF(DATA!B174="T",1,0)+IF(DATA!B178="T",2,0) | D13: =MIN(115,MAX(0,ROUND(IF(C13>=51,110+1.6667*(C13-51),IF(C13>=48,105+1.6667*(C13-48),IF(C13>=45,100+1.6667*(C13-45),IF(C13>=42,95+1.6667*(C13-42),IF(C13>=39,90+1.6667*(C13-39),IF(C13>=36,85+1.6667*(C13-36),IF(C13>=33,80+1.6667*(C13-33),IF(C13>=30,75+1.6667*(C13-30),IF(C13>=27,70+1.6667*(C13-27),IF(C13>=24,65+1.6667*(C13-24),IF(C13>=21,60+1.6667*(C13-21),IF(C13>=18,55+1.6667*(C13-18),IF(C13>=15,50+1.6667*(C13-15),IF(C13>=12,40+3.3333*(C13-12),IF(C13>=9,30+3.3333*(C13-9),IF(C13>=6,20+3.3333*(C13-6),IF(C13>=3,10+3.3333*(C13-3),IF(C13>=0,0+3.3333*(C13-0),0)))))))))))))))))),0))) | E13: 0 | F13: =MIN(115,MAX(0,D13+E13)) | H13: =IF(F13>=85,"PROMINENT",IF(F13>=75,"SIGNIFICANT",IF(F13>=60,"Trait","Not Sig.")))
A14: 1 | B14: Schizoid | C14: =IF(DATA!B5="T",1,0)+IF(DATA!B25="T",1,0)+IF(DATA!B27="T",2,0)+IF(DATA!B44="T",1,0)+IF(DATA!B48="T",1,0)+IF(DATA!B56="T",1,0)+IF(DATA!B59="T",1,0)+IF(DATA!B60="T",2,0)+IF(DATA!B74="T",1,0)+IF(DATA!B84="T",1,0)+IF(DATA!B101="T",1,0)+IF(DATA!B124="T",1,0)+IF(DATA!B138="T",1,0)+IF(DATA!B150="T",2,0)+IF(DATA!B161="T",1,0)+IF(DATA!B175="T",1,0) | D14: =MIN(115,MAX(0,ROUND(IF(C14>=32,110+2.5*(C14-32),IF(C14>=30,105+2.5*(C14-30),IF(C14>=28,100+2.5*(C14-28),IF(C14>=26,95+2.5*(C14-26),IF(C14>=24,90+2.5*(C14-24),IF(C14>=22,85+2.5*(C14-22),IF(C14>=20,80+2.5*(C14-20),IF(C14>=18,75+2.5*(C14-18),IF(C14>=16,70+2.5*(C14-16),IF(C14>=14,65+2.5*(C14-14),IF(C14>=12,60+2.5*(C14-12),IF(C14>=10,55+2.5*(C14-10),IF(C14>=8,48+3.5*(C14-8),IF(C14>=6,38+5.0*(C14-6),IF(C14>=4,28+5.0*(C14-4),IF(C14>=2,15+6.5*(C14-2),IF(C14>=0,0+7.5*(C14-0),0))))))))))))))))),0))) | E14: =C41 | F14: =MIN(115,MAX(0,D14+E14)) | H14: =IF(F14>=85,"PROMINENT",IF(F14>=75,"SIGNIFICANT",IF(F14>=60,"Trait","Not Sig.")))
A15: 2A | B15: Avoidant | C15: =IF(DATA!B5="T",1,0)+IF(DATA!B23="T",1,0)+IF(DATA!B25="T",1,0)+IF(DATA!B44="T",1,0)+IF(DATA!B49="T",2,0)+IF(DATA!B56="T",1,0)+IF(DATA!B59="T",1,0)+IF(DATA!B74="T",1,0)+IF(DATA!B81="T",2,0)+IF(DATA!B84="T",1,0)+IF(DATA!B101="T",1,0)+IF(DATA!B124="T",1,0)+IF(DATA!B138="T",1,0)+IF(DATA!B150="T",2,0)+IF(DATA!B161="T",1,0)+IF(DATA!B175="T",1,0) | D15: =MIN(115,MAX(0,ROUND(IF(C15>=34,113+1.0*(C15-34),IF(C15>=32,108+2.5*(C15-32),IF(C15>=30,103+2.5*(C15-30),IF(C15>=28,98+2.5*(C15-28),IF(C15>=26,93+2.5*(C15-26),IF(C15>=24,88+2.5*(C15-24),IF(C15>=22,83+2.5*(C15-22),IF(C15>=20,78+2.5*(C15-20),IF(C15>=18,73+2.5*(C15-18),IF(C15>=16,68+2.5*(C15-16),IF(C15>=14,63+2.5*(C15-14),IF(C15>=12,58+2.5*(C15-12),IF(C15>=10,52+3.0*(C15-10),IF(C15>=8,45+3.5*(C15-8),IF(C15>=6,35+5.0*(C15-6),IF(C15>=4,24+5.5*(C15-4),IF(C15>=2,12+6.0*(C15-2),IF(C15>=0,0+6.0*(C15-0),0)))))))))))))))))),0))) | E15: =C41 | F15: =MIN(115,MAX(0,D15+E15)) | H15: =IF(F15>=85,"PROMINENT",IF(F15>=75,"SIGNIFICANT",IF(F15>=60,"Trait","Not Sig.")))
A16: 2B | B16: Depressive | C16: =IF(DATA!B5="T",1,0)+IF(DATA!B23="T",2,0)+IF(DATA!B25="T",1,0)+IF(DATA!B44="T",1,0)+IF(DATA!B53="T",2,0)+IF(DATA!B56="T",1,0)+IF(DATA!B59="T",1,0)+IF(DATA!B74="T",1,0)+IF(DATA!B84="T",1,0)+IF(DATA!B101="T",1,0)+IF(DATA!B124="T",1,0)+IF(DATA!B133="T",2,0)+IF(DATA!B138="T",1,0)+IF(DATA!B161="T",1,0)+IF(DATA!B175="T",1,0) | D16: =MIN(115,MAX(0,ROUND(IF(C16>=34,114+0.5*(C16-34),IF(C16>=32,109+2.5*(C16-32),IF(C16>=30,104+2.5*(C16-30),IF(C16>=28,99+2.5*(C16-28),IF(C16>=26,94+2.5*(C16-26),IF(C16>=24,89+2.5*(C16-24),IF(C16>=22,84+2.5*(C16-22),IF(C16>=20,79+2.5*(C16-20),IF(C16>=18,74+2.5*(C16-18),IF(C16>=16,69+2.5*(C16-16),IF(C16>=14,64+2.5*(C16-14),IF(C16>=12,59+2.5*(C16-12),IF(C16>=10,53+3.0*(C16-10),IF(C16>=8,45+4.0*(C16-8),IF(C16>=6,35+5.0*(C16-6),IF(C16>=4,24+5.5*(C16-4),IF(C16>=2,12+6.0*(C16-2),IF(C16>=0,0+6.0*(C16-0),0)))))))))))))))))),0))) | E16: =C41 | F16: =MIN(115,MAX(0,D16+E16)) | H16: =IF(F16>=85,"PROMINENT",IF(F16>=75,"SIGNIFICANT",IF(F16>=60,"Trait","Not Sig.")))
A17: 3 | B17: Dependent | C17: =IF(DATA!B6="T",2,0)+IF(DATA!B8="T",1,0)+IF(DATA!B18="T",1,0)+IF(DATA!B22="T",2,0)+IF(DATA!B25="T",1,0)+IF(DATA!B36="T",1,0)+IF(DATA!B42="T",2,0)+IF(DATA!B48="T",1,0)+IF(DATA!B63="T",1,0)+IF(DATA!B73="T",1,0)+IF(DATA!B78="T",1,0)+IF(DATA!B83="T",1,0)+IF(DATA!B89="T",1,0)+IF(DATA!B94="T",1,0)+IF(DATA!B122="T",1,0)+IF(DATA!B128="T",1,0)+IF(DATA!B163="T",1,0)+IF(DATA!B169="T",1,0)+IF(DATA!B172="T",1,0) | D17: =MIN(115,MAX(0,ROUND(IF(C17>=36,114+0.5*(C17-36),IF(C17>=34,109+2.5*(C17-34),IF(C17>=32,104+2.5*(C17-32),IF(C17>=30,99+2.5*(C17-30),IF(C17>=28,94+2.5*(C17-28),IF(C17>=26,89+2.5*(C17-26),IF(C17>=24,84+2.5*(C17-24),IF(C17>=22,79+2.5*(C17-22),IF(C17>=20,74+2.5*(C17-20),IF(C17>=18,69+2.5*(C17-18),IF(C17>=16,64+2.5*(C17-16),IF(C17>=14,59+2.5*(C17-14),IF(C17>=12,54+2.5*(C17-12),IF(C17>=10,48+3.0*(C17-10),IF(C17>=8,40+4.0*(C17-8),IF(C17>=6,30+5.0*(C17-6),IF(C17>=4,20+5.0*(C17-4),IF(C17>=2,10+5.0*(C17-2),IF(C17>=0,0+5.0*(C17-0),0))))))))))))))))))),0))) | E17: =C41 | F17: =MIN(115,MAX(0,D17+E17)) | H17: =IF(F17>=85,"PROMINENT",IF(F17>=75,"SIGNIFICANT",IF(F17>=60,"Trait","Not Sig.")))
A18: 4 | B18: Histrionic | C18: =IF(DATA!B10="T",1,0)+IF(DATA!B17="T",1,0)+IF(DATA!B29="T",1,0)+IF(DATA!B35="T",1,0)+IF(DATA!B40="T",2,0)+IF(DATA!B43="T",1,0)+IF(DATA!B45="T",1,0)+IF(DATA!B60="T",1,0)+IF(DATA!B69="T",1,0)+IF(DATA!B81="T",1,0)+IF(DATA!B91="T",1,0)+IF(DATA!B96="T",1,0)+IF(DATA!B98="T",2,0)+IF(DATA!B106="T",1,0)+IF(DATA!B109="T",1,0)+IF(DATA!B114="T",1,0)+IF(DATA!B134="T",1,0)+IF(DATA!B158="T",2,0)+IF(DATA!B167="T",1,0) | D18: =MIN(115,MAX(0,ROUND(IF(C18>=48,110+2.5*(C18-48),IF(C18>=45,105+1.6667*(C18-45),IF(C18>=42,100+1.6667*(C18-42),IF(C18>=39,95+1.6667*(C18-39),IF(C18>=36,90+1.6667*(C18-36),IF(C18>=33,85+1.6667*(C18-33),IF(C18>=30,80+1.6667*(C18-30),IF(C18>=27,75+1.6667*(C18-27),IF(C18>=24,70+1.6667*(C18-24),IF(C18>=21,65+1.6667*(C18-21),IF(C18>=18,60+1.6667*(C18-18),IF(C18>=15,54+2.0*(C18-15),IF(C18>=12,47+2.3333*(C18-12),IF(C18>=9,38+3.0*(C18-9),IF(C18>=6,28+3.3333*(C18-6),IF(C18>=3,15+4.3333*(C18-3),IF(C18>=0,0+5.0*(C18-0),0))))))))))))))))),0))) | E18: =C41 | F18: =MIN(115,MAX(0,D18+E18)) | H18: =IF(F18>=85,"PROMINENT",IF(F18>=75,"SIGNIFICANT",IF(F18>=60,"Trait","Not Sig.")))
A19: 5 | B19: Narcissistic | C19: =IF(DATA!B4="T",1,0)+IF(DATA!B10="T",1,0)+IF(DATA!B17="T",1,0)+IF(DATA!B29="T",1,0)+IF(DATA!B35="T",1,0)+IF(DATA!B40="T",2,0)+IF(DATA!B43="T",1,0)+IF(DATA!B45="T",1,0)+IF(DATA!B60="T",1,0)+IF(DATA!B66="T",1,0)+IF(DATA!B69="T",1,0)+IF(DATA!B70="T",2,0)+IF(DATA!B81="T",1,0)+IF(DATA!B88="T",1,0)+IF(DATA!B91="T",1,0)+IF(DATA!B96="T",1,0)+IF(DATA!B106="T",1,0)+IF(DATA!B114="T",1,0)+IF(DATA!B120="T",2,0)+IF(DATA!B134="T",1,0)+IF(DATA!B143="T",1,0)+IF(DATA!B148="T",1,0)+IF(DATA!B158="T",1,0)+IF(DATA!B167="T",1,0) | D19: =MIN(115,MAX(0,ROUND(IF(C19>=51,112+1.0*(C19-51),IF(C19>=48,107+1.6667*(C19-48),IF(C19>=45,102+1.6667*(C19-45),IF(C19>=42,97+1.6667*(C19-42),IF(C19>=39,92+1.6667*(C19-39),IF(C19>=36,87+1.6667*(C19-36),IF(C19>=33,82+1.6667*(C19-33),IF(C19>=30,77+1.6667*(C19-30),IF(C19>=27,72+1.6667*(C19-27),IF(C19>=24,67+1.6667*(C19-24),IF(C19>=21,62+1.6667*(C19-21),IF(C19>=18,56+2.0*(C19-18),IF(C19>=15,50+2.0*(C19-15),IF(C19>=12,42+2.6667*(C19-12),IF(C19>=9,33+3.0*(C19-9),IF(C19>=6,23+3.3333*(C19-6),IF(C19>=3,12+3.6667*(C19-3),IF(C19>=0,0+4.0*(C19-0),0)))))))))))))))))),0))) | E19: =C41 | F19: =MIN(115,MAX(0,D19+E19)) | H19: =IF(F19>=85,"PROMINENT",IF(F19>=75,"SIGNIFICANT",IF(F19>=60,"Trait","Not Sig.")))
A20: 6A | B20: Antisocial | C20: =IF(DATA!B9="T",1,0)+IF(DATA!B15="T",1,0)+IF(DATA!B17="T",1,0)+IF(DATA!B31="T",1,0)+IF(DATA!B35="T",1,0)+IF(DATA!B37="T",2,0)+IF(DATA!B43="T",1,0)+IF(DATA!B50="T",2,0)+IF(DATA!B61="T",1,0)+IF(DATA!B66="T",1,0)+IF(DATA!B69="T",1,0)+IF(DATA!B80="T",1,0)+IF(DATA!B88="T",1,0)+IF(DATA!B96="T",1,0)+IF(DATA!B107="T",2,0)+IF(DATA!B114="T",1,0)+IF(DATA!B134="T",1,0)+IF(DATA!B158="T",1,0)+IF(DATA!B167="T",1,0) | D20: =MIN(115,MAX(0,ROUND(IF(C20>=34,112+1.5*(C20-34),IF(C20>=32,107+2.5*(C20-32),IF(C20>=30,102+2.5*(C20-30),IF(C20>=28,97+2.5*(C20-28),IF(C20>=26,92+2.5*(C20-26),IF(C20>=24,87+2.5*(C20-24),IF(C20>=22,82+2.5*(C20-22),IF(C20>=20,77+2.5*(C20-20),IF(C20>=18,72+2.5*(C20-18),IF(C20>=16,67+2.5*(C20-16),IF(C20>=14,62+2.5*(C20-14),IF(C20>=12,56+3.0*(C20-12),IF(C20>=10,50+3.0*(C20-10),IF(C20>=8,42+4.0*(C20-8),IF(C20>=6,33+4.5*(C20-6),IF(C20>=4,23+5.0*(C20-4),IF(C20>=2,12+5.5*(C20-2),IF(C20>=0,0+6.0*(C20-0),0)))))))))))))))))),0))) | E20: =C41 | F20: =MIN(115,MAX(0,D20+E20)) | H20: =IF(F20>=85,"PROMINENT",IF(F20>=75,"SIGNIFICANT",IF(F20>=60,"Trait","Not Sig.")))
A21: 6B | B21: Aggressive/Sadistic | C21: =IF(DATA!B9="T",1,0)+IF(DATA!B15="T",1,0)+IF(DATA!B20="T",2,0)+IF(DATA!B31="T",1,0)+IF(DATA!B35="T",1,0)+IF(DATA!B37="T",1,0)+IF(DATA!B50="T",1,0)+IF(DATA!B61="T",1,0)+IF(DATA!B66="T",1,0)+IF(DATA!B69="T",1,0)+IF(DATA!B70="T",2,0)+IF(DATA!B80="T",1,0)+IF(DATA!B88="T",1,0)+IF(DATA!B96="T",1,0)+IF(DATA!B107="T",1,0)+IF(DATA!B114="T",1,0)+IF(DATA!B120="T",2,0)+IF(DATA!B134="T",1,0)+IF(DATA!B158="T",1,0)+IF(DATA!B167="T",1,0) | D21: =MIN(115,MAX(0,ROUND(IF(C21>=51,112+1.0*(C21-51),IF(C21>=48,107+1.6667*(C21-48),IF(C21>=45,102+1.6667*(C21-45),IF(C21>=42,97+1.6667*(C21-42),IF(C21>=39,92+1.6667*(C21-39),IF(C21>=36,87+1.6667*(C21-36),IF(C21>=33,82+1.6667*(C21-33),IF(C21>=30,77+1.6667*(C21-30),IF(C21>=27,72+1.6667*(C21-27),IF(C21>=24,67+1.6667*(C21-24),IF(C21>=21,62+1.6667*(C21-21),IF(C21>=18,56+2.0*(C21-18),IF(C21>=15,50+2.0*(C21-15),IF(C21>=12,42+2.6667*(C21-12),IF(C21>=9,33+3.0*(C21-9),IF(C21>=6,23+3.3333*(C21-6),IF(C21>=3,12+3.6667*(C21-3),IF(C21>=0,0+4.0*(C21-0),0)))))))))))))))))),0))) | E21: =C41 | F21: =MIN(115,MAX(0,D21+E21)) | H21: =IF(F21>=85,"PROMINENT",IF(F21>=75,"SIGNIFICANT",IF(F21>=60,"Trait","Not Sig.")))
A22: 7 | B22: Compulsive | C22: =IF(DATA!B7="T",1,0)+IF(DATA!B10="T",1,0)+IF(DATA!B29="T",1,0)+IF(DATA!B35="T",1,0)+IF(DATA!B40="T",1,0)+IF(DATA!B43="T",1,0)+IF(DATA!B60="T",1,0)+IF(DATA!B66="T",1,0)+IF(DATA!B71="T",1,0)+IF(DATA!B77="T",1,0)+IF(DATA!B85="T",1,0)+IF(DATA!B91="T",1,0)+IF(DATA!B98="T",1,0)+IF(DATA!B102="T",2,0)+IF(DATA!B106="T",1,0)+IF(DATA!B136="T",1,0)+IF(DATA!B143="T",2,0)+IF(DATA!B148="T",1,0)+IF(DATA!B165="T",2,0)+IF(DATA!B167="T",1,0) | D22: =MIN(115,MAX(0,ROUND(IF(C22>=48,110+2.5*(C22-48),IF(C22>=45,105+1.6667*(C22-45),IF(C22>=42,100+1.6667*(C22-42),IF(C22>=39,95+1.6667*(C22-39),IF(C22>=36,90+1.6667*(C22-36),IF(C22>=33,85+1.6667*(C22-33),IF(C22>=30,80+1.6667*(C22-30),IF(C22>=27,75+1.6667*(C22-27),IF(C22>=24,70+1.6667*(C22-24),IF(C22>=21,65+1.6667*(C22-21),IF(C22>=18,60+1.6667*(C22-18),IF(C22>=15,54+2.0*(C22-15),IF(C22>=12,47+2.3333*(C22-12),IF(C22>=9,38+3.0*(C22-9),IF(C22>=6,28+3.3333*(C22-6),IF(C22>=3,15+4.3333*(C22-3),IF(C22>=0,0+5.0*(C22-0),0))))))))))))))))),0))) | E22: =C41 | F22: =MIN(115,MAX(0,D22+E22)) | H22: =IF(F22>=85,"PROMINENT",IF(F22>=75,"SIGNIFICANT",IF(F22>=60,"Trait","Not Sig.")))
A23: 8A | B23: Negativistic | C23: =IF(DATA!B8="T",1,0)+IF(DATA!B13="T",2,0)+IF(DATA!B18="T",1,0)+IF(DATA!B23="T",1,0)+IF(DATA!B36="T",1,0)+IF(DATA!B42="T",2,0)+IF(DATA!B49="T",1,0)+IF(DATA!B63="T",1,0)+IF(DATA!B73="T",1,0)+IF(DATA!B78="T",1,0)+IF(DATA!B83="T",1,0)+IF(DATA!B89="T",1,0)+IF(DATA!B94="T",1,0)+IF(DATA!B122="T",1,0)+IF(DATA!B128="T",1,0)+IF(DATA!B163="T",1,0)+IF(DATA!B168="T",2,0)+IF(DATA!B169="T",1,0)+IF(DATA!B172="T",1,0) | D23: =MIN(115,MAX(0,ROUND(IF(C23>=34,114+0.5*(C23-34),IF(C23>=32,109+2.5*(C23-32),IF(C23>=30,104+2.5*(C23-30),IF(C23>=28,99+2.5*(C23-28),IF(C23>=26,94+2.5*(C23-26),IF(C23>=24,89+2.5*(C23-24),IF(C23>=22,84+2.5*(C23-22),IF(C23>=20,79+2.5*(C23-20),IF(C23>=18,74+2.5*(C23-18),IF(C23>=16,69+2.5*(C23-16),IF(C23>=14,64+2.5*(C23-14),IF(C23>=12,59+2.5*(C23-12),IF(C23>=10,53+3.0*(C23-10),IF(C23>=8,45+4.0*(C23-8),IF(C23>=6,35+5.0*(C23-6),IF(C23>=4,24+5.5*(C23-4),IF(C23>=2,12+6.0*(C23-2),IF(C23>=0,0+6.0*(C23-0),0)))))))))))))))))),0))) | E23: =C41 | F23: =MIN(115,MAX(0,D23+E23)) | H23: =IF(F23>=85,"PROMINENT",IF(F23>=75,"SIGNIFICANT",IF(F23>=60,"Trait","Not Sig.")))
A24: 8B | B24: Masochistic | C24: =IF(DATA!B8="T",1,0)+IF(DATA!B18="T",1,0)+IF(DATA!B23="T",1,0)+IF(DATA!B28="T",2,0)+IF(DATA!B36="T",1,0)+IF(DATA!B49="T",1,0)+IF(DATA!B52="T",2,0)+IF(DATA!B63="T",1,0)+IF(DATA!B73="T",1,0)+IF(DATA!B78="T",1,0)+IF(DATA!B83="T",1,0)+IF(DATA!B89="T",1,0)+IF(DATA!B94="T",1,0)+IF(DATA!B122="T",1,0)+IF(DATA!B128="T",1,0)+IF(DATA!B153="T",2,0)+IF(DATA!B163="T",1,0)+IF(DATA!B172="T",1,0) | D24: =MIN(115,MAX(0,ROUND(IF(C24>=34,114+0.5*(C24-34),IF(C24>=32,109+2.5*(C24-32),IF(C24>=30,104+2.5*(C24-30),IF(C24>=28,99+2.5*(C24-28),IF(C24>=26,94+2.5*(C24-26),IF(C24>=24,89+2.5*(C24-24),IF(C24>=22,84+2.5*(C24-22),IF(C24>=20,79+2.5*(C24-20),IF(C24>=18,74+2.5*(C24-18),IF(C24>=16,69+2.5*(C24-16),IF(C24>=14,64+2.5*(C24-14),IF(C24>=12,59+2.5*(C24-12),IF(C24>=10,53+3.0*(C24-10),IF(C24>=8,45+4.0*(C24-8),IF(C24>=6,35+5.0*(C24-6),IF(C24>=4,24+5.5*(C24-4),IF(C24>=2,12+6.0*(C24-2),IF(C24>=0,0+6.0*(C24-0),0)))))))))))))))))),0))) | E24: =C41 | F24: =MIN(115,MAX(0,D24+E24)) | H24: =IF(F24>=85,"PROMINENT",IF(F24>=75,"SIGNIFICANT",IF(F24>=60,"Trait","Not Sig.")))
A25: S | B25: Schizotypal | C25: =IF(DATA!B5="T",1,0)+IF(DATA!B23="T",1,0)+IF(DATA!B25="T",1,0)+IF(DATA!B27="T",2,0)+IF(DATA!B44="T",1,0)+IF(DATA!B49="T",1,0)+IF(DATA!B56="T",1,0)+IF(DATA!B59="T",1,0)+IF(DATA!B60="T",2,0)+IF(DATA!B74="T",1,0)+IF(DATA!B81="T",1,0)+IF(DATA!B84="T",1,0)+IF(DATA!B101="T",1,0)+IF(DATA!B124="T",1,0)+IF(DATA!B138="T",1,0)+IF(DATA!B150="T",2,0)+IF(DATA!B161="T",1,0)+IF(DATA!B175="T",1,0) | D25: =MIN(115,MAX(0,ROUND(IF(C25>=34,114+0.5*(C25-34),IF(C25>=32,109+2.5*(C25-32),IF(C25>=30,104+2.5*(C25-30),IF(C25>=28,99+2.5*(C25-28),IF(C25>=26,94+2.5*(C25-26),IF(C25>=24,89+2.5*(C25-24),IF(C25>=22,84+2.5*(C25-22),IF(C25>=20,79+2.5*(C25-20),IF(C25>=18,74+2.5*(C25-18),IF(C25>=16,69+2.5*(C25-16),IF(C25>=14,64+2.5*(C25-14),IF(C25>=12,59+2.5*(C25-12),IF(C25>=10,53+3.0*(C25-10),IF(C25>=8,45+4.0*(C25-8),IF(C25>=6,35+5.0*(C25-6),IF(C25>=4,24+5.5*(C25-4),IF(C25>=2,12+6.0*(C25-2),IF(C25>=0,0+6.0*(C25-0),0)))))))))))))))))),0))) | E25: =C42 | F25: =MIN(115,MAX(0,D25+E25)) | H25: =IF(F25>=85,"PROMINENT",IF(F25>=75,"SIGNIFICANT",IF(F25>=60,"Trait","Not Sig.")))
A26: C | B26: Borderline | C26: =IF(DATA!B8="T",1,0)+IF(DATA!B13="T",1,0)+IF(DATA!B18="T",1,0)+IF(DATA!B23="T",1,0)+IF(DATA!B28="T",2,0)+IF(DATA!B36="T",1,0)+IF(DATA!B42="T",1,0)+IF(DATA!B49="T",1,0)+IF(DATA!B52="T",2,0)+IF(DATA!B63="T",1,0)+IF(DATA!B73="T",1,0)+IF(DATA!B78="T",1,0)+IF(DATA!B83="T",1,0)+IF(DATA!B89="T",1,0)+IF(DATA!B94="T",1,0)+IF(DATA!B122="T",1,0)+IF(DATA!B128="T",1,0)+IF(DATA!B163="T",1,0)+IF(DATA!B168="T",2,0) | D26: =MIN(115,MAX(0,ROUND(IF(C26>=34,114+0.5*(C26-34),IF(C26>=32,109+2.5*(C26-32),IF(C26>=30,104+2.5*(C26-30),IF(C26>=28,99+2.5*(C26-28),IF(C26>=26,94+2.5*(C26-26),IF(C26>=24,89+2.5*(C26-24),IF(C26>=22,84+2.5*(C26-22),IF(C26>=20,79+2.5*(C26-20),IF(C26>=18,74+2.5*(C26-18),IF(C26>=16,69+2.5*(C26-16),IF(C26>=14,64+2.5*(C26-14),IF(C26>=12,59+2.5*(C26-12),IF(C26>=10,53+3.0*(C26-10),IF(C26>=8,45+4.0*(C26-8),IF(C26>=6,35+5.0*(C26-6),IF(C26>=4,24+5.5*(C26-4),IF(C26>=2,12+6.0*(C26-2),IF(C26>=0,0+6.0*(C26-0),0)))))))))))))))))),0))) | E26: =C42 | F26: =MIN(115,MAX(0,D26+E26)) | H26: =IF(F26>=85,"PROMINENT",IF(F26>=75,"SIGNIFICANT",IF(F26>=60,"Trait","Not Sig.")))
A27: P | B27: Paranoid | C27: =IF(DATA!B9="T",1,0)+IF(DATA!B11="T",2,0)+IF(DATA!B15="T",1,0)+IF(DATA!B20="T",1,0)+IF(DATA!B31="T",1,0)+IF(DATA!B32="T",2,0)+IF(DATA!B35="T",1,0)+IF(DATA!B37="T",1,0)+IF(DATA!B50="T",1,0)+IF(DATA!B61="T",1,0)+IF(DATA!B66="T",1,0)+IF(DATA!B70="T",1,0)+IF(DATA!B80="T",1,0)+IF(DATA!B88="T",1,0)+IF(DATA!B96="T",1,0)+IF(DATA!B107="T",1,0)+IF(DATA!B114="T",1,0)+IF(DATA!B120="T",1,0)+IF(DATA!B146="T",2,0)+IF(DATA!B158="T",1,0) | D27: =MIN(115,MAX(0,ROUND(IF(C27>=51,112+1.0*(C27-51),IF(C27>=48,107+1.6667*(C27-48),IF(C27>=45,102+1.6667*(C27-45),IF(C27>=42,97+1.6667*(C27-42),IF(C27>=39,92+1.6667*(C27-39),IF(C27>=36,87+1.6667*(C27-36),IF(C27>=33,82+1.6667*(C27-33),IF(C27>=30,77+1.6667*(C27-30),IF(C27>=27,72+1.6667*(C27-27),IF(C27>=24,67+1.6667*(C27-24),IF(C27>=21,62+1.6667*(C27-21),IF(C27>=18,56+2.0*(C27-18),IF(C27>=15,50+2.0*(C27-15),IF(C27>=12,42+2.6667*(C27-12),IF(C27>=9,33+3.0*(C27-9),IF(C27>=6,23+3.3333*(C27-6),IF(C27>=3,12+3.6667*(C27-3),IF(C27>=0,0+4.0*(C27-0),0)))))))))))))))))),0))) | E27: =C42 | F27: =MIN(115,MAX(0,D27+E27)) | H27: =IF(F27>=85,"PROMINENT",IF(F27>=75,"SIGNIFICANT",IF(F27>=60,"Trait","Not Sig.")))
A28: A | B28: Anxiety | C28: =IF(DATA!B19="T",1,0)+IF(DATA!B38="T",1,0)+IF(DATA!B47="T",2,0)+IF(DATA!B51="T",1,0)+IF(DATA!B59="T",1,0)+IF(DATA!B86="T",1,0)+IF(DATA!B90="T",1,0)+IF(DATA!B95="T",1,0)+IF(DATA!B110="T",1,0)+IF(DATA!B117="T",1,0)+IF(DATA!B121="T",2,0)+IF(DATA!B125="T",1,0)+IF(DATA!B139="T",1,0)+IF(DATA!B157="T",1,0)+IF(DATA!B166="T",1,0) | D28: =MIN(115,MAX(0,ROUND(IF(C28>=28,110+2.5*(C28-28),IF(C28>=26,105+2.5*(C28-26),IF(C28>=24,100+2.5*(C28-24),IF(C28>=22,95+2.5*(C28-22),IF(C28>=20,90+2.5*(C28-20),IF(C28>=18,85+2.5*(C28-18),IF(C28>=16,79+3.0*(C28-16),IF(C28>=14,73+3.0*(C28-14),IF(C28>=12,67+3.0*(C28-12),IF(C28>=10,60+3.5*(C28-10),IF(C28>=8,52+4.0*(C28-8),IF(C28>=6,42+5.0*(C28-6),IF(C28>=4,30+6.0*(C28-4),IF(C28>=2,15+7.5*(C28-2),IF(C28>=0,0+7.5*(C28-0),0))))))))))))))),0))) | E28: =C42 | F28: =MIN(115,MAX(0,D28+E28)) | H28: =IF(F28>=85,"PROMINENT",IF(F28>=75,"SIGNIFICANT",IF(F28>=60,"Trait","Not Sig.")))
A29: H | B29: Somatoform | C29: =IF(DATA!B19="T",1,0)+IF(DATA!B38="T",1,0)+IF(DATA!B51="T",1,0)+IF(DATA!B64="T",1,0)+IF(DATA!B79="T",2,0)+IF(DATA!B90="T",1,0)+IF(DATA!B95="T",1,0)+IF(DATA!B103="T",1,0)+IF(DATA!B110="T",1,0)+IF(DATA!B117="T",1,0)+IF(DATA!B135="T",2,0)+IF(DATA!B139="T",1,0)+IF(DATA!B166="T",1,0) | D29: =MIN(115,MAX(0,ROUND(IF(C29>=30,113+1.0*(C29-30),IF(C29>=28,108+2.5*(C29-28),IF(C29>=26,103+2.5*(C29-26),IF(C29>=24,98+2.5*(C29-24),IF(C29>=22,93+2.5*(C29-22),IF(C29>=20,88+2.5*(C29-20),IF(C29>=18,83+2.5*(C29-18),IF(C29>=16,77+3.0*(C29-16),IF(C29>=14,71+3.0*(C29-14),IF(C29>=12,65+3.0*(C29-12),IF(C29>=10,58+3.5*(C29-10),IF(C29>=8,50+4.0*(C29-8),IF(C29>=6,40+5.0*(C29-6),IF(C29>=4,28+6.0*(C29-4),IF(C29>=2,15+6.5*(C29-2),IF(C29>=0,0+7.5*(C29-0),0)))))))))))))))),0))) | E29: =C42 | F29: =MIN(115,MAX(0,D29+E29)) | H29: =IF(F29>=85,"PROMINENT",IF(F29>=75,"SIGNIFICANT",IF(F29>=60,"Trait","Not Sig.")))
A30: N | B30: Bipolar:Manic | C30: =IF(DATA!B9="T",1,0)+IF(DATA!B15="T",1,0)+IF(DATA!B17="T",1,0)+IF(DATA!B31="T",1,0)+IF(DATA!B35="T",1,0)+IF(DATA!B37="T",1,0)+IF(DATA!B40="T",2,0)+IF(DATA!B50="T",1,0)+IF(DATA!B61="T",1,0)+IF(DATA!B66="T",1,0)+IF(DATA!B80="T",1,0)+IF(DATA!B88="T",1,0)+IF(DATA!B98="T",2,0) | D30: =MIN(115,MAX(0,ROUND(IF(C30>=30,113+1.0*(C30-30),IF(C30>=28,108+2.5*(C30-28),IF(C30>=26,103+2.5*(C30-26),IF(C30>=24,98+2.5*(C30-24),IF(C30>=22,93+2.5*(C30-22),IF(C30>=20,88+2.5*(C30-20),IF(C30>=18,83+2.5*(C30-18),IF(C30>=16,77+3.0*(C30-16),IF(C30>=14,71+3.0*(C30-14),IF(C30>=12,65+3.0*(C30-12),IF(C30>=10,58+3.5*(C30-10),IF(C30>=8,50+4.0*(C30-8),IF(C30>=6,40+5.0*(C30-6),IF(C30>=4,28+6.0*(C30-4),IF(C30>=2,15+6.5*(C30-2),IF(C30>=0,0+7.5*(C30-0),0)))))))))))))))),0))) | E30: =C42 | F30: =MIN(115,MAX(0,D30+E30)) | H30: =IF(F30>=85,"PROMINENT",IF(F30>=75,"SIGNIFICANT",IF(F30>=60,"Trait","Not Sig.")))
A31: D | B31: Dysthymia | C31: =IF(DATA!B19="T",1,0)+IF(DATA!B38="T",1,0)+IF(DATA!B47="T",1,0)+IF(DATA!B51="T",1,0)+IF(DATA!B53="T",2,0)+IF(DATA!B59="T",1,0)+IF(DATA!B86="T",1,0)+IF(DATA!B90="T",1,0)+IF(DATA!B95="T",1,0)+IF(DATA!B99="T",1,0)+IF(DATA!B110="T",1,0)+IF(DATA!B125="T",1,0)+IF(DATA!B133="T",2,0)+IF(DATA!B139="T",1,0)+IF(DATA!B166="T",1,0) | D31: =MIN(115,MAX(0,ROUND(IF(C31>=30,113+1.0*(C31-30),IF(C31>=28,108+2.5*(C31-28),IF(C31>=26,103+2.5*(C31-26),IF(C31>=24,98+2.5*(C31-24),IF(C31>=22,93+2.5*(C31-22),IF(C31>=20,88+2.5*(C31-20),IF(C31>=18,83+2.5*(C31-18),IF(C31>=16,77+3.0*(C31-16),IF(C31>=14,71+3.0*(C31-14),IF(C31>=12,65+3.0*(C31-12),IF(C31>=10,58+3.5*(C31-10),IF(C31>=8,50+4.0*(C31-8),IF(C31>=6,40+5.0*(C31-6),IF(C31>=4,28+6.0*(C31-4),IF(C31>=2,15+6.5*(C31-2),IF(C31>=0,0+7.5*(C31-0),0)))))))))))))))),0))) | E31: =C42 | F31: =MIN(115,MAX(0,D31+E31)) | H31: =IF(F31>=85,"PROMINENT",IF(F31>=75,"SIGNIFICANT",IF(F31>=60,"Trait","Not Sig.")))
A32: B | B32: Alcohol Dep. | C32: =IF(DATA!B9="T",1,0)+IF(DATA!B15="T",1,0)+IF(DATA!B31="T",1,0)+IF(DATA!B37="T",1,0)+IF(DATA!B50="T",1,0)+IF(DATA!B55="T",2,0)+IF(DATA!B61="T",1,0)+IF(DATA!B66="T",1,0)+IF(DATA!B80="T",1,0)+IF(DATA!B88="T",1,0)+IF(DATA!B107="T",1,0)+IF(DATA!B114="T",1,0)+IF(DATA!B132="T",2,0)+IF(DATA!B134="T",1,0)+IF(DATA!B158="T",1,0) | D32: =MIN(115,MAX(0,ROUND(IF(C32>=30,113+1.0*(C32-30),IF(C32>=28,108+2.5*(C32-28),IF(C32>=26,103+2.5*(C32-26),IF(C32>=24,98+2.5*(C32-24),IF(C32>=22,93+2.5*(C32-22),IF(C32>=20,88+2.5*(C32-20),IF(C32>=18,83+2.5*(C32-18),IF(C32>=16,77+3.0*(C32-16),IF(C32>=14,71+3.0*(C32-14),IF(C32>=12,65+3.0*(C32-12),IF(C32>=10,58+3.5*(C32-10),IF(C32>=8,50+4.0*(C32-8),IF(C32>=6,40+5.0*(C32-6),IF(C32>=4,28+6.0*(C32-4),IF(C32>=2,15+6.5*(C32-2),IF(C32>=0,0+7.5*(C32-0),0)))))))))))))))),0))) | E32: =C42 | F32: =MIN(115,MAX(0,D32+E32)) | H32: =IF(F32>=85,"PROMINENT",IF(F32>=75,"SIGNIFICANT",IF(F32>=60,"Trait","Not Sig.")))
A33: T | B33: Drug Dep. | C33: =IF(DATA!B9="T",1,0)+IF(DATA!B15="T",1,0)+IF(DATA!B31="T",1,0)+IF(DATA!B37="T",1,0)+IF(DATA!B41="T",2,0)+IF(DATA!B50="T",1,0)+IF(DATA!B61="T",1,0)+IF(DATA!B66="T",1,0)+IF(DATA!B67="T",2,0)+IF(DATA!B80="T",1,0)+IF(DATA!B88="T",1,0)+IF(DATA!B107="T",1,0)+IF(DATA!B114="T",1,0)+IF(DATA!B134="T",1,0) | D33: =MIN(115,MAX(0,ROUND(IF(C33>=30,113+1.0*(C33-30),IF(C33>=28,108+2.5*(C33-28),IF(C33>=26,103+2.5*(C33-26),IF(C33>=24,98+2.5*(C33-24),IF(C33>=22,93+2.5*(C33-22),IF(C33>=20,88+2.5*(C33-20),IF(C33>=18,83+2.5*(C33-18),IF(C33>=16,77+3.0*(C33-16),IF(C33>=14,71+3.0*(C33-14),IF(C33>=12,65+3.0*(C33-12),IF(C33>=10,58+3.5*(C33-10),IF(C33>=8,50+4.0*(C33-8),IF(C33>=6,40+5.0*(C33-6),IF(C33>=4,28+6.0*(C33-4),IF(C33>=2,15+6.5*(C33-2),IF(C33>=0,0+7.5*(C33-0),0)))))))))))))))),0))) | E33: =C42 | F33: =MIN(115,MAX(0,D33+E33)) | H33: =IF(F33>=85,"PROMINENT",IF(F33>=75,"SIGNIFICANT",IF(F33>=60,"Trait","Not Sig.")))
A34: R | B34: PTSD | C34: =IF(DATA!B12="T",2,0)+IF(DATA!B19="T",1,0)+IF(DATA!B33="T",2,0)+IF(DATA!B38="T",1,0)+IF(DATA!B47="T",1,0)+IF(DATA!B51="T",1,0)+IF(DATA!B59="T",1,0)+IF(DATA!B79="T",1,0)+IF(DATA!B86="T",1,0)+IF(DATA!B90="T",1,0)+IF(DATA!B95="T",1,0)+IF(DATA!B99="T",1,0)+IF(DATA!B110="T",1,0)+IF(DATA!B117="T",1,0)+IF(DATA!B121="T",1,0)+IF(DATA!B125="T",1,0)+IF(DATA!B139="T",1,0) | D34: =MIN(115,MAX(0,ROUND(IF(C34>=34,114+0.5*(C34-34),IF(C34>=32,109+2.5*(C34-32),IF(C34>=30,104+2.5*(C34-30),IF(C34>=28,99+2.5*(C34-28),IF(C34>=26,94+2.5*(C34-26),IF(C34>=24,89+2.5*(C34-24),IF(C34>=22,84+2.5*(C34-22),IF(C34>=20,79+2.5*(C34-20),IF(C34>=18,74+2.5*(C34-18),IF(C34>=16,69+2.5*(C34-16),IF(C34>=14,64+2.5*(C34-14),IF(C34>=12,59+2.5*(C34-12),IF(C34>=10,53+3.0*(C34-10),IF(C34>=8,45+4.0*(C34-8),IF(C34>=6,35+5.0*(C34-6),IF(C34>=4,24+5.5*(C34-4),IF(C34>=2,12+6.0*(C34-2),IF(C34>=0,0+6.0*(C34-0),0)))))))))))))))))),0))) | E34: =C42 | F34: =MIN(115,MAX(0,D34+E34)) | H34: =IF(F34>=85,"PROMINENT",IF(F34>=75,"SIGNIFICANT",IF(F34>=60,"Trait","Not Sig.")))
A35: SS | B35: Thought Disorder | C35: =IF(DATA!B19="T",1,0)+IF(DATA!B33="T",2,0)+IF(DATA!B38="T",1,0)+IF(DATA!B47="T",1,0)+IF(DATA!B51="T",1,0)+IF(DATA!B59="T",1,0)+IF(DATA!B75="T",2,0)+IF(DATA!B79="T",1,0)+IF(DATA!B86="T",1,0)+IF(DATA!B90="T",1,0)+IF(DATA!B95="T",1,0)+IF(DATA!B99="T",1,0)+IF(DATA!B103="T",1,0)+IF(DATA!B110="T",1,0)+IF(DATA!B117="T",1,0)+IF(DATA!B121="T",1,0)+IF(DATA!B125="T",1,0)+IF(DATA!B139="T",1,0)+IF(DATA!B178="T",2,0) | D35: =MIN(115,MAX(0,ROUND(IF(C35>=34,113+1.0*(C35-34),IF(C35>=32,108+2.5*(C35-32),IF(C35>=30,103+2.5*(C35-30),IF(C35>=28,98+2.5*(C35-28),IF(C35>=26,93+2.5*(C35-26),IF(C35>=24,88+2.5*(C35-24),IF(C35>=22,83+2.5*(C35-22),IF(C35>=20,78+2.5*(C35-20),IF(C35>=18,73+2.5*(C35-18),IF(C35>=16,67+3.0*(C35-16),IF(C35>=14,61+3.0*(C35-14),IF(C35>=12,55+3.0*(C35-12),IF(C35>=10,48+3.5*(C35-10),IF(C35>=8,40+4.0*(C35-8),IF(C35>=6,30+5.0*(C35-6),IF(C35>=4,20+5.0*(C35-4),IF(C35>=2,10+5.0*(C35-2),IF(C35>=0,0+5.0*(C35-0),0)))))))))))))))))),0))) | E35: =C42 | F35: =MIN(115,MAX(0,D35+E35+C44)) | H35: =IF(F35>=85,"PROMINENT",IF(F35>=75,"SIGNIFICANT",IF(F35>=60,"Trait","Not Sig.")))
A36: CC | B36: Major Depression | C36: =IF(DATA!B12="T",2,0)+IF(DATA!B19="T",1,0)+IF(DATA!B38="T",1,0)+IF(DATA!B47="T",1,0)+IF(DATA!B51="T",1,0)+IF(DATA!B53="T",1,0)+IF(DATA!B59="T",1,0)+IF(DATA!B79="T",1,0)+IF(DATA!B86="T",1,0)+IF(DATA!B90="T",1,0)+IF(DATA!B95="T",1,0)+IF(DATA!B99="T",1,0)+IF(DATA!B103="T",1,0)+IF(DATA!B110="T",1,0)+IF(DATA!B112="T",2,0)+IF(DATA!B125="T",1,0)+IF(DATA!B133="T",1,0)+IF(DATA!B139="T",1,0)+IF(DATA!B151="T",2,0) | D36: =MIN(115,MAX(0,ROUND(IF(C36>=34,113+1.0*(C36-34),IF(C36>=32,108+2.5*(C36-32),IF(C36>=30,103+2.5*(C36-30),IF(C36>=28,98+2.5*(C36-28),IF(C36>=26,93+2.5*(C36-26),IF(C36>=24,88+2.5*(C36-24),IF(C36>=22,83+2.5*(C36-22),IF(C36>=20,78+2.5*(C36-20),IF(C36>=18,73+2.5*(C36-18),IF(C36>=16,67+3.0*(C36-16),IF(C36>=14,61+3.0*(C36-14),IF(C36>=12,55+3.0*(C36-12),IF(C36>=10,48+3.5*(C36-10),IF(C36>=8,40+4.0*(C36-8),IF(C36>=6,30+5.0*(C36-6),IF(C36>=4,20+5.0*(C36-4),IF(C36>=2,10+5.0*(C36-2),IF(C36>=0,0+5.0*(C36-0),0)))))))))))))))))),0))) | E36: =C42 | F36: =MIN(115,MAX(0,D36+E36+C45)) | H36: =IF(F36>=85,"PROMINENT",IF(F36>=75,"SIGNIFICANT",IF(F36>=60,"Trait","Not Sig.")))
A37: PP | B37: Delusional | C37: =IF(DATA!B9="T",1,0)+IF(DATA!B11="T",1,0)+IF(DATA!B15="T",1,0)+IF(DATA!B20="T",1,0)+IF(DATA!B31="T",1,0)+IF(DATA!B32="T",1,0)+IF(DATA!B37="T",1,0)+IF(DATA!B50="T",1,0)+IF(DATA!B61="T",1,0)+IF(DATA!B66="T",1,0)+IF(DATA!B80="T",1,0)+IF(DATA!B88="T",1,0)+IF(DATA!B146="T",2,0)+IF(DATA!B178="T",2,0) | D37: =MIN(115,MAX(0,ROUND(IF(C37>=32,111+2.0*(C37-32),IF(C37>=30,106+2.5*(C37-30),IF(C37>=28,101+2.5*(C37-28),IF(C37>=26,96+2.5*(C37-26),IF(C37>=24,91+2.5*(C37-24),IF(C37>=22,86+2.5*(C37-22),IF(C37>=20,81+2.5*(C37-20),IF(C37>=18,76+2.5*(C37-18),IF(C37>=16,70+3.0*(C37-16),IF(C37>=14,64+3.0*(C37-14),IF(C37>=12,58+3.0*(C37-12),IF(C37>=10,51+3.5*(C37-10),IF(C37>=8,43+4.0*(C37-8),IF(C37>=6,33+5.0*(C37-6),IF(C37>=4,23+5.0*(C37-4),IF(C37>=2,12+5.5*(C37-2),IF(C37>=0,0+6.0*(C37-0),0))))))))))))))))),0))) | E37: =C42 | F37: =MIN(115,MAX(0,D37+E37+C46)) | H37: =IF(F37>=85,"PROMINENT",IF(F37>=75,"SIGNIFICANT",IF(F37>=60,"Trait","Not Sig.")))
A39: X | B39: Disclosure Raw Score | C39: =ROUND(C14+C15+C16+C17+C18+C20+C21+C22+C23+C24+C19*2/3,0) | D39: =IF(OR(C39<34,C39>178),"INVALID","OK: "&C39)
A41: 1-8B adj | C41: =IF(OR(C39<34,C39>178),0,IF(C39<=60,IF(C39<=37,20,IF(C39<=38,19,IF(C39<=39,18,IF(C39<=41,17,IF(C39<=42,16,IF(C39<=43,15,IF(C39<=44,14,IF(C39<=45,13,IF(C39<=46,12,IF(C39<=47,11,IF(C39<=48,10,IF(C39<=50,9,IF(C39<=51,8,IF(C39<=52,7,IF(C39<=53,6,IF(C39<=54,5,IF(C39<=55,4,IF(C39<=56,3,IF(C39<=58,2,IF(C39<=59,1,IF(C39<=60,1,0))))))))))))))))))))),IF(C39<=123,0,IF(C39<=125,-1,IF(C39<=128,-2,IF(C39<=130,-3,IF(C39<=132,-4,IF(C39<=134,-5,IF(C39<=137,-6,IF(C39<=139,-7,IF(C39<=141,-8,IF(C39<=144,-9,IF(C39<=147,-10,IF(C39<=151,-11,IF(C39<=153,-12,IF(C39<=156,-13,IF(C39<=158,-14,IF(C39<=161,-15,IF(C39<=163,-16,IF(C39<=166,-17,IF(C39<=168,-18,IF(C39<=171,-19,IF(C39<=178,-20,-20)))))))))))))))))))))))
A42: S-PP adj | C42: =IF(OR(C39<34,C39>178),0,IF(C39<=60,IF(C39<=38,10,IF(C39<=42,9,IF(C39<=44,8,IF(C39<=45,7,IF(C39<=47,6,IF(C39<=48,6,IF(C39<=50,5,IF(C39<=51,4,IF(C39<=52,4,IF(C39<=55,3,IF(C39<=58,2,IF(C39<=59,1,IF(C39<=60,1,0))))))))))))),IF(C39<=123,0,IF(C39<=125,-1,IF(C39<=128,-2,IF(C39<=130,-2,IF(C39<=132,-3,IF(C39<=135,-4,IF(C39<=139,-5,IF(C39<=141,-5,IF(C39<=144,-6,IF(C39<=147,-7,IF(C39<=150,-8,IF(C39<=153,-9,IF(C39<=156,-9,IF(C39<=158,-10,IF(C39<=161,-10,IF(C39<=163,-11,IF(C39<=166,-12,IF(C39<=168,-12,IF(C39<=171,-13,IF(C39<=178,-14,-14))))))))))))))))))))))
A44: SS inp | C44: =IF(DATA!G1="IPD",IF(DATA!I1="",0,IF(DATA!I1<1,6,IF(DATA!I1<=4,4,0))),0)
A45: CC inp | C45: =IF(DATA!G1="IPD",IF(DATA!I1="",0,IF(DATA!I1<1,10,IF(DATA!I1<=4,8,0))),0)
...
